Workbook
Name DATES_A: 'Complete DataSet A'!$E$2:$AE$2
Name DATES_Q: 'Complete DataSet Q'!$E$4:$AZ$4
Name DATES_Q: #REF!
Name NAMES_A: 'Complete DataSet A'!$C$5:$C$299
Name NAMES_Q: 'Complete DataSet Q'!$C$7:$C$267
Name NAMES_Q: #REF!
Name WEO_ALL: 'Complete DataSet A'!$F$304:$AL$334
Name WEO_ALL: #REF!
Name WEOGAS_Rwametric_Qdata: 'Complete DataSet Q'!$E$272:$CB$302
Name WEOGAS_Rwametric_Qdata: #REF!

Sheet ControlSheet
A2: Query1
B3: Driver | C3: AREMLG32
B4: OutputType | C4: Excel
B5: ResultSet | C5: Complete Data Set (Quarterly)
B6: StartRow | C6: 5
B7: From | C7: P:\WRK\GEE\GAS.BNK
B8: Where | C8: Frequency=Q,SeriesName in ("","","",W111NGDP_R,W163NGDP_R,W134NGDP_R,W132NGDP_R,W136NGDP_R,W184NGDP_R,W158NGDP_R,W112NGDP_R,W156NGDP_R,W203NGDP_R,"","",W111NGDP_D,W163NGDP_D,W134NGDP_D,W132NGDP_D,W136NGDP_D,W158NGDP_D,W112NGDP_D,W156NGDP_D,"","",W110TXGM
C9: _D,"","",W001PNRGW,W001POILAPSP,W001PNGASW,W001PCOALW,W001PNFUELW,W001PFOODW,W001PBEVEW,W001PRAWMW,W001PMETAW,"","",W001PALUM,W001PBANSOP,W001PBEEF,W001PCOCO,W001PCOIL,W001PCOFFOTM,W001PCOFFROB,W001PCOPP,W001PCOTTIND,W001PFISH,W001PLOGSK,W001PSAWMAL,W001
C10: PHIDE,W001PGOLD,W001PIORECR,W001PLAMB,W001PLEAD,W001PMAIZMT,W001PNGASEU,W001PNICK,W001PPOIL,W001PRICENPQ,W001PRUBB,W001PLOGORE,W001PSAWORE,W001PSMEA,W001PSOIL,W001PSOYB,W001PSUGAUSA,W001PSUGAEEC,W001PSUGAISA,W001PTEA,W001PTIN,W001PWHEAMT,W001PWOOLC,W001P
C11: WOOLF,W001PZINC,"","","","",W163EDNA,W134EDNA,W134EDNA_N,W132EDNA,W132EDNA_N,W136EDNA,W136EDNA_N,W158EDNA,W112EDNA,W156EDNA,"",W122EDNA,W122EDNA_N,W124EDNA,W124EDNA_N,W128EDNA,W137EDNA,W137EDNA_N,W138EDNA,W138EDNA_N,W142EDNA,W144EDNA,W146EDNA,W172EDNA,W1
C12: 72EDNA_N,W174EDNA,W174EDNA_N,W176EDNA,W178EDNA,W178EDNA_N,W182EDNA,W182EDNA_N,W184EDNA,W184EDNA_N,W193EDNA,W196EDNA,W436EDNA,W528EDNA,W532EDNA,W542EDNA,W576EDNA,"","",W163EDNE,W134EDNE,W134EDNE_N,W132EDNE,W132EDNE_N,W158EDNE,W112EDNE,W146EDNE,"",W111ESDA
C13: ,"","",W111ENULC,W163ENULC,W134ENULC,W132ENULC,W136ENULC,W158ENULC,W112ENULC,W156ENULC,"",W122ENULC,W124ENULC,W128ENULC,W137ENULC,W138ENULC,W142ENULC,W144ENULC,W146ENULC,W172ENULC,W174ENULC,W178ENULC,W182ENULC,W184ENULC,W193ENULC,W196ENULC,"","",W111EE,W
C14: 163EE,W134EE,W132EE,W136EE,W158EE,W112EE,W156EE,"",W122EE,W124EE,W128EE,W137EE,W138EE,W142EE,W144EE,W146EE,W172EE,W174EE,W178EE,W182EE,W184EE,W193EE,W196EE,"","","","",W111FLIBOR,W163FLIBOR,W158FLIBOR,W112FPIBOR),Period In (2001Q1,2001Q2,2001Q3,2001Q4,20
C15: 02Q1,2002Q2,2002Q3,2002Q4,2003Q1,2003Q2,2003Q3,2003Q4,2004Q1,2004Q2,2004Q3,2004Q4,2005Q1,2005Q2,2005Q3,2005Q4,2006Q1,2006Q2,2006Q3,2006Q4,2007Q1,2007Q2,2007Q3,2007Q4,2008Q1,2008Q2,2008Q3,2008Q4,2009Q1,2009Q2,2009Q3,2009Q4,2010Q1,2010Q2,2010Q3,2010Q4,2011
C16: Q1,2011Q2,2011Q3,2011Q4)
B17: CancelDialog | C17: *
B18: Select | C18: DATA
B19: ColumnLocations | C19: E
A26: Query1

Sheet Complete DataSet A
E1: 1997 | F1: =E1+1 -> 1998 | G1: =F1+1 -> 1999 | H1: =G1+1 -> 2000 | I1: =H1+1 -> 2001 | J1: =I1+1 -> 2002 | K1: =J1+1 -> 2003 | L1: =K1+1 -> 2004 | M1: =L1+1 -> 2005 | ... AN1: =AM1+1 -> 2032
B2: DATASET | C2: Series_Code | E2: 1997A1 | F2: 1998A1 | G2: 1999A1 | H2: 2000A1 | I2: 2001A1 | J2: 2002A1 | K2: 2003A1 | L2: 2004A1 | M2: 2005A1 | N2: 2006A1 | O2: 2007A1 | P2: 2008A1 | Q2: 2009A1 | R2: 2010A1 | S2: 2011A1 | T2: 2012A1 | U2: 2013A1 | V2: 2014A1 | W2: 2015A1 | X2: 2016A1 | Y2: 2017A1 | Z2: 2018A1 | AA2: 2019A1 | AB2: 2020A1 | AC2: 2021A1 | AD2: 2022A1 | AE2: 2023A1 | AF2: 2024A1 | AG2: 2025A1 | AH2: 2026A1 | AI2: 2027A1 | AJ2: 2028A1 | AK2: 2029A1 | AL2: 2030A1 | AM2: 2030A2 | AN2: 2030A3
A3: OUTPUT, DEMAND, INFLATION, AND TRADE
A4: IMF.RES.GAS:GAS_LIVE_2026_JAN_GAS1_VINTAGE | B4: IMF.RES.GAS:GAS_LIVE
A5: GDP in U.S. dollars -- advanced economies | B5: =B4 -> IMF.RES.GAS:GAS_LIVE | C5: G110.NGDP_USD.A | E5: 25172.195 | F5: 25222.819 | G5: 26566.424 | H5: 27054.307 | I5: 26772.695 | J5: 27930.45 | K5: 31323.946 | L5: 34748.092 | M5: 36574.547 | N5: 38473.794 | O5: 42037.24 | P5: 44426.372 | Q5: 41919.516 | R5: 43779.085 | S5: 47015.251 | T5: 46843.373 | U5: 47310.524 | V5: 48461.898 | W5: 45874.294 | X5: 47134.41 | Y5: 49207.56 | Z5: 52079.724 | AA5: 52632.771 | AB5: 51798.477 | AC5: 57936.31 | AD5: 59304.88 | AE5: 62685.047 | AF5: 65265.927 | AG5: 69112.019 | AH5: 72469.846 | AI5: 75209.689 | AJ5: 78155.255 | AK5: 81072.809 | AL5: 84146.622
A7: Real GDP
A8: World | B8: =$B$4 -> IMF.RES.GAS:GAS_LIVE | C8: G001.NGDP_R.A | E8: 74.463085 | F8: 76.408226 | G8: 79.137441 | H8: 82.936547 | I8: 84.994332 | J8: 87.398187 | K8: 90.72254 | L8: 95.498095 | M8: 100 | N8: 105.28336 | O8: 110.92693 | P8: 114.17652 | Q8: 113.78127 | R8: 119.76139 | S8: 124.65305 | T8: 128.87585 | U8: 133.2366 | V8: 137.99901 | W8: 142.74543 | X8: 147.34759 | Y8: 153.00836 | Z8: 158.58856 | AA8: 163.27929 | AB8: 158.85138 | AC8: 169.41276 | AD8: 175.80977 | AE8: 181.96228 | AF8: 188.03716 | AG8: 194.30623 | AH8: 200.64672 | AI8: 207.08403 | AJ8: 213.7325 | AK8: 220.46593 | AL8: 227.22784
A9: Advanced economies | B9: =$B$4 -> IMF.RES.GAS:GAS_LIVE | C9: G110.NGDP_R.A | E9: 80.634925 | F9: 82.85286 | G9: 85.826215 | H9: 89.424342 | I9: 90.817239 | J9: 92.312471 | K9: 94.175525 | L9: 97.228471 | M9: 100 | N9: 103.10026 | O9: 105.99483 | P9: 106.36205 | Q9: 102.7559 | R9: 105.95134 | S9: 107.77732 | T9: 109.05122 | U9: 110.66779 | V9: 113.05774 | W9: 115.78628 | X9: 117.91534 | Y9: 120.99274 | Z9: 123.78572 | AA9: 126.08737 | AB9: 121.13332 | AC9: 128.52734 | AD9: 132.44461 | AE9: 134.69532 | AF9: 137.13825 | AG9: 139.51913 | AH9: 142.04149 | AI9: 144.46656 | AJ9: 146.94074 | AK9: 149.27785 | AL9: 151.54926
A10: Major industrial countries, by country
A11: United States | B11: =$A$4 -> IMF.RES.GAS:GAS_LIVE_2026_JAN_GAS1_VINTAGE | C11: USA.NGDP_R.A | E11: 12370.3 | F11: 12924.875 | G11: 13543.775 | H11: 14096.025 | I11: 14230.725 | J11: 14472.7 | K11: 14877.325 | L11: 15449.775 | M11: 15987.95 | N11: 16433.15 | O11: 16762.45 | P11: 16781.5 | Q11: 16349.125 | R11: 16789.775 | S11: 17052.4 | T11: 17442.775 | U11: 17812.175 | V11: 18261.7 | W11: 18799.6 | X11: 19141.675 | Y11: 19612.1 | Z11: 20193.925 | AA11: 20715.65 | AB11: 20284.5 | AC11: 21532.375 | AD11: 22075.9 | AE11: 22723.725 | AF11: 23358.425 | AG11: 23829.45 | AH11: 24330.363 | AI11: 24830.38 | AJ11: 25349.963 | AK11: 25826.691 | AL11: 26279.467
A12: Euro Area | B12: =$A$4 -> IMF.RES.GAS:GAS_LIVE_2026_JAN_GAS1_VINTAGE | C12: G163.NGDP_R.A | E12: 8854.2428 | F12: 9116.0197 | G12: 9388.1257 | H12: 9750.2117 | I12: 9960.6607 | J12: 10051.549 | K12: 10124.016 | L12: 10356.55 | M12: 10538.132 | N12: 10887.327 | O12: 11213.56 | P12: 11259.449 | Q12: 10757.64 | R12: 10980.692 | S12: 11170.013 | T12: 11063.458 | U12: 11043.582 | V12: 11202.796 | W12: 11439.335 | X12: 11645.413 | Y12: 11950.632 | Z12: 12163.226 | AA12: 12360.414 | AB12: 11615.805 | AC12: 12359.43 | AD12: 12808.086 | AE12: 12859.906 | AF12: 12969.312 | AG12: 13124.616 | AH12: 13274.292 | AI12: 13456.47 | AJ12: 13632.836 | AK12: 13800.05 | AL12: 13955.281
A13: Germany | B13: =$A$4 -> IMF.RES.GAS:GAS_LIVE_2026_JAN_GAS1_VINTAGE | C13: DEU.NGDP_R.A | E13: 2634.54 | F13: 2689.92 | G13: 2747.13 | H13: 2826.22 | I13: 2872.56 | J13: 2865.83 | K13: 2850.64 | L13: 2883.86 | M13: 2909.49 | N13: 3021.7 | O13: 3109.09 | P13: 3136.71 | Q13: 2962.61 | R13: 3085.38 | S13: 3201.32 | T13: 3216.24 | U13: 3228.93 | V13: 3299.23 | W13: 3354.1 | X13: 3428.47 | Y13: 3524.66 | Z13: 3564.6 | AA13: 3599.28 | AB13: 3450.72 | AC13: 3585.73 | AD13: 3650.52 | AE13: 3618.69 | AF13: 3600.74 | AG13: 3607.6064 | AH13: 3641.6747 | AI13: 3695.2992 | AJ13: 3739.7603 | AK13: 3776.4078 | AL13: 3802.0599
A14: Italy | B14: =$A$4 -> IMF.RES.GAS:GAS_LIVE_2026_JAN_GAS1_VINTAGE | C14: ITA.NGDP_R.A | E14: 1646.334 | F14: 1676.04 | G14: 1704.163 | H14: 1770.32 | I14: 1805.84 | J14: 1810.715 | K14: 1811.92 | L14: 1838.629 | M14: 1852.647 | N14: 1885.985 | O14: 1913.564 | P14: 1893.985 | Q14: 1793.506 | R14: 1820.931 | S14: 1833.595 | T14: 1776.291 | U14: 1743.996 | V14: 1743.972 | W14: 1759.418 | X14: 1781.17 | Y14: 1809.733 | Z14: 1824.694 | AA14: 1832.525 | AB14: 1670.013 | AC14: 1819.162 | AD14: 1906.866 | AE14: 1920.508 | AF14: 1934.445 | AG14: 1944.9977 | AH14: 1959.7549 | AI14: 1970.884 | AJ14: 1984.3578 | AK14: 1998.625 | AL14: 2012.9856
A15: France | B15: =$A$4 -> IMF.RES.GAS:GAS_LIVE_2026_JAN_GAS1_VINTAGE | C15: FRA.NGDP_R.A | E15: 1747.084 | F15: 1807.639 | G15: 1866.581 | H15: 1948.082 | I15: 1983.982 | J15: 2006.255 | K15: 2026.132 | L15: 2077.272 | M15: 2118.498 | N15: 2180.574 | O15: 2234.758 | P15: 2240.62 | Q15: 2179.436 | R15: 2219.5 | S15: 2274.631 | T15: 2279.853 | U15: 2300.951 | V15: 2323.982 | W15: 2347.165 | X15: 2364.41 | Y15: 2418.034 | Z15: 2456.56 | AA15: 2507.915 | AB15: 2317.229 | AC15: 2474.653 | AD15: 2543.966 | AE15: 2585.16 | AF15: 2613.658 | AG15: 2631.2048 | AH15: 2655.1788 | AI15: 2686.639 | AJ15: 2720.7751 | AK15: 2754.6062 | AL15: 2787.9604
A16: Spain | B16: =$A$4 -> IMF.RES.GAS:GAS_LIVE_2026_JAN_GAS1_VINTAGE | C16: ESP.NGDP_R.A | E16: 808.88679 | F16: 845.03412 | G16: 885.13326 | H16: 929.85833 | I16: 966.30088 | J16: 992.92747 | K16: 1022.112 | L16: 1053.9462 | M16: 1091.3738 | N16: 1135.5026 | O16: 1175.6258 | P16: 1184.6451 | Q16: 1140.0065 | R16: 1141.0792 | S16: 1133.7771 | T16: 1101.2933 | U16: 1085.5738 | V16: 1102.0798 | W16: 1146.8334 | X16: 1180.2658 | Y16: 1214.4471 | Z16: 1243.5382 | AA16: 1267.9261 | AB16: 1129.214 | AC16: 1204.6811 | AD16: 1281.4233 | AE16: 1312.9577 | AF16: 1358.3228 | AG16: 1397.8206 | AH16: 1425.1836 | AI16: 1449.8587 | AJ16: 1473.055 | AK16: 1496.5956 | AL16: 1520.4
A17: Japan | B17: =$A$4 -> IMF.RES.GAS:GAS_LIVE_2026_JAN_GAS1_VINTAGE | C17: JPN.NGDP_R.A | E17: 477269.5 | F17: 471206.7 | G17: 469633.1 | H17: 482616.9 | I17: 484480.2 | J17: 484683.5 | K17: 492124.1 | L17: 502882.4 | M17: 511954 | N17: 518979.7 | O17: 526681.2 | P17: 520233.1 | Q17: 490615.1 | R17: 510720 | S17: 510841.6 | T17: 517864.4 | U17: 528248.1 | V17: 529812.7 | W17: 538081.2 | X17: 542137.5 | Y17: 551220 | Z17: 554766.6 | AA17: 552535.4 | AB17: 529501.4 | AC17: 543779.9 | AD17: 549002.4 | AE17: 555837.9 | AF17: 556417.7 | AG17: 562403.89 | AH17: 565961.74 | AI17: 569552.68 | AJ17: 572693.75 | AK17: 575692.69 | AL17: 578546.14
A18: United Kingdom | B18: =$A$4 -> IMF.RES.GAS:GAS_LIVE_2026_JAN_GAS1_VINTAGE | C18: GBR.NGDP_R.A | E18: 1615.678 | F18: 1670.654 | G18: 1721.748 | H18: 1796.5 | I18: 1842.72 | J18: 1875.809 | K18: 1934.941 | L18: 1982.5 | M18: 2036.675 | N18: 2085.162 | O18: 2139.895 | P18: 2134.571 | Q18: 2035.942 | R18: 2081.411 | S18: 2105.105 | T18: 2136.871 | U18: 2175.333 | V18: 2244.827 | W18: 2294.727 | X18: 2338.825 | Y18: 2400.956 | Z18: 2434.694 | AA18: 2474.245 | AB18: 2219.474 | AC18: 2409.815 | AD18: 2526.428 | AE18: 2536.46 | AF18: 2564.378 | AG18: 2597.9238 | AH18: 2630.7485 | AI18: 2671.2642 | AJ18: 2709.6944 | AK18: 2748.5094 | AL18: 2788.1621
A19: Canada | B19: =$A$4 -> IMF.RES.GAS:GAS_LIVE_2026_JAN_GAS1_VINTAGE | C19: CAN.NGDP_R.A | E19: 1338.011 | F19: 1390.0983 | G19: 1461.5632 | H19: 1536.6662 | I19: 1565.4803 | J19: 1612.433 | K19: 1641.5597 | L19: 1692.3228 | M19: 1746.654 | N19: 1792.7297 | O19: 1829.479 | P19: 1847.6898 | Q19: 1793.828 | R19: 1849.2718 | S19: 1907.287 | T19: 1940.7725 | U19: 1985.9113 | V19: 2042.9758 | W19: 2056.2545 | X19: 2077.6098 | Y19: 2140.641 | Z19: 2199.358 | AA19: 2241.3313 | AB19: 2128.4077 | AC19: 2255.0592 | AD19: 2349.5245 | AE19: 2385.4428 | AF19: 2422.5315 | AG19: 2450.4538 | AH19: 2488.216 | AI19: 2534.9856 | AJ19: 2577.6919 | AK19: 2622.3134 | AL19: 2665.1823
A20: Other advanced economies | B20: =$B$4 -> IMF.RES.GAS:GAS_LIVE | C20: GX123.NGDP_R.A | E20: 74.066188 | F20: 74.819166 | G20: 79.001161 | H20: 83.671603 | I20: 85.473353 | J20: 88.836946 | K20: 91.249975 | L20: 95.999601 | M20: 100 | N20: 104.84516 | O20: 110.2613 | P20: 112.27825 | Q20: 111.32106 | R20: 117.95943 | S20: 122.00814 | T20: 124.7619 | U20: 128.00149 | V20: 131.79557 | W20: 134.88772 | X20: 138.51244 | Y20: 142.96355 | Z20: 146.9632 | AA20: 149.97007 | AB20: 147.58994 | AC20: 156.20543 | AD20: 160.47246 | AE20: 163.42698 | AF20: 167.22769 | AG20: 170.31516 | AH20: 173.75238 | AI20: 177.44738 | AJ20: 181.28279 | AK20: 185.03205 | AL20: 188.86293
A21: European Union | B21: =$B$4 -> IMF.RES.GAS:GAS_LIVE | C21: G998.NGDP_R.A | E21: 82.568892 | F21: 84.995723 | G21: 87.480055 | H21: 90.941922 | I21: 92.990683 | J21: 94.165751 | K21: 95.248124 | L21: 97.87456 | M21: 100 | N21: 103.78948 | O21: 107.25309 | P21: 108.1952 | Q21: 103.67098 | R21: 105.77962 | S21: 107.90647 | T21: 107.13375 | U21: 107.10834 | V21: 108.97322 | W21: 111.73693 | X21: 113.93817 | Y21: 117.40356 | Z21: 120.08595 | AA21: 122.53889 | AB21: 115.77526 | AC21: 123.227 | AD21: 127.84542 | AE21: 128.59337 | AF21: 130.07952 | AG21: 132.05996 | AH21: 134.09913 | AI21: 136.23997 | AJ21: 138.33495 | AK21: 140.35389 | AL21: 142.31459
A22: Emerging market and developing economies | B22: =$B$4 -> IMF.RES.GAS:GAS_LIVE | C22: G200.NGDP_R.A | E22: 67.406488 | F22: 69.033935 | G22: 71.483186 | H22: 75.526589 | I22: 78.354249 | J22: 81.805674 | K22: 86.79318 | L22: 93.524169 | M22: 100 | N22: 107.76243 | O22: 116.51251 | P22: 123.01986 | Q22: 126.23149 | R22: 135.39636 | S22: 143.79923 | T22: 151.41214 | U22: 158.94246 | V22: 166.45942 | W22: 173.55565 | X22: 181.03781 | Y22: 189.70817 | Z22: 198.5206 | AA22: 205.99513 | AB22: 202.218 | AC22: 216.44093 | AD22: 225.71594 | AE22: 236.37509 | AF22: 246.65623 | AG22: 257.4293 | AH22: 268.19845 | AI22: 279.28974 | AJ22: 290.78147 | AK22: 302.61545 | AL22: 314.58926
A23: Net creditor countries | B23: =$B$4 -> IMF.RES.GAS:GAS_LIVE | C23: G209.NGDP_R.A | E23: 61.975571 | F23: 63.453212 | G23: 66.32525 | H23: 71.089757 | I23: 74.536027 | J23: 78.387566 | K23: 84.569936 | L23: 92.279415 | M23: 100 | N23: 109.36478 | O23: 120.48833 | P23: 128.69612 | Q23: 132.9934 | R23: 143.7533 | S23: 154.27178 | T23: 164.12594 | U23: 172.80533 | V23: 181.49422 | W23: 189.81392 | X23: 198.86492 | Y23: 208.60083 | Z23: 218.50362 | AA23: 227.77505 | AB23: 227.72943 | AC23: 244.06439 | AD23: 252.71701 | AE23: 264.00677 | AF23: 275.73404 | AG23: 287.07819 | AH23: 298.27423 | AI23: 309.03706 | AJ23: 319.91873 | AK23: 330.64673 | AL23: 341.01966
A24: Net debtor countries | B24: =$B$4 -> IMF.RES.GAS:GAS_LIVE | C24: G606.NGDP_R.A | E24: 72.204 | F24: 73.948489 | G24: 76.05663 | H24: 79.475581 | I24: 81.748192 | J24: 84.836156 | K24: 88.780243 | L24: 94.6381 | M24: 100 | N24: 106.337 | O24: 112.95366 | P24: 117.94878 | Q24: 120.17522 | R24: 127.95048 | S24: 134.47251 | T24: 140.09711 | U24: 146.61382 | V24: 153.09761 | W24: 159.11593 | X24: 165.21642 | Y24: 172.94525 | Z24: 180.79339 | AA24: 186.69343 | AB24: 179.66932 | AC24: 192.03381 | AD24: 201.78729 | AE24: 211.86608 | AF24: 220.87136 | AG24: 231.11369 | AH24: 241.47458 | AI24: 252.79324 | AJ24: 264.74749 | AK24: 277.45813 | AL24: 290.72209
A26: Real total domestic demand
A27: Advanced economies | B27: =$B$4 -> IMF.RES.GAS:GAS_LIVE | C27: G110.NTDD_R.A | E27: 79.685077 | F27: 82.204545 | G27: 85.580143 | H27: 89.199754 | I27: 90.567939 | J27: 92.076936 | K27: 94.148821 | L27: 97.130192 | M27: 100 | N27: 102.87535 | O27: 105.41449 | P27: 105.30625 | Q27: 101.51559 | R27: 104.53306 | S27: 105.99344 | T27: 106.83062 | U27: 108.16165 | V27: 110.57313 | W27: 113.60169 | X27: 115.88153 | Y27: 118.93214 | Z27: 121.78638 | AA27: 124.38254 | AB27: 119.61058 | AC27: 126.92891 | AD27: 131.3038 | AE27: 132.78032 | AF27: 135.18641 | AG27: 137.92873 | AH27: 140.33963 | AI27: 142.68672 | AJ27: 145.03792 | AK27: 147.33232 | AL27: 149.55378
A29: GDP deflator
A30: Advanced economies | B30: =$B$4 -> IMF.RES.GAS:GAS_LIVE | C30: G110.NGDP_D.A | E30: 87.677697 | F30: 88.907124 | G30: 89.716946 | H30: 91.197188 | I30: 92.975924 | J30: 94.428605 | K30: 95.996763 | L30: 97.935374 | M30: 100 | N30: 102.13947 | O30: 104.45489 | P30: 106.51628 | Q30: 107.32123 | R30: 108.31401 | S30: 109.84109 | T30: 111.22159 | U30: 112.68896 | V30: 114.26753 | W30: 115.67819 | X30: 116.79569 | Y30: 118.47315 | Z30: 120.48525 | AA30: 122.31362 | AB30: 124.33298 | AC30: 128.45145 | AD30: 135.90418 | AE30: 141.65836 | AF30: 145.72091 | AG30: 149.45681 | AH30: 152.4506 | AI30: 155.36305 | AJ30: 158.42485 | AK30: 161.56114 | AL30: 164.75576
A31: Major industrial countries, by country
A32: United States | B32: =$A$4 -> IMF.RES.GAS:GAS_LIVE_2026_JAN_GAS1_VINTAGE | C32: USA.NGDP_D.A | E32: 69.33987 | F32: 70.119247 | G32: 71.111452 | H32: 72.722275 | I32: 74.359704 | J32: 75.51528 | K32: 77.006115 | L32: 79.076718 | M32: 81.556422 | N32: 84.071526 | O32: 86.349251 | P32: 88.012693 | Q32: 88.555504 | R32: 89.631785 | S32: 91.481111 | T32: 93.184427 | U32: 94.770431 | V32: 96.421062 | W32: 97.3159 | X32: 98.240619 | Y32: 100 | Z32: 102.29079 | AA32: 103.97924 | AB32: 105.37738 | AC32: 110.18594 | AD32: 118.02282 | AE32: 122.38971 | AF32: 125.42808 | AG32: 128.4786 | AH32: 130.7884 | AI32: 132.98217 | AJ32: 135.14182 | AK32: 137.50825 | AL32: 140.08751
A33: Euro area | B33: =$A$4 -> IMF.RES.GAS:GAS_LIVE_2026_JAN_GAS1_VINTAGE | C33: G163.NGDP_D.A | E33: 69.503095 | F33: 70.250986 | G33: 71.412134 | H33: 72.414584 | I33: 74.236591 | J33: 76.092737 | K33: 77.791072 | L33: 79.311425 | M33: 80.847037 | N33: 82.492839 | O33: 84.54593 | P33: 86.32726 | Q33: 87.206488 | R33: 87.836566 | S33: 88.816586 | T33: 89.947049 | U33: 91.06738 | V33: 91.926485 | W33: 93.202229 | X33: 94.049439 | Y33: 95.126749 | Z33: 96.578487 | AA33: 98.219077 | AB33: 100 | AC33: 102.09789 | AD33: 107.41472 | AE33: 113.82416 | AF33: 117.20093 | AG33: 119.72419 | AH33: 122.08704 | AI33: 124.64975 | AJ33: 127.2258 | AK33: 129.87328 | AL33: 132.59959
A34: Germany | B34: =$A$4 -> IMF.RES.GAS:GAS_LIVE_2026_JAN_GAS1_VINTAGE | C34: DEU.NGDP_D.A | E34: 74.668823 | F34: 75.181046 | G34: 75.614914 | H34: 75.353653 | I34: 76.431128 | J34: 77.581713 | K34: 78.60726 | L34: 79.512875 | M34: 79.935315 | N34: 80.291889 | O34: 81.767334 | P34: 82.547637 | Q34: 84.181516 | R34: 84.762979 | S34: 85.805543 | T34: 87.035793 | U34: 88.774919 | V34: 90.459592 | W34: 92.037506 | X34: 93.196382 | Y34: 94.565433 | Z34: 96.337036 | AA34: 98.277433 | AB34: 100 | AC34: 102.69429 | AD34: 109.28279 | AE34: 116.59772 | AF34: 120.22445 | AG34: 123.0336 | AH34: 125.36169 | AI34: 127.82502 | AJ34: 130.57212 | AK34: 133.40186 | AL34: 136.36821
A35: Italy | B35: =$A$4 -> IMF.RES.GAS:GAS_LIVE_2026_JAN_GAS1_VINTAGE | C35: ITA.NGDP_D.A | E35: 66.51694 | F35: 68.092408 | G35: 69.098437 | H35: 70.311808 | I35: 72.466165 | J35: 74.861201 | K35: 77.232218 | L35: 79.263245 | M35: 80.915199 | N35: 82.708187 | O35: 84.748354 | P35: 86.786221 | Q35: 88.3246 | R35: 88.85257 | S35: 90.388663 | T35: 91.927449 | U35: 92.962484 | V35: 93.801391 | W35: 94.535693 | X35: 95.715513 | Y35: 96.395104 | Z35: 97.426966 | AA35: 98.447115 | AB35: 100 | AC35: 101.28334 | AD35: 104.78308 | AE35: 110.98053 | AF35: 113.32351 | AG35: 115.78129 | AH35: 118.11281 | AI35: 120.47507 | AJ35: 122.88457 | AK35: 125.34226 | AL35: 127.84911
A36: France | B36: =$A$4 -> IMF.RES.GAS:GAS_LIVE_2026_JAN_GAS1_VINTAGE | C36: FRA.NGDP_D.A | E36: 73.818374 | F36: 74.479362 | G36: 74.743502 | H36: 75.639372 | I36: 77.121214 | J36: 78.670458 | K36: 80.069462 | L36: 81.650742 | M36: 83.1744 | N36: 84.657572 | O36: 86.715251 | P36: 88.814703 | Q36: 88.82298 | R36: 89.933544 | S36: 90.658265 | T36: 91.597441 | U36: 92.151115 | V36: 92.674255 | W36: 93.789827 | X36: 94.392216 | Y36: 94.774557 | Z36: 95.88054 | AA36: 96.981237 | AB36: 100.04518 | AC36: 101.35166 | AD36: 104.32518 | AE36: 109.47887 | AF36: 111.76688 | AG36: 113.10489 | AH36: 114.83322 | AI36: 117.06101 | AJ36: 119.33094 | AK36: 121.64707 | AL36: 123.98089
A37: Japan | B37: =$A$4 -> IMF.RES.GAS:GAS_LIVE_2026_JAN_GAS1_VINTAGE | C37: JPN.NGDP_D.A | E37: 113.88645 | F37: 113.85606 | G37: 112.44308 | H37: 110.94054 | I37: 109.73697 | J37: 108.21055 | K37: 106.47085 | L37: 105.2733 | M37: 104.0163 | N37: 103.11968 | O37: 102.39243 | P37: 101.4591 | Q37: 100.8812 | R37: 98.983905 | S37: 97.378326 | T37: 96.642017 | U37: 96.299561 | V37: 97.923493 | W37: 99.990931 | X37: 100.4108 | Y37: 100.33616 | Z37: 100.33591 | AA37: 100.97288 | AB37: 101.9159 | AC37: 101.70812 | AD37: 102.11374 | AE37: 106.27291 | AF37: 109.34212 | AG37: 112.38423 | AH37: 114.58432 | AI37: 116.90007 | AJ37: 119.23784 | AK37: 121.59358 | AL37: 123.97493
A38: United Kingdom | B38: =$A$4 -> IMF.RES.GAS:GAS_LIVE_2026_JAN_GAS1_VINTAGE | C38: GBR.NGDP_D.A | E38: 59.009592 | F38: 59.767073 | G38: 60.592375 | H38: 61.272029 | I38: 62.198001 | J38: 63.516008 | K38: 65.032164 | L38: 66.715612 | M38: 68.678066 | N38: 70.595858 | O38: 72.182841 | P38: 74.656687 | Q38: 76.072992 | R38: 77.281854 | S38: 78.978958 | T38: 80.197401 | U38: 81.889118 | V38: 82.969155 | W38: 83.515425 | X38: 85.155794 | Y38: 86.735534 | Z38: 88.401417 | AA38: 90.286976 | AB38: 94.774077 | AC38: 94.837156 | AD38: 100 | AE38: 106.88854 | AF38: 111.17663 | AG38: 115.10398 | AH38: 117.79054 | AI38: 120.28061 | AJ38: 122.77302 | AK38: 125.46129 | AL38: 128.37017
A39: Canada | B39: =$A$4 -> IMF.RES.GAS:GAS_LIVE_2026_JAN_GAS1_VINTAGE | C39: CAN.NGDP_D.A | E39: 67.781655 | F39: 67.660541 | G39: 68.962257 | H39: 71.97861 | I39: 73.111302 | J39: 74.030611 | K39: 76.436267 | L39: 78.928857 | M39: 81.389331 | N39: 83.481852 | O39: 86.235535 | P39: 89.681777 | Q39: 87.596693 | R39: 90.092113 | S39: 93.015 | T39: 94.148129 | U39: 95.78711 | V39: 97.64668 | W39: 96.79935 | X39: 97.493526 | Y39: 100 | Z39: 101.65125 | AA39: 103.22272 | AB39: 104.32808 | AC39: 112.45017 | AD39: 121.34115 | AE39: 122.98807 | AF39: 126.82378 | AG39: 129.86364 | AH39: 133.02775 | AI39: 136.07692 | AJ39: 138.86798 | AK39: 141.69764 | AL39: 145.41865
A41: Switzerland | B41: =$A$4 -> IMF.RES.GAS:GAS_LIVE_2026_JAN_GAS1_VINTAGE | C41: CHE.NGDP_D.A | E41: 91.352505 | F41: 91.184197 | G41: 91.227692 | H41: 92.466775 | I41: 93.366462 | J41: 93.134527 | K41: 94.232051 | L41: 94.519719 | M41: 95.39019 | N41: 97.436982 | O41: 99.752517 | P41: 101.20049 | Q41: 101.67237 | R41: 101.98978 | S41: 101.96502 | T41: 102.02555 | U41: 101.9343 | V41: 101.27026 | W41: 100 | X41: 99.412885 | Y41: 99.045927 | Z41: 99.802165 | AA41: 99.6988 | AB41: 99.006906 | AC41: 100.30972 | AD41: 103.35696 | AE41: 104.27302 | AF41: 105.68621 | AG41: 105.77576 | AH41: 106.43196 | AI41: 107.15421 | AJ41: 107.90004 | AK41: 108.61692 | AL41: 109.34568
A42: European Union | B42: =$B$4 -> IMF.RES.GAS:GAS_LIVE | C42: G998.NGDP_D.A | E42: 79.76771 | F42: 82.7028 | G42: 84.717671 | H42: 87.039796 | I42: 90.108693 | J42: 92.845987 | K42: 95.353592 | L42: 97.820964 | M42: 100 | N42: 102.26631 | O42: 105.37467 | P42: 108.2513 | Q42: 109.72814 | R42: 110.78005 | S42: 112.2383 | T42: 113.8061 | U42: 115.1355 | V42: 116.31474 | W42: 118.0045 | X42: 119.14928 | Y42: 120.77717 | Z42: 122.90589 | AA42: 125.42365 | AB42: 128.24228 | AC42: 131.60134 | AD42: 139.764 | AE42: 148.98615 | AF42: 153.85593 | AG42: 157.73766 | AH42: 161.2715 | AI42: 164.76963 | AJ42: 168.47863 | AK42: 172.066 | AL42: 175.7294
A44: Consumer prices
A45: Advanced economies | B45: =$B$41 -> IMF.RES.GAS:GAS_LIVE_2026_JAN_GAS1_VINTAGE | C45: G110.PCPI.A | E45: 86.01928 | F45: 87.37389 | G45: 88.59606 | H45: 90.594702 | I45: 92.572886 | J45: 94.030436 | K45: 95.775339 | L45: 97.720559 | M45: 100 | N45: 102.36277 | O45: 104.60849 | P45: 108.21651 | Q45: 108.4212 | R45: 110.10371 | S45: 113.08414 | T45: 115.35285 | U45: 116.94667 | V45: 118.52827 | W45: 118.89044 | X45: 119.77868 | Y45: 121.82358 | Z45: 124.20966 | AA45: 125.94727 | AB45: 126.80507 | AC45: 130.7362 | AD45: 140.29448 | AE45: 146.78291 | AF45: 150.63185 | AG45: 154.33402 | AH45: 157.67663 | AI45: 160.98024 | AJ45: 164.32009 | AK45: 167.73867 | AL45: 171.21809
...

Sheet Complete DataSet Q
A1: CONFIDENTIAL do not share outside the Fund without prior authorization
A2: IMF.RES.GAS:GAS_LIVE_2026_JAN_GAS1_VINTAGE | E2: 2012 | F2: =E2 -> 2012 | G2: =E2 -> 2012 | H2: =E2 -> 2012 | I2: =E2+1 -> 2013 | J2: =F2+1 -> 2013 | K2: =G2+1 -> 2013 | L2: =H2+1 -> 2013 | M2: =I2+1 -> 2014 | N2: =J2+1 -> 2014 | O2: =K2+1 -> 2014 | P2: =L2+1 -> 2014 | ... BT2: =BP2+1 -> 2028
E3: Q1 | F3: Q2 | G3: Q3 | H3: Q4 | I3: =E3 -> Q1 | J3: =F3 -> Q2 | K3: =G3 -> Q3 | L3: =H3 -> Q4 | M3: =I3 -> Q1 | N3: =J3 -> Q2 | O3: =K3 -> Q3 | P3: =L3 -> Q4 | ... BT3: =BP3 -> Q4
A4: IMF.RES.GAS:GAS_LIVE | B4: DATASET | C4: Series_Code | E4: 2012Q1 | F4: 2012Q2 | G4: 2012Q3 | H4: 2012Q4 | I4: 2013Q1 | J4: 2013Q2 | K4: 2013Q3 | L4: 2013Q4 | M4: 2014Q1 | N4: 2014Q2 | O4: 2014Q3 | P4: 2014Q4 | Q4: 2015Q1 | R4: 2015Q2 | S4: 2015Q3 | T4: 2015Q4 | U4: 2016Q1 | V4: 2016Q2 | W4: 2016Q3 | X4: 2016Q4 | Y4: 2017Q1 | Z4: 2017Q2 | AA4: 2017Q3 | AB4: 2017Q4 | AC4: 2018Q1 | AD4: 2018Q2 | AE4: 2018Q3 | AF4: 2018Q4 | AG4: 2019Q1 | AH4: 2019Q2 | AI4: 2019Q3 | AJ4: 2019Q4 | AK4: 2020Q1 | AL4: 2020Q2 | AM4: 2020Q3 | AN4: 2020Q4 | AO4: 2021Q1 | AP4: 2021Q2 | AQ4: 2021Q3 | AR4: 2021Q4 | AS4: 2022Q1 | AT4: 2022Q2 | AU4: 2022Q3 | AV4: 2022Q4 | AW4: 2023Q1 | AX4: 2023Q2 | AY4: 2023Q3 | AZ4: 2023Q4 | BA4: 2024Q1 | BB4: 2024Q2 | BC4: 2024Q3 | BD4: 2024Q4 | BE4: 2025Q1 | BF4: 2025Q2 | BG4: 2025Q3 | BH4: 2025Q4 | BI4: 2026Q1 | BJ4: 2026Q2 | BK4: 2026Q3 | BL4: 2026Q4 | BM4: 2027Q1 | BN4: 2027Q2 | BO4: 2027Q3 | BP4: 2027Q4 | BQ4: 2028Q1 | BR4: 2028Q2 | BS4: 2028Q3 | BT4: 2028Q4
A5: OUTPUT, DEMAND, INFLATION, AND TRADE
A7: Real GDP for G-7 countries
A8: United States | B8: =$A$2 -> IMF.RES.GAS:GAS_LIVE_2026_JAN_GAS1_VINTAGE | C8: USA.NGDP_R.Q | E8: 17367 | F8: 17444.5 | G8: 17469.7 | H8: 17489.9 | I8: 17662.4 | J8: 17709.7 | K8: 17860.5 | L8: 18016.1 | M8: 17954 | N8: 18185.9 | O8: 18406.9 | P8: 18500 | Q8: 18666.6 | R8: 18782.2 | S8: 18857.4 | T8: 18892.2 | U8: 19001.7 | V8: 19062.7 | W8: 19197.9 | X8: 19304.4 | Y8: 19398.3 | Z8: 19506.9 | AA8: 19660.8 | AB8: 19882.4 | AC8: 20044.1 | AD8: 20150.5 | AE8: 20276.2 | AF8: 20304.9 | AG8: 20431.6 | AH8: 20602.3 | AI8: 20843.3 | AJ8: 20985.4 | AK8: 20709.2 | AL8: 19078 | AM8: 20558.9 | AN8: 20791.9 | AO8: 21082.1 | AP8: 21440.9 | AQ8: 21617.8 | AR8: 21988.7 | AS8: 21932.7 | AT8: 21967 | AU8: 22125.6 | AV8: 22278.3 | AW8: 22439.6 | AX8: 22580.5 | AY8: 22841 | AZ8: 23033.8 | BA8: 23082.1 | BB8: 23286.5 | BC8: 23478.6 | BD8: 23586.5 | BE8: 23548.2 | BF8: 23771 | BG8: 23956.083 | BH8: 24042.515 | BI8: 24151.763 | BJ8: 24267.461 | BK8: 24389.692 | BL8: 24512.538 | BM8: 24770.795 | BN8: 24774.29 | BO8: 24831.148 | BP8: 24991.75
A9: Euro Area | B9: =$A$2 -> IMF.RES.GAS:GAS_LIVE_2026_JAN_GAS1_VINTAGE | C9: G163.NGDP_R.Q | E9: 2778.1288 | F9: 2768.7046 | G9: 2764.8182 | H9: 2753.3559 | I9: 2743.9248 | J9: 2761.8141 | K9: 2769.8961 | L9: 2776.0367 | M9: 2788.6404 | N9: 2795.3781 | O9: 2808.9647 | P9: 2819.8843 | Q9: 2840.6981 | R9: 2852.7294 | S9: 2864.9559 | T9: 2879.5295 | U9: 2892.9647 | V9: 2898.4784 | W9: 2912.6434 | X9: 2934.8098 | Y9: 2958.3911 | Z9: 2977.9179 | AA9: 3000.1045 | AB9: 3024.5315 | AC9: 3025.5798 | AD9: 3040.978 | AE9: 3043.7449 | AF9: 3060.2127 | AG9: 3081.7403 | AH9: 3092.8387 | AI9: 3099.5705 | AJ9: 3096.0218 | AK9: 2993.6474 | AL9: 2662.4523 | AM9: 2970.8374 | AN9: 2980.3075 | AO9: 3003.7649 | AP9: 3068.6383 | AQ9: 3123.6013 | AR9: 3148.1916 | AS9: 3170.8437 | AT9: 3200.4374 | AU9: 3215.2694 | AV9: 3213.848 | AW9: 3211.9732 | AX9: 3218.4514 | AY9: 3217.1067 | AZ9: 3218.6997 | BA9: 3227.6652 | BB9: 3234.1493 | BC9: 3247.2933 | BD9: 3260.2848 | BE9: 3278.566 | BF9: 3282.4749 | BG9: 3280.7244 | BH9: 3282.9229 | BI9: 3295.4005 | BJ9: 3311.4041 | BK9: 3327.4565 | BL9: 3340.1037 | BM9: 3312.3214 | BN9: 3340.5882 | BO9: 3374.8542 | BP9: 3398.2805
A10: Germany | B10: =$A$2 -> IMF.RES.GAS:GAS_LIVE_2026_JAN_GAS1_VINTAGE | C10: DEU.NGDP_R.Q | E10: 803.57 | F10: 804.43 | G10: 806.07 | H10: 803.65 | I10: 799.21 | J10: 808.53 | K10: 812.67 | L10: 813.87 | M10: 822.37 | N10: 822.2 | O10: 826.77 | P10: 833.07 | Q10: 831.26 | R10: 835.57 | S10: 840.06 | T10: 844.37 | U10: 851.79 | V10: 853.69 | W10: 856.71 | X10: 860.67 | Y10: 871.85 | Z10: 878.06 | AA10: 885.05 | AB10: 894.02 | AC10: 889.08 | AD10: 896.07 | AE10: 890.2 | AF10: 894.17 | AG10: 900.03 | AH10: 900.55 | AI10: 904 | AJ10: 900.98 | AK10: 882.69 | AL10: 804.36 | AM10: 874.15 | AN10: 882.61 | AO10: 877.17 | AP10: 897.79 | AQ10: 898.57 | AR10: 903.4 | AS10: 909.52 | AT10: 910.9 | AU10: 913.58 | AV10: 910.39 | AW10: 906.09 | AX10: 905.4 | AY10: 905.4 | AZ10: 902.9 | BA10: 901.93 | BB10: 899.6 | BC10: 899.78 | BD10: 901.41 | BE10: 904.18 | BF10: 901.67 | BG10: 902.92678 | BH10: 904.33093 | BI10: 906.05217 | BJ10: 908.18124 | BK10: 910.60851 | BL10: 913.34411 | BM10: 907.92822 | BN10: 914.73949 | BO10: 918.35559 | BP10: 922.44713
A11: France | B11: =$A$2 -> IMF.RES.GAS:GAS_LIVE_2026_JAN_GAS1_VINTAGE | C11: FRA.NGDP_R.Q | E11: 570.803 | F11: 568.561 | G11: 570.275 | H11: 570.214 | I11: 571.282 | J11: 576.301 | K11: 574.93 | L11: 578.438 | M11: 578.458 | N11: 579.909 | O11: 583.604 | P11: 582.011 | Q11: 585.375 | R11: 585.786 | S11: 587.286 | T11: 588.718 | U11: 590.553 | V11: 589.52 | W11: 590.302 | X11: 594.035 | Y11: 598.014 | Z11: 602.59 | AA11: 606.887 | AB11: 610.543 | AC11: 610.307 | AD11: 611.92 | AE11: 614.846 | AF11: 619.487 | AG11: 625.191 | AH11: 628.634 | AI11: 628.582 | AJ11: 625.508 | AK11: 593.757 | AL11: 521.351 | AM11: 601.406 | AN11: 600.715 | AO11: 603.162 | AP11: 610.51 | AQ11: 628.722 | AR11: 632.259 | AS11: 631.696 | AT11: 634.423 | AU11: 637.7 | AV11: 640.147 | AW11: 640.545 | AX11: 646.222 | AY11: 647.783 | AZ11: 650.61 | BA11: 651.405 | BB11: 652.617 | BC11: 655.015 | BD11: 654.621 | BE11: 655.373 | BF11: 657.57 | BG11: 658.46719 | BH11: 659.70854 | BI11: 661.01927 | BJ11: 662.94135 | BK11: 664.63913 | BL11: 666.49222 | BM11: 666.71419 | BN11: 668.35657 | BO11: 670.86892 | BP11: 673.34565
A12: Italy | B12: =$A$2 -> IMF.RES.GAS:GAS_LIVE_2026_JAN_GAS1_VINTAGE | C12: ITA.NGDP_R.Q | E12: 449.162 | F12: 445.757 | G12: 442.682 | H12: 439.553 | I12: 435.578 | J12: 435.555 | K12: 436.971 | L12: 436.608 | M12: 436.416 | N12: 436.627 | O12: 436.722 | P12: 436.269 | Q12: 437.801 | R12: 439.526 | S12: 439.695 | T12: 442.027 | U12: 442.808 | V12: 444.022 | W12: 447.174 | X12: 448.867 | Y12: 450.875 | Z12: 452.625 | AA12: 453.397 | AB12: 456.102 | AC12: 455.296 | AD12: 456.236 | AE12: 456.218 | AF12: 457.576 | AG12: 458.562 | AH12: 459.828 | AI12: 458.126 | AJ12: 456.423 | AK12: 429.875 | AL12: 376.881 | AM12: 431.182 | AN12: 430.917 | AO12: 438.548 | AP12: 449.303 | AQ12: 460.468 | AR12: 467.533 | AS12: 470.949 | AT12: 477.841 | AU12: 479.065 | AV12: 478.331 | AW12: 480.508 | AX12: 479.729 | AY12: 480.336 | AZ12: 481.133 | BA12: 481.897 | BB12: 482.933 | BC12: 482.951 | BD12: 483.91 | BE12: 485.416 | BF12: 485.046 | BG12: 485.9652 | BH12: 488.57249 | BI12: 488.76282 | BJ12: 490.13328 | BK12: 491.66824 | BL12: 489.19258 | BM12: 492.13271 | BN12: 495.27391 | BO12: 497.4382 | BP12: 489.81346
A13: Spain | B13: =$A$2 -> IMF.RES.GAS:GAS_LIVE_2026_JAN_GAS1_VINTAGE | C13: ESP.NGDP_R.Q | E13: 278.55084 | F13: 275.85089 | G13: 274.58419 | H13: 272.30742 | I13: 271.55903 | J13: 271.2804 | K13: 271.10932 | L13: 271.62509 | M13: 272.65183 | N13: 274.12432 | O13: 276.31613 | P13: 278.98756 | Q13: 282.38396 | R13: 285.54604 | S13: 288.16497 | T13: 290.73845 | U13: 292.75861 | V13: 293.72691 | W13: 296.04886 | X13: 297.73139 | Y13: 299.83935 | Z13: 302.97461 | AA13: 304.88863 | AB13: 306.74449 | AC13: 308.05635 | AD13: 310.06494 | AE13: 311.79603 | AF13: 313.62084 | AG13: 315.54361 | AH13: 316.45347 | AI13: 317.05986 | AJ13: 318.86914 | AK13: 302.36003 | AL13: 248.56908 | AM13: 288.09721 | AN13: 290.18767 | AO13: 293.67497 | AP13: 297.7009 | AQ13: 303.56914 | AR13: 309.73606 | AS13: 314.60438 | AT13: 319.95658 | AU13: 322.56675 | AV13: 324.29558 | AW13: 325.94988 | AX13: 326.41935 | AY13: 328.99735 | AZ13: 331.59115 | BA13: 335.2817 | BB13: 338.36305 | BC13: 340.95177 | BD13: 343.72625 | BE13: 345.91467 | BF13: 348.69479 | BG13: 350.80107 | BH13: 352.41008 | BI13: 353.83064 | BJ13: 355.42306 | BK13: 357.26853 | BL13: 358.66136 | BM13: 361.92777 | BN13: 362.28115 | BO13: 363.85522 | BP13: 365.02353
A14: Japan | B14: =$A$2 -> IMF.RES.GAS:GAS_LIVE_2026_JAN_GAS1_VINTAGE | C14: JPN.NGDP_R.Q | E14: 522781.1 | F14: 517866.4 | G14: 515836.5 | H14: 515391.7 | I14: 522631.9 | J14: 527382.9 | K14: 532360.6 | L14: 531674.2 | M14: 536079.8 | N14: 526459.3 | O14: 526816.9 | P14: 529228.1 | Q14: 537485.1 | R14: 538298.2 | S14: 538760.8 | T14: 537827.9 | U14: 541992.2 | V14: 541063.1 | W14: 542162.7 | X14: 542875.8 | Y14: 547149.2 | Z14: 549313.6 | AA14: 554075 | AB14: 554361.2 | AC14: 554797.9 | AD14: 556986.7 | AE14: 554216.5 | AF14: 552790.9 | AG14: 554140.6 | AH14: 556645.5 | AI14: 557714.9 | AJ14: 541536 | AK14: 544380.8 | AL14: 502967.4 | AM14: 530361.8 | AN14: 539394.9 | AO14: 540760.2 | AP14: 544268.2 | AQ14: 542375.9 | AR14: 548424.1 | AS14: 545878.2 | AT14: 550864.7 | AU14: 549094 | AV14: 550266.9 | AW14: 557450.2 | AX14: 558556.9 | AY14: 554032 | AZ14: 553403.6 | BA14: 552190.6 | BB14: 554839.2 | BC14: 558007.6 | BD14: 560846.8 | BE14: 561265.3 | BF14: 564278.8 | BG14: 562238.12 | BH14: 561833.34 | BI14: 563855.21 | BJ14: 565160.28 | BK14: 566928.21 | BL14: 567903.27 | BM14: 566457.07 | BN14: 566043.14 | BO14: 571657.42 | BP14: 574038.78
A15: United Kingdom | B15: =$A$2 -> IMF.RES.GAS:GAS_LIVE_2026_JAN_GAS1_VINTAGE | C15: GBR.NGDP_R.Q | E15: 532.3 | F15: 531.663 | G15: 536.72 | H15: 536.188 | I15: 537.974 | J15: 541.586 | K15: 546.064 | L15: 549.709 | M15: 554.183 | N15: 559.331 | O15: 563.694 | P15: 567.619 | Q15: 569.15 | R15: 572.673 | S15: 574.836 | T15: 578.068 | U15: 580.11 | V15: 583.383 | W15: 585.856 | X15: 589.476 | Y15: 594.423 | Z15: 598.176 | AA15: 601.961 | AB15: 606.396 | AC15: 606.785 | AD15: 607.775 | AE15: 609.653 | AF15: 610.481 | AG15: 614.936 | AH15: 616.853 | AI15: 621.227 | AJ15: 621.229 | AK15: 604.719 | AL15: 481.769 | AM15: 562.648 | AN15: 570.338 | AO15: 564.411 | AP15: 605.353 | AQ15: 615.459 | AR15: 624.592 | AS15: 629.149 | AT15: 631.258 | AU15: 631.977 | AV15: 634.044 | AW15: 634.428 | AX15: 634.694 | AY15: 634.327 | AZ15: 633.011 | BA15: 638.746 | BB15: 641.67 | BC15: 641.675 | BD15: 642.287 | BE15: 647.018 | BF15: 649.249 | BG15: 650.45062 | BH15: 651.20615 | BI15: 655.14608 | BJ15: 656.64379 | BK15: 658.74669 | BL15: 660.21197 | BM15: 663.37628 | BN15: 664.1228 | BO15: 667.14858 | BP15: 669.34234
A16: Canada | B16: =$A$2 -> IMF.RES.GAS:GAS_LIVE_2026_JAN_GAS1_VINTAGE | C16: CAN.NGDP_R.Q | E16: 1933.731 | F16: 1940.017 | G16: 1942.672 | H16: 1946.67 | I16: 1964.095 | J16: 1975.406 | K16: 1991.65 | L16: 2012.494 | M16: 2015.895 | N16: 2034.271 | O16: 2053.771 | P16: 2067.966 | Q16: 2056.452 | R16: 2050.838 | S16: 2058.182 | T16: 2059.546 | U16: 2071.732 | V16: 2061.412 | W16: 2082.805 | X16: 2094.49 | Y16: 2120.843 | Z16: 2143.166 | AA16: 2143.839 | AB16: 2154.716 | AC16: 2179.765 | AD16: 2196.768 | AE16: 2207.849 | AF16: 2213.05 | AG16: 2218.376 | AH16: 2242.662 | AI16: 2248.933 | AJ16: 2255.354 | AK16: 2211.376 | AL16: 1968.126 | AM16: 2146.901 | AN16: 2187.228 | AO16: 2224.489 | AP16: 2221.882 | AQ16: 2266.642 | AR16: 2307.224 | AS16: 2326.901 | AT16: 2348.717 | AU16: 2362.933 | AV16: 2359.547 | AW16: 2382.355 | AX16: 2387.28 | AY16: 2383.979 | AZ16: 2388.157 | BA16: 2400.862 | BB16: 2416.022 | BC16: 2430.425 | BD16: 2442.817 | BE16: 2455.138 | BF16: 2445.368 | BG16: 2446.4505 | BH16: 2454.8587 | BI16: 2466.5305 | BJ16: 2480.4517 | BK16: 2494.9386 | BL16: 2510.9433 | BM16: 2477.9759 | BN16: 2516.0387 | BO16: 2544.3877 | BP16: 2568.3092
A17: Newly Industrialized Asian economies
A19: GDP deflator
A20: United States | B20: =$A$2 -> IMF.RES.GAS:GAS_LIVE_2026_JAN_GAS1_VINTAGE | C20: USA.NGDP_D.Q | E20: 92.524904 | F20: 92.906647 | G20: 93.416029 | H20: 93.885042 | I20: 94.257859 | J20: 94.460663 | K20: 94.923434 | L20: 95.425758 | M20: 95.787568 | N20: 96.330124 | O20: 96.725684 | P20: 96.822162 | Q20: 96.769096 | R20: 97.325127 | S20: 97.582912 | T20: 97.580483 | U20: 97.496014 | V20: 98.158708 | W20: 98.409722 | X20: 98.886264 | Y20: 99.390668 | Z20: 99.649867 | AA20: 100.16174 | AB20: 100.77808 | AC20: 101.41937 | AD20: 102.13593 | AE20: 102.57691 | AF20: 103.01898 | AG20: 103.32818 | AH20: 103.8617 | AI20: 104.19271 | AJ20: 104.51647 | AK20: 105.03158 | AL20: 104.61422 | AM20: 105.5718 | AN20: 106.22983 | AO20: 107.58274 | AP20: 109.25801 | AQ20: 110.93821 | AR20: 112.84705 | AS20: 115.12627 | AT20: 117.72796 | AU20: 119.0309 | AV20: 120.16402 | AW20: 121.28737 | AX20: 121.9198 | AY20: 122.91406 | AZ20: 123.4043 | BA20: 124.3743 | BB20: 125.16694 | BC20: 125.69617 | BD20: 126.4503 | BE20: 127.57705 | BF20: 128.24744 | BG20: 128.67234 | BH20: 129.3971 | BI20: 130.00031 | BJ20: 130.5184 | BK20: 131.04611 | BL20: 131.57578 | BM20: 132.46959 | BN20: 132.82956 | BO20: 133.46367 | BP20: 133.79114
A21: Euro Area | B21: =$A$2 -> IMF.RES.GAS:GAS_LIVE_2026_JAN_GAS1_VINTAGE | C21: G163.NGDP_D.Q | E21: 89.538253 | F21: 89.77541 | G21: 90.153928 | H21: 90.323906 | I21: 90.834618 | J21: 91.04653 | K21: 91.162412 | L21: 91.223585 | M21: 91.64164 | N21: 91.830204 | O21: 91.984791 | P21: 92.246987 | Q21: 92.712788 | R21: 93.107815 | S21: 93.432859 | T21: 93.55146 | U21: 93.791767 | V21: 93.949981 | W21: 94.187043 | X21: 94.267482 | Y21: 94.636892 | Z21: 95.030488 | AA21: 95.240832 | AB21: 95.589363 | AC21: 96.022339 | AD21: 96.275284 | AE21: 96.772111 | AF21: 97.239162 | AG21: 97.576584 | AH21: 97.916603 | AI21: 98.401014 | AJ21: 98.980782 | AK21: 99.44259 | AL21: 100.61621 | AM21: 99.617892 | AN21: 100.39031 | AO21: 100.8992 | AP21: 101.2584 | AQ21: 102.49625 | AR21: 103.66455 | AS21: 105.19807 | AT21: 106.53888 | AU21: 107.87917 | AV21: 110.00803 | AW21: 112.16033 | AX21: 113.42052 | AY21: 114.266 | AZ21: 115.44454 | BA21: 116.20087 | BB21: 116.78978 | BC21: 117.43567 | BD21: 118.36341 | BE21: 118.84658 | BF21: 119.70532 | BG21: 119.78391 | BH21: 120.54667 | BI21: 121.27609 | BJ21: 122.24651 | BK21: 122.20298 | BL21: 122.60803 | BM21: 123.75527 | BN21: 124.84164 | BO21: 124.6709 | BP21: 124.70464
A22: Germany | B22: =$A$2 -> IMF.RES.GAS:GAS_LIVE_2026_JAN_GAS1_VINTAGE | C22: DEU.NGDP_D.Q | E22: 87.278296 | F22: 86.520723 | G22: 86.831279 | H22: 87.437067 | I22: 88.077949 | J22: 88.659758 | K22: 88.886838 | L22: 88.923827 | M22: 89.78858 | N22: 90.193167 | O22: 90.606291 | P22: 90.69797 | Q22: 91.359984 | R22: 91.776043 | S22: 92.428346 | T22: 92.876989 | U22: 92.285553 | V22: 94.192622 | W22: 93.418788 | X22: 93.473986 | Y22: 94.466201 | Z22: 94.319246 | AA22: 94.633646 | AB22: 94.288413 | AC22: 95.55246 | AD22: 96.216818 | AE22: 96.246433 | AF22: 96.72855 | AG22: 97.436818 | AH22: 97.929121 | AI22: 98.709898 | AJ22: 98.326508 | AK22: 100.14118 | AL22: 100.72806 | AM22: 99.701988 | AN22: 100.15291 | AO22: 101.40697 | AP22: 101.69401 | AQ22: 103.87097 | AR22: 104.77546 | AS22: 107.12266 | AT22: 109.09305 | AU22: 109.90587 | AV22: 111.80651 | AW22: 115.20731 | AX22: 115.87424 | AY22: 116.86831 | AZ22: 118.38269 | BA22: 118.75481 | BB22: 120.13968 | BC22: 120.72149 | BD22: 121.0689 | BE22: 121.32138 | BF22: 123.03518 | BG22: 123.80681 | BH22: 123.22349 | BI22: 124.04837 | BJ22: 125.12814 | BK22: 126.41974 | BL22: 126.32079 | BM22: 126.83665 | BN22: 127.25671 | BO22: 129.08781 | BP22: 129.49595
A23: France | B23: =$A$2 -> IMF.RES.GAS:GAS_LIVE_2026_JAN_GAS1_VINTAGE | C23: FRA.NGDP_D.Q | E23: 91.179969 | F23: 91.552885 | G23: 91.816229 | H23: 91.807813 | I23: 92.263891 | J23: 92.400673 | K23: 92.288279 | L23: 92.123961 | M23: 92.503691 | N23: 92.690232 | O23: 92.825615 | P23: 93.146178 | Q23: 93.424215 | R23: 93.690358 | S23: 94.056899 | T23: 94.217605 | U23: 94.366975 | V23: 94.241586 | W23: 94.373897 | X23: 94.386189 | Y23: 94.646446 | Z23: 94.879105 | AA23: 94.911079 | AB23: 95.08847 | AC23: 95.527825 | AD23: 95.643058 | AE23: 96.207018 | AF23: 96.392176 | AG23: 96.659421 | AH23: 96.954985 | AI23: 97.257637 | AJ23: 97.537681 | AK23: 98.857108 | AL23: 102.2739 | AM23: 99.118898 | AN23: 100.04894 | AO23: 100.62902 | AP23: 101.09728 | AQ23: 101.35306 | AR23: 101.77459 | AS23: 102.70621 | AT23: 103.27573 | AU23: 104.76886 | AV23: 106.33558 | AW23: 107.91982 | AX23: 109.38284 | AY23: 109.83138 | AZ23: 110.75744 | BA23: 111.20762 | BB23: 111.12153 | BC23: 112.35773 | BD23: 112.37602 | BE23: 112.85207 | BF23: 113.06781 | BG23: 113.14696 | BH23: 113.35271 | BI23: 113.95348 | BJ23: 114.55743 | BK23: 115.16459 | BL23: 115.65742 | BM23: 115.06563 | BN23: 116.06668 | BO23: 117.21819 | BP23: 118.00899
A24: Italy | B24: =$A$2 -> IMF.RES.GAS:GAS_LIVE_2026_JAN_GAS1_VINTAGE | C24: ITA.NGDP_D.Q | E24: 91.589671 | F24: 91.702205 | G24: 92.111267 | H24: 92.328343 | I24: 92.284275 | J24: 93.024073 | K24: 93.17552 | L24: 93.375751 | M24: 93.573334 | N24: 93.745691 | O24: 93.732626 | P24: 94.16736 | Q24: 94.285303 | R24: 94.496799 | S24: 94.783884 | T24: 94.589245 | U24: 95.658615 | V24: 95.636928 | W24: 95.772786 | X24: 95.810786 | Y24: 95.964513 | Z24: 96.313284 | AA24: 96.400506 | AB24: 96.902886 | AC24: 97.367647 | AD24: 97.352686 | AE24: 97.441136 | AF24: 97.554068 | AG24: 97.902574 | AH24: 98.074497 | AI24: 98.661285 | AJ24: 99.161085 | AK24: 98.973655 | AL24: 100.43223 | AM24: 100.06934 | AN24: 100.57645 | AO24: 100.29757 | AP24: 101.07233 | AQ24: 101.72607 | AR24: 101.97975 | AS24: 103.10543 | AT24: 104.46069 | AU24: 104.79079 | AV24: 106.7447 | AW24: 109.34761 | AX24: 111.10877 | AY24: 111.5007 | AZ24: 111.95657 | BA24: 112.82515 | BB24: 112.8991 | BC24: 113.44733 | BD24: 114.12721 | BE24: 114.41877 | BF24: 115.54244 | BG24: 116.2357 | BH24: 116.93311 | BI24: 117.3138 | BJ24: 117.69572 | BK24: 118.07889 | BL24: 118.46331 | BM24: 120.28208 | BN24: 119.88914 | BO24: 119.95132 | BP24: 120.01353
A25: Japan | B25: =$A$2 -> IMF.RES.GAS:GAS_LIVE_2026_JAN_GAS1_VINTAGE | C25: JPN.NGDP_D.Q | E25: 97.070265 | F25: 96.584389 | G25: 96.460972 | H25: 96.476136 | I25: 96.233525 | J25: 96.240208 | K25: 96.342592 | L25: 96.388879 | M25: 96.367742 | N25: 98.382002 | O25: 98.376058 | P25: 98.652169 | Q25: 99.486907 | R25: 99.98055 | S25: 100.21182 | T25: 100.27486 | U25: 100.61077 | V25: 100.4257 | W25: 100.26145 | X25: 100.30711 | Y25: 100.10257 | Z25: 100.22725 | AA25: 100.54888 | AB25: 100.43975 | AC25: 100.65804 | AD25: 100.33949 | AE25: 100.21122 | AF25: 100.12699 | AG25: 100.83916 | AH25: 100.75854 | AI25: 100.6797 | AJ25: 101.60457 | AK25: 101.84114 | AL25: 102.15767 | AM25: 101.89474 | AN25: 101.80563 | AO25: 101.86193 | AP25: 101.76382 | AQ25: 101.71195 | AR25: 101.52707 | AS25: 102.10126 | AT25: 101.69081 | AU25: 101.56596 | AV25: 103.08846 | AW25: 104.46659 | AX25: 106.04078 | AY25: 107.04766 | AZ25: 107.49439 | BA25: 107.74117 | BB25: 109.32777 | BC25: 109.69186 | BD25: 110.48046 | BE25: 111.37989 | BF25: 112.55716 | BG25: 112.45689 | BH25: 113.14115 | BI25: 113.91158 | BJ25: 114.21446 | BK25: 114.79407 | BL25: 115.41097 | BM25: 116.50081 | BN25: 115.89615 | BO25: 117.17983 | BP25: 117.72632
A26: United Kingdom | B26: =$A$2 -> IMF.RES.GAS:GAS_LIVE_2026_JAN_GAS1_VINTAGE | C26: GBR.NGDP_D.Q | E26: 79.755777 | F26: 79.926382 | G26: 80.295871 | H26: 80.805986 | I26: 81.469179 | J26: 81.629695 | K26: 82.188168 | L26: 82.258613 | M26: 82.586979 | N26: 82.518044 | O26: 83.489269 | P26: 83.270292 | Q26: 83.401564 | R26: 83.222188 | S26: 83.488856 | T26: 83.944449 | U26: 84.412094 | V26: 84.628794 | W26: 85.481927 | X26: 86.085099 | Y26: 86.439118 | Z26: 86.539079 | AA26: 86.593151 | AB26: 87.361229 | AC26: 87.531992 | AD26: 88.142322 | AE26: 88.608602 | AF26: 89.316621 | AG26: 89.28734 | AH26: 90.151787 | AI26: 90.626937 | AJ26: 91.070765 | AK26: 91.925506 | AL26: 98.835749 | AM26: 94.873882 | AN26: 94.26498 | AO26: 95.319191 | AP26: 93.915616 | AQ26: 94.531886 | AR26: 95.595525 | AS26: 97.01136 | AT26: 99.082625 | AU26: 100.72408 | AV26: 103.15719 | AW26: 104.97093 | AX26: 106.78532 | AY26: 107.79787 | AZ26: 108.0027 | BA26: 109.31231 | BB26: 110.09974 | BC26: 112.06374 | BD26: 113.22026 | BE26: 114.08632 | BF26: 114.5656 | BG26: 115.75345 | BH26: 116.04751 | BI26: 116.98783 | BJ26: 117.48691 | BK26: 118.29428 | BL26: 118.39806 | BM26: 119.96314 | BN26: 120.48271 | BO26: 120.89089 | BP26: 120.79621
A27: Canada | B27: =$A$2 -> IMF.RES.GAS:GAS_LIVE_2026_JAN_GAS1_VINTAGE | C27: CAN.NGDP_D.Q | E27: 93.86621 | F27: 93.76124 | G27: 94.232892 | H27: 94.729153 | I27: 95.5577 | J27: 95.504013 | K27: 96.022293 | L27: 96.056137 | M27: 97.398525 | N27: 97.745286 | O27: 98.053386 | P27: 97.387675 | Q27: 96.491433 | R27: 96.785802 | S27: 97.215115 | T27: 96.704808 | U27: 96.461318 | V27: 97.125271 | W27: 97.724943 | X27: 98.64683 | Y27: 99.391987 | Z27: 99.386608 | AA27: 99.902651 | AB27: 101.30542 | AC27: 101.25257 | AD27: 101.97108 | AE27: 102.31461 | AF27: 101.06468 | AG27: 102.27806 | AH27: 103.12209 | AI27: 103.27013 | AJ27: 104.20466 | AK27: 103.46572 | AL27: 102.42901 | AM27: 104.63845 | AN27: 106.60416 | AO27: 109.30097 | AP27: 111.97786 | AQ27: 113.08817 | AR27: 115.31451 | AS27: 119.26197 | AT27: 123.05374 | AU27: 121.5442 | AV27: 121.48349 | AW27: 121.02042 | AX27: 121.66231 | AY27: 123.79169 | AZ27: 125.474 | BA27: 125.15038 | BB27: 126.45795 | BC27: 127.25297 | BD27: 128.40323 | BE27: 129.32259 | BF27: 129.33105 | BG27: 129.82731 | BH27: 130.97149 | BI27: 131.83827 | BJ27: 132.73126 | BK27: 133.24778 | BL27: 134.27047 | BM27: 134.40288 | BN27: 136.22087 | BO27: 136.75837 | BP27: 137.65255
A29: Trade prices (export price deflator)
A30: Manufactures -- advanced economies | B30: IMF.RES.GAS:GAS_LIVE | C30: G110.TXGM_D.Q | E30: 120.03021 | F30: 120.45004 | G30: 120.33303 | H30: 119.66854 | I30: 118.06417 | J30: 116.92465 | K30: 116.01368 | L30: 115.53901 | M30: 115.87867 | N30: 116.07994 | O30: 116.18506 | P30: 115.87508 | Q30: 114.92316 | R30: 113.46394 | S30: 111.66907 | T30: 109.85677 | U30: 107.9273 | V30: 106.85193 | W30: 106.26914 | X30: 106.09643 | Y30: 106.42513 | Z30: 106.69721 | AA30: 107.07538 | AB30: 107.54724 | AC30: 108.22604 | AD30: 108.85412 | AE30: 109.46234 | AF30: 109.92085 | AG30: 110.26688 | AH30: 110.03485 | AI30: 109.3855 | AJ30: 108.42053 | AK30: 106.65152 | AL30: 105.84715 | AM30: 105.65894 | AN30: 106.40312 | AO30: 108.46421 | AP30: 111.31999 | AQ30: 114.85982 | AR30: 118.54461 | AS30: 122.77399 | AT30: 125.01389 | AU30: 126.02441 | AV30: 125.89356 | AW30: 123.96072 | AX30: 122.88815 | AY30: 122.14034 | AZ30: 122.02144 | BA30: 122.9379 | BB30: 123.83525 | BC30: 124.74218 | BD30: 125.34257 | BE30: 125.41207 | BF30: 125.22356 | BG30: 124.91079 | BH30: 124.71045 | BI30: 124.77594 | BJ30: 125.01134 | BK30: 125.28656 | BL30: 125.42511 | BM30: 125.25583 | BN30: 124.99864 | BO30: 124.73287 | BP30: 124.64078 | BQ30: 124.86865 | BR30: 125.29486 | BS30: 125.8203 | BT30: 126.27298
A32: Commodity price indices (except otherwise indicated)
A33: All Commodity | B33: IMF.RES.GAS:GAS_LIVE | C33: G001.PZPIW.Q | E33: 181.14527 | F33: 171.19786 | G33: 169.51642 | H33: 168.83725 | I33: 170.84336 | J33: 164.57403 | K33: 165.55191 | L33: 163.22204 | M33: 166.64347 | N33: 168.83417 | O33: 159.68558 | P33: 137.23829 | Q33: 114.84102 | R33: 116.13376 | S33: 104.51828 | T33: 96.204646 | U33: 88.608385 | V33: 100.42844 | W33: 103.0411 | X33: 107.92207 | Y33: 114.28626 | Z33: 108.56009 | AA33: 111.11139 | AB33: 119.3449 | AC33: 126.96418 | AD33: 130.85981 | AE33: 129.68508 | AF33: 123.39229 | AG33: 118.38246 | AH33: 119.09151 | AI33: 114.49437 | AJ33: 116.12151 | AK33: 107.38361 | AL33: 92.218 | AM33: 106.62546 | AN33: 117.22979 | AO33: 138.65061 | AP33: 153.72815 | AQ33: 166.53283 | AR33: 187.09889 | AS33: 211.87047 | AT33: 228.74345 | AU33: 230.47578 | AV33: 192.57855 | AW33: 175.16617 | AX33: 160.65113 | AY33: 162.59512 | AZ33: 164.18059 | BA33: 160.3445 | BB33: 168.6069 | BC33: 163.85906 | BD33: 166.46059 | BE33: 170.72407 | BF33: 163.05038 | BG33: 165.14633 | BH33: 168.79878 | BI33: 179.92766 | BJ33: 181.47937 | BK33: 180.73817 | BL33: 180.61639 | BM33: 181.63023 | BN33: 179.4904 | BO33: 179.27896 | BP33: 180.22228
A34: Fuel | B34: IMF.RES.GAS:GAS_LIVE | C34: G001.PZPINRGW.Q | E34: 242.8439 | F34: 225.08664 | G34: 223.085 | H34: 221.46836 | I34: 227.32101 | J34: 218.75754 | K34: 229.53352 | L34: 227.90751 | M34: 229.46451 | N34: 230.69254 | O34: 216.90771 | P34: 172.21802 | Q34: 127.99715 | R34: 134.0564 | S34: 113.73049 | T34: 100.14445 | U34: 81.029943 | V34: 100.24013 | W34: 103.26084 | X34: 115.46909 | Y34: 123.07229 | Z34: 113.86479 | AA34: 118.15622 | AB34: 138.1095 | AC34: 149.10555 | AD34: 159.27654 | AE34: 166.749 | AF34: 151.00793 | AG34: 135.05368 | AH34: 134.13927 | AI34: 121.76935 | AJ34: 126.17762 | AK34: 102.80853 | AL34: 68.766525 | AM34: 90.313763 | AN34: 104.93075 | AO34: 139.41591 | AP34: 156.21544 | AQ34: 192.6785 | AR34: 244.04504 | AS34: 277.7365 | AT34: 311.77721 | AU34: 350.12389 | AV34: 258.40674 | AW34: 203.67138 | AX34: 175.80579 | AY34: 189.25055 | AZ34: 189.29235 | BA34: 175.57064 | BB34: 185.81748 | BC34: 179.36104 | BD34: 177.2656 | BE34: 181.50722 | BF34: 160.24527 | BG34: 160.39838 | BH34: 150.39757 | BI34: 157.76916 | BJ34: 156.44936 | BK34: 155.17385 | BL34: 155.09821 | BM34: 154.71809 | BN34: 148.00997 | BO34: 148.62901 | BP34: 150.90831
A35: Petroleum spot price (APSP; US$) | B35: IMF.RES.GAS:GAS_LIVE | C35: G001.PZPIOIL.Q | E35: 112.41666 | F35: 103.00314 | G35: 102.99068 | H35: 101.97598 | I35: 105.20577 | J35: 99.367262 | K35: 107.44797 | L35: 104.66626 | M35: 103.80442 | N35: 106.44512 | O35: 100.46671 | P35: 74.588258 | Q35: 51.848596 | R35: 60.516114 | S35: 49.019454 | T35: 42.263526 | U35: 33.138265 | V35: 45.288668 | W35: 45.107305 | X35: 49.52119 | Y35: 53.191376 | Z35: 49.663256 | AA35: 50.343225 | AB35: 58.712722 | AC35: 64.743638 | AD35: 71.646128 | AE35: 73.302796 | AF35: 64.437561 | AG35: 60.702674 | AH35: 64.98577 | AI35: 59.739889 | AJ35: 60.301003 | AK35: 49.096132 | AL35: 31.451852 | AM35: 42.312499 | AN35: 44.201508 | AO35: 59.648475 | AP35: 67.35089 | AQ35: 71.707374 | AR35: 78.293174 | AS35: 95.353101 | AT35: 109.42357 | AU35: 95.474348 | AV35: 85.197222 | AW35: 79.560982 | AX35: 76.476929 | AY35: 84.926467 | AZ35: 81.415253 | BA35: 80.851638 | BB35: 84.423473 | BC35: 78.249595 | BD35: 73.158495 | BE35: 74.517561 | BF35: 66.296647 | BG35: 67.998835 | BH35: 62.134092 | BI35: 65.467436 | BJ35: 65.632106 | BK35: 64.360508 | BL35: 63.513439 | BM35: 63.001375 | BN35: 62.857268 | BO35: 62.866186 | BP35: 62.984757
A36: Natural gas | B36: IMF.RES.GAS:GAS_LIVE | C36: G001.PZPINGASW.Q | E36: 205.11234 | F36: 211.54948 | G36: 208.83975 | H36: 210.43333 | I36: 212.83817 | J36: 218.31395 | K36: 206.60483 | L36: 210.42508 | M36: 224.40682 | N36: 220.28925 | O36: 202.40896 | P36: 201.34548 | Q36: 172.98703 | R36: 135.18634 | S36: 130.35284 | T36: 119.01369 | U36: 98.199632 | V36: 90.752543 | W36: 101.41468 | X36: 109.63314 | Y36: 117.30493 | Z36: 104.8572 | AA36: 109.3018 | AB36: 132.07446 | AC36: 141.52086 | AD36: 132.8416 | AE36: 149.13802 | AF36: 154.82683 | AG36: 114.13851 | AH36: 87.050406 | AI36: 76.341962 | AJ36: 88.572449 | AK36: 65.048036 | AL36: 45.479157 | AM36: 64.224897 | AN36: 112.10468 | AO36: 136.69349 | AP36: 151.43635 | AQ36: 265.88276 | AR36: 460.68374 | AS36: 445.59039 | AT36: 453.80333 | AU36: 762.35354 | AV36: 424.56681 | AW36: 239.76338 | AX36: 164.89469 | AY36: 169.29397 | AZ36: 201.48212 | BA36: 135.54182 | BB36: 156.56951 | BC36: 173.66423 | BD36: 203.95126 | BE36: 223.71651 | BF36: 190.55182 | BG36: 177.86444 | BH36: 179.2269 | BI36: 178.33355 | BJ36: 171.58421 | BK36: 175.38663 | BL36: 181.88553 | BM36: 184.0272 | BN36: 150.52586 | BO36: 152.89809 | BP36: 161.43272
A37: Coal | B37: IMF.RES.GAS:GAS_LIVE | C37: G001.PZPICLW.Q | E37: 167.57347 | F37: 145.43636 | G37: 134.00529 | H37: 130.98505 | I37: 135.79715 | J37: 128.02544 | K37: 115.58627 | L37: 127.19707 | M37: 120.43406 | N37: 114.14747 | O37: 106.64203 | P37: 99.37082 | Q37: 96.084995 | R37: 92.728663 | S37: 87.193528 | T37: 80.172817 | U37: 79.196418 | V37: 81.869332 | W37: 101.18721 | X37: 137.74704 | Y37: 126.73339 | Z37: 119.8138 | AA37: 138.40422 | AB37: 146.00437 | AC37: 151.36715 | AD37: 156.56725 | AE37: 166.96863 | AF37: 152.26231 | AG37: 136.35597 | AH37: 111.99523 | AI37: 98.605194 | AJ37: 108.86301 | AK37: 111.69043 | AL37: 83.195327 | AM37: 79.886997 | AN37: 104.61115 | AO37: 136.7959 | AP37: 160.62722 | AQ37: 232.39691 | AR37: 269.93649 | AS37: 388.02049 | AT37: 527.00989 | AU37: 567.31841 | AV37: 455.66913 | AW37: 313.64136 | AX37: 210.35237 | AY37: 196.09792 | AZ37: 191.14164 | BA37: 170.46401 | BB37: 185.3403 | BC37: 190.60199 | BD37: 190.39781 | BE37: 154.10621 | BF37: 144.44369 | BG37: 151.54753 | BH37: 147.51266 | BI37: 167.46995 | BJ37: 162.65316 | BK37: 163.38376 | BL37: 164.02801 | BM37: 164.53584 | BN37: 163.89399 | BO37: 165.94423 | BP37: 172.11737
A38: Propane
A39: Nonfuel | B39: IMF.RES.GAS:GAS_LIVE | C39: G001.PZPINFW.Q | E39: 132.16131 | F39: 128.41432 | G39: 129.98594 | H39: 129.99858 | I39: 129.16616 | J39: 124.58978 | K39: 118.33724 | L39: 115.48796 | M39: 120.28523 | N39: 123.18632 | O39: 117.459 | P39: 111.4253 | Q39: 105.74571 | R39: 103.74319 | S39: 98.149543 | T39: 93.480918 | U39: 93.847636 | V39: 100.55863 | W39: 102.88919 | X39: 102.70454 | Y39: 108.21216 | Z39: 104.89276 | AA39: 106.24105 | AB39: 106.37225 | AC39: 111.65705 | AD39: 111.21429 | AE39: 104.06144 | AF39: 104.3006 | AG39: 106.85704 | AH39: 108.68845 | AI39: 109.46491 | AJ39: 109.16935 | AK39: 110.54653 | AL39: 108.43085 | AM39: 117.90232 | AN39: 125.73256 | AO39: 138.12153 | AP39: 152.00859 | AQ39: 148.45738 | AR39: 147.72996 | AS39: 166.3349 | AT39: 171.33921 | AU39: 147.75871 | AV39: 147.06915 | AW39: 155.4595 | AX39: 150.17416 | AY39: 144.16727 | AZ39: 146.81992 | BA39: 149.81811 | BB39: 156.70861 | BC39: 153.14197 | BD39: 158.99069 | BE39: 163.26929 | BF39: 164.98965 | BG39: 168.42875 | BH39: 181.5202 | BI39: 195.24663 | BJ39: 198.78352 | BK39: 198.41171 | BL39: 198.25804 | BM39: 200.23557 | BN39: 201.56335 | BO39: 200.77447 | BP39: 200.79425
A40: Food | B40: IMF.RES.GAS:GAS_LIVE | C40: G001.PZPIFW.Q | E40: 119.15155 | F40: 117.45989 | G40: 123.57622 | H40: 120.89542 | I40: 121.69744 | J40: 125.0627 | K40: 119.11932 | L40: 115.97952 | M40: 122.2892 | N40: 126.18476 | O40: 115.4001 | P40: 110.55776 | Q40: 101.79566 | R40: 100.60112 | S40: 97.833033 | T40: 93.972154 | U40: 94.271839 | V40: 101.7083 | W40: 102.56313 | X40: 101.45673 | Y40: 105.64111 | Z40: 104.13755 | AA40: 103.22624 | AB40: 102.05009 | AC40: 106.16362 | AD40: 106.40358 | AE40: 99.097788 | AF40: 98.327504 | AG40: 99.124545 | AH40: 99.944002 | AI40: 98.188328 | AJ40: 100.2097 | AK40: 101.27534 | AL40: 96.413059 | AM40: 98.723 | AN40: 107.92975 | AO40: 119.73265 | AP40: 131.76672 | AQ40: 129.80133 | AR40: 132.15801 | AS40: 150.49857 | AT40: 161.49221 | AU40: 140.03082 | AV40: 137.58855 | AW40: 142.40391 | AX40: 140.27353 | AY40: 133.02026 | AZ40: 134.01358 | BA40: 135.21307 | BB40: 135.31333 | BC40: 129.24169 | BD40: 132.78055 | BE40: 132.15977 | BF40: 126.75014 | BG40: 125.50523 | BH40: 123.84439 | BI40: 126.98048 | BJ40: 133.92533 | BK40: 131.37672 | BL40: 129.67509 | BM40: 132.63836 | BN40: 133.60241 | BO40: 130.75409 | BP40: 130.00338
A41: Beverages | B41: IMF.RES.GAS:GAS_LIVE | C41: G001.PZPIBEVW.Q | E41: 111.27697 | F41: 103.85914 | G41: 108.06683 | H41: 101.92771 | I41: 97.566147 | J41: 93.206315 | K41: 90.449409 | L41: 87.944686 | M41: 103.89683 | N41: 113.97999 | O41: 114.1418 | P41: 113.21275 | Q41: 105.50829 | R41: 102.60067 | S41: 103.0716 | T41: 100.9826 | U41: 93.38134 | V41: 97.830305 | W41: 104.00243 | X41: 104.78592 | Y41: 102.06722 | Z41: 95.972163 | AA41: 96.249517 | AB41: 90.53807 | AC41: 89.720745 | AD41: 91.279411 | AE41: 83.45079 | AF41: 84.851651 | AG41: 82.423688 | AH41: 80.662824 | AI41: 81.020514 | AJ41: 85.341227 | AK41: 84.911352 | AL41: 81.170297 | AM41: 85.962295 | AN41: 85.461831 | AO41: 89.004495 | AP41: 93.971053 | AQ41: 108.2616 | AR41: 122.01294 | AS41: 124.15053 | AT41: 119.81044 | AU41: 119.22664 | AV41: 108.47635 | AW41: 112.30988 | AX41: 122.96535 | AY41: 123.70794 | AZ41: 131.5356 | BA41: 161.44855 | BB41: 207.8829 | BC41: 206.07124 | BD41: 230.76864 | BE41: 267.20273 | BF41: 245.92422 | BG41: 217.70982 | BH41: 215.67499 | BI41: 183.31752 | BJ41: 170.9643 | BK41: 168.23483 | BL41: 165.92 | BM41: 164.19378 | BN41: 162.77631 | BO41: 161.44512 | BP41: 160.39104
A42: Agricultural raw materials | B42: IMF.RES.GAS:GAS_LIVE | C42: G001.PZPIRAW.Q | E42: 136.69638 | F42: 131.49743 | G42: 122.01124 | H42: 123.36946 | I42: 125.23646 | J42: 124.95402 | K42: 119.52231 | L42: 119.29315 | M42: 119.29124 | N42: 117.42837 | O42: 109.78593 | P42: 105.10042 | Q42: 104.09474 | R42: 104.66654 | S42: 97.545961 | T42: 94.406891 | U42: 94.569023 | V42: 100.58052 | W42: 101.84791 | X42: 103.00255 | Y42: 109.68414 | Z42: 106.63968 | AA42: 103.00232 | AB42: 102.20801 | AC42: 110.31557 | AD42: 110.1888 | AE42: 106.63199 | AF42: 102.82649 | AG42: 104.5209 | AH42: 105.26022 | AI42: 98.754405 | AJ42: 98.111809 | AK42: 98.870199 | AL42: 91.973478 | AM42: 95.308471 | AN42: 106.61854 | AO42: 112.06542 | AP42: 116.91769 | AQ42: 110.33635 | AR42: 114.20581 | AS42: 125.33964 | AT42: 132.83885 | AU42: 115.9734 | AV42: 105.41971 | AW42: 102.61115 | AX42: 100.77347 | AY42: 101.20746 | AZ42: 100.35358 | BA42: 108.13034 | BB42: 104.9274 | BC42: 104.64533 | BD42: 104.73033 | BE42: 104.70965 | BF42: 104.771 | BG42: 104.27878 | BH42: 100.44242 | BI42: 97.123861 | BJ42: 98.854746 | BK42: 99.72191 | BL42: 100.58986 | BM42: 101.27507 | BN42: 101.4597 | BO42: 101.56644 | BP42: 101.20295
A43: Metals | B43: IMF.RES.GAS:GAS_LIVE | C43: G001.PZPIMETW.Q | E43: 160.21553 | F43: 149.12728 | G43: 143.56007 | H43: 147.30975 | I43: 148.65162 | J43: 134.94337 | K43: 131.09004 | L43: 132.01451 | M43: 131.9759 | N43: 138.97013 | O43: 143.61827 | P43: 132.23173 | Q43: 116.43546 | R43: 113.35143 | S43: 101.19707 | T43: 91.434035 | U43: 90.500302 | V43: 96.636712 | W43: 100.89639 | X43: 111.9666 | Y43: 125.76864 | Z43: 112.80588 | AA43: 123.43509 | AB43: 126.74514 | AC43: 135.56567 | AD43: 134.51856 | AE43: 125.5108 | AF43: 125.55426 | AG43: 131.94421 | AH43: 140.0887 | AI43: 138.60658 | AJ43: 130.64184 | AK43: 126.76468 | AL43: 123.18215 | AM43: 147.01824 | AN43: 163.07507 | AO43: 193.60174 | AP43: 224.86068 | AQ43: 214.14888 | AR43: 189.03887 | AS43: 219.65549 | AT43: 213.26142 | AU43: 171.02276 | AV43: 171.64084 | AW43: 203.83515 | AX43: 184.23023 | AY43: 179.60958 | AZ43: 186.51532 | BA43: 184.56476 | BB43: 192.18493 | BC43: 179.17448 | BD43: 183.87374 | BE43: 184.93137 | BF43: 178.55897 | BG43: 187.19074 | BH43: 204.6207 | BI43: 218.61573 | BJ43: 217.0214 | BK43: 217.28745 | BL43: 217.04998 | BM43: 216.72058 | BN43: 216.78931 | BO43: 216.63311 | BP43: 216.32412
A45: Agriculture | B45: IMF.RES.GAS:GAS_LIVE | C45: G001.PZPIAGRW.Q | E45: 121.02891 | F45: 118.46647 | G45: 122.32061 | H45: 119.92495 | I45: 120.5132 | J45: 122.88366 | K45: 117.22273 | L45: 114.50095 | M45: 120.65311 | N45: 124.22758 | O45: 114.59155 | P45: 110.03536 | Q45: 102.34408 | R45: 101.26059 | S45: 98.152089 | T45: 94.504591 | U45: 94.249592 | V45: 101.2995 | W45: 102.56884 | X45: 101.88207 | Y45: 105.91891 | Z45: 103.90485 | AA45: 102.72325 | AB45: 101.28804 | AC45: 105.58083 | AD45: 105.86319 | AE45: 99.004687 | AF45: 97.991062 | AG45: 98.684494 | AH45: 99.318265 | AI45: 97.094461 | AJ45: 98.929016 | AK45: 99.853445 | AL45: 94.805358 | AM45: 97.416001 | AN45: 106.2339 | AO45: 116.65684 | AP45: 127.28566 | AQ45: 125.83059 | AR45: 129.15651 | AS45: 145.46773 | AT45: 154.96921 | AU45: 135.51862 | AV45: 131.46707 | AW45: 135.23383 | AX45: 134.01011 | AY45: 128.29028 | AZ45: 129.51019 | BA45: 133.50819 | BB45: 136.33202 | BC45: 131.29552 | BD45: 135.82756 | BE45: 137.80241 | BF45: 132.01888 | BG45: 129.038 | BH45: 127.07156 | BI45: 126.96414 | BJ45: 131.92595 | BK45: 129.80495 | BL45: 128.39258 | BM45: 130.74376 | BN45: 131.40393 | BO45: 129.05978 | BP45: 128.34372
...

Sheet Sheet1
