Workbook
Name GEE_ALL: Annual!$X$79:$BB$91
Name GEE_ALL: #REF!
Name WEOGEE_Rwametric_Qdata: Quarterly!$D$79:$CD$91
Name WEOGEE_Rwametric_Qdata: #REF!

Sheet Definitions
A2: Rwanda
A3: Advanced economy partners
A5: Real GDP | B5: Real GDP, 2005=100, Weighted by trade exports to advanced economies. Source of the Real GDP is desk submitted data for Real GDP (NGDP_R). | C5: Real GDP, 2005=100, Weighted by trade exports to advanced economies. Source of the Real GDP is desk submitted data for Real GDP (NGDP_R). | D5: Real GDP, 2005=100, Weighted by trade exports to advanced economies. Source of the Real GDP is desk submitted data for Real GDP (NGDP_R). | E5: Real GDP, 2005=100, Weighted by trade exports to advanced economies. Source of the Real GDP is desk submitted data for Real GDP (NGDP_R). | F5: Real GDP, 2005=100, Weighted by trade exports to advanced economies. Source of the Real GDP is desk submitted data for Real GDP (NGDP_R). | G5: Real GDP, 2005=100, Weighted by trade exports to advanced economies. Source of the Real GDP is desk submitted data for Real GDP (NGDP_R). | H5: Real GDP, 2005=100, Weighted by trade exports to advanced economies. Source of the Real GDP is desk submitted data for Real GDP (NGDP_R). | I5: Real GDP, 2005=100, Weighted by trade exports to advanced economies. Source of the Real GDP is desk submitted data for Real GDP (NGDP_R). | J5: Real GDP, 2005=100, Weighted by trade exports to advanced economies. Source of the Real GDP is desk submitted data for Real GDP (NGDP_R). | K5: Real GDP, 2005=100, Weighted by trade exports to advanced economies. Source of the Real GDP is desk submitted data for Real GDP (NGDP_R).
A6: Real total dometic demand | B6: Real total domestic demand, 2005=100, Weighted by trade exports to advanced economies. Source of the Real total domestic demand is desk submitted data for (NTDD_R). | C6: Real total domestic demand, 2005=100, Weighted by trade exports to advanced economies. Source of the Real total domestic demand is desk submitted data for (NTDD_R). | D6: Real total domestic demand, 2005=100, Weighted by trade exports to advanced economies. Source of the Real total domestic demand is desk submitted data for (NTDD_R). | E6: Real total domestic demand, 2005=100, Weighted by trade exports to advanced economies. Source of the Real total domestic demand is desk submitted data for (NTDD_R). | F6: Real total domestic demand, 2005=100, Weighted by trade exports to advanced economies. Source of the Real total domestic demand is desk submitted data for (NTDD_R). | G6: Real total domestic demand, 2005=100, Weighted by trade exports to advanced economies. Source of the Real total domestic demand is desk submitted data for (NTDD_R). | H6: Real total domestic demand, 2005=100, Weighted by trade exports to advanced economies. Source of the Real total domestic demand is desk submitted data for (NTDD_R). | I6: Real total domestic demand, 2005=100, Weighted by trade exports to advanced economies. Source of the Real total domestic demand is desk submitted data for (NTDD_R). | J6: Real total domestic demand, 2005=100, Weighted by trade exports to advanced economies. Source of the Real total domestic demand is desk submitted data for (NTDD_R). | K6: Real total domestic demand, 2005=100, Weighted by trade exports to advanced economies. Source of the Real total domestic demand is desk submitted data for (NTDD_R). | L6: Real total domestic demand, 2005=100, Weighted by trade exports to advanced economies. Source of the Real total domestic demand is desk submitted data for (NTDD_R). | M6: Real total domestic demand, 2005=100, Weighted by trade exports to advanced economies. Source of the Real total domestic demand is desk submitted data for (NTDD_R).
A8: All countries
A10: Real GDP | B10: Real GDP, 2005=100, Weighted by trade exports to all partner countries. Source of the Real GDP is desk submitted data for Real GDP (NGDP_R). | C10: Real GDP, 2005=100, Weighted by trade exports to all partner countries. Source of the Real GDP is desk submitted data for Real GDP (NGDP_R). | D10: Real GDP, 2005=100, Weighted by trade exports to all partner countries. Source of the Real GDP is desk submitted data for Real GDP (NGDP_R). | E10: Real GDP, 2005=100, Weighted by trade exports to all partner countries. Source of the Real GDP is desk submitted data for Real GDP (NGDP_R). | F10: Real GDP, 2005=100, Weighted by trade exports to all partner countries. Source of the Real GDP is desk submitted data for Real GDP (NGDP_R). | G10: Real GDP, 2005=100, Weighted by trade exports to all partner countries. Source of the Real GDP is desk submitted data for Real GDP (NGDP_R). | H10: Real GDP, 2005=100, Weighted by trade exports to all partner countries. Source of the Real GDP is desk submitted data for Real GDP (NGDP_R). | I10: Real GDP, 2005=100, Weighted by trade exports to all partner countries. Source of the Real GDP is desk submitted data for Real GDP (NGDP_R). | J10: Real GDP, 2005=100, Weighted by trade exports to all partner countries. Source of the Real GDP is desk submitted data for Real GDP (NGDP_R). | K10: Real GDP, 2005=100, Weighted by trade exports to all partner countries. Source of the Real GDP is desk submitted data for Real GDP (NGDP_R).
A11: Real imports
A12: Goods and services | B12: Imports volume of goods and services, 2005=100, Weighted by trade exports to all partner countries. Source of the Volume of total imports of goods and services (TM_R) is desk submitted data.
A13: Goods | B13: Imports volume of goods, 2005=100, Weighted by trade exports to all partner countries. Source of the Volume of imports of goods (TMG_R) is desk submitted data. | C13: Imports volume of goods, 2005=100, Weighted by trade exports to all partner countries. Source of the Volume of imports of goods (TMG_R) is desk submitted data. | D13: Imports volume of goods, 2005=100, Weighted by trade exports to all partner countries. Source of the Volume of imports of goods (TMG_R) is desk submitted data. | E13: Imports volume of goods, 2005=100, Weighted by trade exports to all partner countries. Source of the Volume of imports of goods (TMG_R) is desk submitted data. | F13: Imports volume of goods, 2005=100, Weighted by trade exports to all partner countries. Source of the Volume of imports of goods (TMG_R) is desk submitted data. | G13: Imports volume of goods, 2005=100, Weighted by trade exports to all partner countries. Source of the Volume of imports of goods (TMG_R) is desk submitted data. | H13: Imports volume of goods, 2005=100, Weighted by trade exports to all partner countries. Source of the Volume of imports of goods (TMG_R) is desk submitted data. | I13: Imports volume of goods, 2005=100, Weighted by trade exports to all partner countries. Source of the Volume of imports of goods (TMG_R) is desk submitted data. | J13: Imports volume of goods, 2005=100, Weighted by trade exports to all partner countries. Source of the Volume of imports of goods (TMG_R) is desk submitted data. | K13: Imports volume of goods, 2005=100, Weighted by trade exports to all partner countries. Source of the Volume of imports of goods (TMG_R) is desk submitted data. | L13: Imports volume of goods, 2005=100, Weighted by trade exports to all partner countries. Source of the Volume of imports of goods (TMG_R) is desk submitted data.
A14: Excluding oil | B14: Imports volume of goods excl. oil, 2005=100, Weighted by trade exports to all partner countries. The Volume of non-oil imports is calculated by TMG_R-TMGO_R which are provided by desk. | C14: Imports volume of goods excl. oil, 2005=100, Weighted by trade exports to all partner countries. The Volume of non-oil imports is calculated by TMG_R-TMGO_R which are provided by desk. | D14: Imports volume of goods excl. oil, 2005=100, Weighted by trade exports to all partner countries. The Volume of non-oil imports is calculated by TMG_R-TMGO_R which are provided by desk. | E14: Imports volume of goods excl. oil, 2005=100, Weighted by trade exports to all partner countries. The Volume of non-oil imports is calculated by TMG_R-TMGO_R which are provided by desk. | F14: Imports volume of goods excl. oil, 2005=100, Weighted by trade exports to all partner countries. The Volume of non-oil imports is calculated by TMG_R-TMGO_R which are provided by desk. | G14: Imports volume of goods excl. oil, 2005=100, Weighted by trade exports to all partner countries. The Volume of non-oil imports is calculated by TMG_R-TMGO_R which are provided by desk. | H14: Imports volume of goods excl. oil, 2005=100, Weighted by trade exports to all partner countries. The Volume of non-oil imports is calculated by TMG_R-TMGO_R which are provided by desk. | I14: Imports volume of goods excl. oil, 2005=100, Weighted by trade exports to all partner countries. The Volume of non-oil imports is calculated by TMG_R-TMGO_R which are provided by desk. | J14: Imports volume of goods excl. oil, 2005=100, Weighted by trade exports to all partner countries. The Volume of non-oil imports is calculated by TMG_R-TMGO_R which are provided by desk. | K14: Imports volume of goods excl. oil, 2005=100, Weighted by trade exports to all partner countries. The Volume of non-oil imports is calculated by TMG_R-TMGO_R which are provided by desk. | L14: Imports volume of goods excl. oil, 2005=100, Weighted by trade exports to all partner countries. The Volume of non-oil imports is calculated by TMG_R-TMGO_R which are provided by desk. | M14: Imports volume of goods excl. oil, 2005=100, Weighted by trade exports to all partner countries. The Volume of non-oil imports is calculated by TMG_R-TMGO_R which are provided by desk. | N14: Imports volume of goods excl. oil, 2005=100, Weighted by trade exports to all partner countries. The Volume of non-oil imports is calculated by TMG_R-TMGO_R which are provided by desk. | O14: Imports volume of goods excl. oil, 2005=100, Weighted by trade exports to all partner countries. The Volume of non-oil imports is calculated by TMG_R-TMGO_R which are provided by desk.
A16: Real exports
A17: Goods and services | B17: Exports volume of goods and services, 2005=100, Weighted by trade imports from all partner countries. Source of the Volume of total exports of goods and services (TX_R) is desk submitted data.
A18: Goods | B18: Exports volume of goods, 2005=100, Weighted by trade imports from all partner countries. Source of the Volume of exports of goods (TXG_R) is desk submitted data. | C18: Imports volume of goods, 2005=100, Weighted by trade exports to all partner countries. Source of the Volume of imports of goods (TMG_R) is desk submitted data. | D18: Imports volume of goods, 2005=100, Weighted by trade exports to all partner countries. Source of the Volume of imports of goods (TMG_R) is desk submitted data. | E18: Imports volume of goods, 2005=100, Weighted by trade exports to all partner countries. Source of the Volume of imports of goods (TMG_R) is desk submitted data. | F18: Imports volume of goods, 2005=100, Weighted by trade exports to all partner countries. Source of the Volume of imports of goods (TMG_R) is desk submitted data. | G18: Imports volume of goods, 2005=100, Weighted by trade exports to all partner countries. Source of the Volume of imports of goods (TMG_R) is desk submitted data. | H18: Imports volume of goods, 2005=100, Weighted by trade exports to all partner countries. Source of the Volume of imports of goods (TMG_R) is desk submitted data. | I18: Imports volume of goods, 2005=100, Weighted by trade exports to all partner countries. Source of the Volume of imports of goods (TMG_R) is desk submitted data. | J18: Imports volume of goods, 2005=100, Weighted by trade exports to all partner countries. Source of the Volume of imports of goods (TMG_R) is desk submitted data. | K18: Imports volume of goods, 2005=100, Weighted by trade exports to all partner countries. Source of the Volume of imports of goods (TMG_R) is desk submitted data. | L18: Imports volume of goods, 2005=100, Weighted by trade exports to all partner countries. Source of the Volume of imports of goods (TMG_R) is desk submitted data.
A19: Excluding oil | B19: Exports volume of goods excl. oil, 2005=100, Weighted by trade imports from all partner countries. The Volume of non-oil imports is calculated by TXG_R-TMGO_R which are provided by desk. | C19: Imports volume of goods excl. oil, 2005=100, Weighted by trade exports to all partner countries. The Volume of non-oil imports is calculated by TMG_R-TMGO_R which are provided by desk. | D19: Imports volume of goods excl. oil, 2005=100, Weighted by trade exports to all partner countries. The Volume of non-oil imports is calculated by TMG_R-TMGO_R which are provided by desk. | E19: Imports volume of goods excl. oil, 2005=100, Weighted by trade exports to all partner countries. The Volume of non-oil imports is calculated by TMG_R-TMGO_R which are provided by desk. | F19: Imports volume of goods excl. oil, 2005=100, Weighted by trade exports to all partner countries. The Volume of non-oil imports is calculated by TMG_R-TMGO_R which are provided by desk. | G19: Imports volume of goods excl. oil, 2005=100, Weighted by trade exports to all partner countries. The Volume of non-oil imports is calculated by TMG_R-TMGO_R which are provided by desk. | H19: Imports volume of goods excl. oil, 2005=100, Weighted by trade exports to all partner countries. The Volume of non-oil imports is calculated by TMG_R-TMGO_R which are provided by desk. | I19: Imports volume of goods excl. oil, 2005=100, Weighted by trade exports to all partner countries. The Volume of non-oil imports is calculated by TMG_R-TMGO_R which are provided by desk. | J19: Imports volume of goods excl. oil, 2005=100, Weighted by trade exports to all partner countries. The Volume of non-oil imports is calculated by TMG_R-TMGO_R which are provided by desk. | K19: Imports volume of goods excl. oil, 2005=100, Weighted by trade exports to all partner countries. The Volume of non-oil imports is calculated by TMG_R-TMGO_R which are provided by desk. | L19: Imports volume of goods excl. oil, 2005=100, Weighted by trade exports to all partner countries. The Volume of non-oil imports is calculated by TMG_R-TMGO_R which are provided by desk. | M19: Imports volume of goods excl. oil, 2005=100, Weighted by trade exports to all partner countries. The Volume of non-oil imports is calculated by TMG_R-TMGO_R which are provided by desk. | N19: Imports volume of goods excl. oil, 2005=100, Weighted by trade exports to all partner countries. The Volume of non-oil imports is calculated by TMG_R-TMGO_R which are provided by desk. | O19: Imports volume of goods excl. oil, 2005=100, Weighted by trade exports to all partner countries. The Volume of non-oil imports is calculated by TMG_R-TMGO_R which are provided by desk.
A22: Foreign Prices and Costs | B22: Foreign Prices and Costs | C22: Foreign Prices and Costs | D22: Foreign Prices and Costs | E22: Foreign Prices and Costs | F22: Foreign Prices and Costs | G22: Foreign Prices and Costs | H22: Foreign Prices and Costs | I22: Foreign Prices and Costs | J22: Foreign Prices and Costs | K22: Foreign Prices and Costs | L22: Foreign Prices and Costs | M22: Foreign Prices and Costs | N22: Foreign Prices and Costs | O22: Foreign Prices and Costs
A23: Advanced economy partners
A25: GDP deflators
A26: In national currency | B26: GDP deflator, 2005=100, Weighted by trade imports from advanced economies. Source of the GDP deflator is desk submitted data for Nominal GDP (NGDP) divided by Real GDP (NGDP_R). | C26: GDP deflator, 2005=100, Weighted by trade imports from advanced economies. Source of the GDP deflator is desk submitted data for Nominal GDP (NGDP) divided by Real GDP (NGDP_R). | D26: GDP deflator, 2005=100, Weighted by trade imports from advanced economies. Source of the GDP deflator is desk submitted data for Nominal GDP (NGDP) divided by Real GDP (NGDP_R). | E26: GDP deflator, 2005=100, Weighted by trade imports from advanced economies. Source of the GDP deflator is desk submitted data for Nominal GDP (NGDP) divided by Real GDP (NGDP_R). | F26: GDP deflator, 2005=100, Weighted by trade imports from advanced economies. Source of the GDP deflator is desk submitted data for Nominal GDP (NGDP) divided by Real GDP (NGDP_R). | G26: GDP deflator, 2005=100, Weighted by trade imports from advanced economies. Source of the GDP deflator is desk submitted data for Nominal GDP (NGDP) divided by Real GDP (NGDP_R). | H26: GDP deflator, 2005=100, Weighted by trade imports from advanced economies. Source of the GDP deflator is desk submitted data for Nominal GDP (NGDP) divided by Real GDP (NGDP_R). | I26: GDP deflator, 2005=100, Weighted by trade imports from advanced economies. Source of the GDP deflator is desk submitted data for Nominal GDP (NGDP) divided by Real GDP (NGDP_R). | J26: GDP deflator, 2005=100, Weighted by trade imports from advanced economies. Source of the GDP deflator is desk submitted data for Nominal GDP (NGDP) divided by Real GDP (NGDP_R). | K26: GDP deflator, 2005=100, Weighted by trade imports from advanced economies. Source of the GDP deflator is desk submitted data for Nominal GDP (NGDP) divided by Real GDP (NGDP_R). | L26: GDP deflator, 2005=100, Weighted by trade imports from advanced economies. Source of the GDP deflator is desk submitted data for Nominal GDP (NGDP) divided by Real GDP (NGDP_R). | M26: GDP deflator, 2005=100, Weighted by trade imports from advanced economies. Source of the GDP deflator is desk submitted data for Nominal GDP (NGDP) divided by Real GDP (NGDP_R). | N26: GDP deflator, 2005=100, Weighted by trade imports from advanced economies. Source of the GDP deflator is desk submitted data for Nominal GDP (NGDP) divided by Real GDP (NGDP_R).
A27: In U.S. dollars | B27: GDP deflator, US$, 2005=100, Weighted by trade imports from advanced economies. Source of the GDP deflator is desk submitted data for Nominal GDP (NGDP) divided by Real GDP (NGDP_R) converted to US$. | C27: GDP deflator, US$, 2005=100, Weighted by trade imports from advanced economies. Source of the GDP deflator is desk submitted data for Nominal GDP (NGDP) divided by Real GDP (NGDP_R) converted to US$. | D27: GDP deflator, US$, 2005=100, Weighted by trade imports from advanced economies. Source of the GDP deflator is desk submitted data for Nominal GDP (NGDP) divided by Real GDP (NGDP_R) converted to US$. | E27: GDP deflator, US$, 2005=100, Weighted by trade imports from advanced economies. Source of the GDP deflator is desk submitted data for Nominal GDP (NGDP) divided by Real GDP (NGDP_R) converted to US$. | F27: GDP deflator, US$, 2005=100, Weighted by trade imports from advanced economies. Source of the GDP deflator is desk submitted data for Nominal GDP (NGDP) divided by Real GDP (NGDP_R) converted to US$. | G27: GDP deflator, US$, 2005=100, Weighted by trade imports from advanced economies. Source of the GDP deflator is desk submitted data for Nominal GDP (NGDP) divided by Real GDP (NGDP_R) converted to US$. | H27: GDP deflator, US$, 2005=100, Weighted by trade imports from advanced economies. Source of the GDP deflator is desk submitted data for Nominal GDP (NGDP) divided by Real GDP (NGDP_R) converted to US$. | I27: GDP deflator, US$, 2005=100, Weighted by trade imports from advanced economies. Source of the GDP deflator is desk submitted data for Nominal GDP (NGDP) divided by Real GDP (NGDP_R) converted to US$. | J27: GDP deflator, US$, 2005=100, Weighted by trade imports from advanced economies. Source of the GDP deflator is desk submitted data for Nominal GDP (NGDP) divided by Real GDP (NGDP_R) converted to US$. | K27: GDP deflator, US$, 2005=100, Weighted by trade imports from advanced economies. Source of the GDP deflator is desk submitted data for Nominal GDP (NGDP) divided by Real GDP (NGDP_R) converted to US$. | L27: GDP deflator, US$, 2005=100, Weighted by trade imports from advanced economies. Source of the GDP deflator is desk submitted data for Nominal GDP (NGDP) divided by Real GDP (NGDP_R) converted to US$. | M27: GDP deflator, US$, 2005=100, Weighted by trade imports from advanced economies. Source of the GDP deflator is desk submitted data for Nominal GDP (NGDP) divided by Real GDP (NGDP_R) converted to US$. | N27: GDP deflator, US$, 2005=100, Weighted by trade imports from advanced economies. Source of the GDP deflator is desk submitted data for Nominal GDP (NGDP) divided by Real GDP (NGDP_R) converted to US$. | O27: GDP deflator, US$, 2005=100, Weighted by trade imports from advanced economies. Source of the GDP deflator is desk submitted data for Nominal GDP (NGDP) divided by Real GDP (NGDP_R) converted to US$.
A29: Consumer prices
A30: In national currency | B30: CPI, 2005=100, Weighted by trade imports from advanced economies. Source of the consumer price index is desk submitted data (PCPI). | C30: CPI, 2005=100, Weighted by trade imports from advanced economies. Source of the consumer price index is desk submitted data (PCPI). | D30: CPI, 2005=100, Weighted by trade imports from advanced economies. Source of the consumer price index is desk submitted data (PCPI). | E30: CPI, 2005=100, Weighted by trade imports from advanced economies. Source of the consumer price index is desk submitted data (PCPI). | F30: CPI, 2005=100, Weighted by trade imports from advanced economies. Source of the consumer price index is desk submitted data (PCPI). | G30: CPI, 2005=100, Weighted by trade imports from advanced economies. Source of the consumer price index is desk submitted data (PCPI). | H30: CPI, 2005=100, Weighted by trade imports from advanced economies. Source of the consumer price index is desk submitted data (PCPI). | I30: CPI, 2005=100, Weighted by trade imports from advanced economies. Source of the consumer price index is desk submitted data (PCPI). | J30: CPI, 2005=100, Weighted by trade imports from advanced economies. Source of the consumer price index is desk submitted data (PCPI).
A31: In U.S. dollars | B31: CPI, US$, 2005=100, Weighted by trade imports from advanced economies. Source of the consumer price index is desk submitted data (PCPI) converted to US$. | C31: CPI, US$, 2005=100, Weighted by trade imports from advanced economies. Source of the consumer price index is desk submitted data (PCPI) converted to US$. | D31: CPI, US$, 2005=100, Weighted by trade imports from advanced economies. Source of the consumer price index is desk submitted data (PCPI) converted to US$. | E31: CPI, US$, 2005=100, Weighted by trade imports from advanced economies. Source of the consumer price index is desk submitted data (PCPI) converted to US$. | F31: CPI, US$, 2005=100, Weighted by trade imports from advanced economies. Source of the consumer price index is desk submitted data (PCPI) converted to US$. | G31: CPI, US$, 2005=100, Weighted by trade imports from advanced economies. Source of the consumer price index is desk submitted data (PCPI) converted to US$. | H31: CPI, US$, 2005=100, Weighted by trade imports from advanced economies. Source of the consumer price index is desk submitted data (PCPI) converted to US$. | I31: CPI, US$, 2005=100, Weighted by trade imports from advanced economies. Source of the consumer price index is desk submitted data (PCPI) converted to US$. | J31: CPI, US$, 2005=100, Weighted by trade imports from advanced economies. Source of the consumer price index is desk submitted data (PCPI) converted to US$. | K31: CPI, US$, 2005=100, Weighted by trade imports from advanced economies. Source of the consumer price index is desk submitted data (PCPI) converted to US$. | L31: CPI, US$, 2005=100, Weighted by trade imports from advanced economies. Source of the consumer price index is desk submitted data (PCPI) converted to US$. | M31: CPI, US$, 2005=100, Weighted by trade imports from advanced economies. Source of the consumer price index is desk submitted data (PCPI) converted to US$. | N31: CPI, US$, 2005=100, Weighted by trade imports from advanced economies. Source of the consumer price index is desk submitted data (PCPI) converted to US$. | O31: CPI, US$, 2005=100, Weighted by trade imports from advanced economies. Source of the consumer price index is desk submitted data (PCPI) converted to US$.
A33: All countries
A35: Export deflators in U.S. dollars
A36: Goods and services | B36: Exports deflator of goods and services, 2005=100, Weighted by trade imports from all partner countries. Source of the exports deflator of goods and services is WEO calculated data (TX_D). | C36: Exports deflator of goods and services, 2005=100, Weighted by trade imports from all partner countries. Source of the exports deflator of goods and services is WEO calculated data (TX_D). | D36: Exports deflator of goods and services, 2005=100, Weighted by trade imports from all partner countries. Source of the exports deflator of goods and services is WEO calculated data (TX_D). | E36: Exports deflator of goods and services, 2005=100, Weighted by trade imports from all partner countries. Source of the exports deflator of goods and services is WEO calculated data (TX_D). | F36: Exports deflator of goods and services, 2005=100, Weighted by trade imports from all partner countries. Source of the exports deflator of goods and services is WEO calculated data (TX_D). | G36: Exports deflator of goods and services, 2005=100, Weighted by trade imports from all partner countries. Source of the exports deflator of goods and services is WEO calculated data (TX_D). | H36: Exports deflator of goods and services, 2005=100, Weighted by trade imports from all partner countries. Source of the exports deflator of goods and services is WEO calculated data (TX_D). | I36: Exports deflator of goods and services, 2005=100, Weighted by trade imports from all partner countries. Source of the exports deflator of goods and services is WEO calculated data (TX_D). | J36: Exports deflator of goods and services, 2005=100, Weighted by trade imports from all partner countries. Source of the exports deflator of goods and services is WEO calculated data (TX_D). | K36: Exports deflator of goods and services, 2005=100, Weighted by trade imports from all partner countries. Source of the exports deflator of goods and services is WEO calculated data (TX_D). | L36: Exports deflator of goods and services, 2005=100, Weighted by trade imports from all partner countries. Source of the exports deflator of goods and services is WEO calculated data (TX_D). | M36: Exports deflator of goods and services, 2005=100, Weighted by trade imports from all partner countries. Source of the exports deflator of goods and services is WEO calculated data (TX_D). | N36: Exports deflator of goods and services, 2005=100, Weighted by trade imports from all partner countries. Source of the exports deflator of goods and services is WEO calculated data (TX_D). | O36: Exports deflator of goods and services, 2005=100, Weighted by trade imports from all partner countries. Source of the exports deflator of goods and services is WEO calculated data (TX_D).
A37: Goods | B37: Exports deflator of goods, 2005=100, Weighted by trade imports from all partner countries. Source of the exports deflator of goods is WEO calculated data (TXG_D). | C37: Exports deflator of goods, 2005=100, Weighted by trade imports from all partner countries. Source of the exports deflator of goods is WEO calculated data (TXG_D). | D37: Exports deflator of goods, 2005=100, Weighted by trade imports from all partner countries. Source of the exports deflator of goods is WEO calculated data (TXG_D). | E37: Exports deflator of goods, 2005=100, Weighted by trade imports from all partner countries. Source of the exports deflator of goods is WEO calculated data (TXG_D). | F37: Exports deflator of goods, 2005=100, Weighted by trade imports from all partner countries. Source of the exports deflator of goods is WEO calculated data (TXG_D). | G37: Exports deflator of goods, 2005=100, Weighted by trade imports from all partner countries. Source of the exports deflator of goods is WEO calculated data (TXG_D). | H37: Exports deflator of goods, 2005=100, Weighted by trade imports from all partner countries. Source of the exports deflator of goods is WEO calculated data (TXG_D). | I37: Exports deflator of goods, 2005=100, Weighted by trade imports from all partner countries. Source of the exports deflator of goods is WEO calculated data (TXG_D). | J37: Exports deflator of goods, 2005=100, Weighted by trade imports from all partner countries. Source of the exports deflator of goods is WEO calculated data (TXG_D). | K37: Exports deflator of goods, 2005=100, Weighted by trade imports from all partner countries. Source of the exports deflator of goods is WEO calculated data (TXG_D). | L37: Exports deflator of goods, 2005=100, Weighted by trade imports from all partner countries. Source of the exports deflator of goods is WEO calculated data (TXG_D).
A38: Excluding oil | B38: Exports deflator of goods excl. oil, 2005=100, Weighted by trade imports from all partner countries. Source of the exports deflator of goods excluding oil is WEO calculated data (TXGXO_D). | C38: Exports deflator of goods excl. oil, 2005=100, Weighted by trade imports from all partner countries. Source of the exports deflator of goods excluding oil is WEO calculated data (TXGXO_D). | D38: Exports deflator of goods excl. oil, 2005=100, Weighted by trade imports from all partner countries. Source of the exports deflator of goods excluding oil is WEO calculated data (TXGXO_D). | E38: Exports deflator of goods excl. oil, 2005=100, Weighted by trade imports from all partner countries. Source of the exports deflator of goods excluding oil is WEO calculated data (TXGXO_D). | F38: Exports deflator of goods excl. oil, 2005=100, Weighted by trade imports from all partner countries. Source of the exports deflator of goods excluding oil is WEO calculated data (TXGXO_D). | G38: Exports deflator of goods excl. oil, 2005=100, Weighted by trade imports from all partner countries. Source of the exports deflator of goods excluding oil is WEO calculated data (TXGXO_D). | H38: Exports deflator of goods excl. oil, 2005=100, Weighted by trade imports from all partner countries. Source of the exports deflator of goods excluding oil is WEO calculated data (TXGXO_D). | I38: Exports deflator of goods excl. oil, 2005=100, Weighted by trade imports from all partner countries. Source of the exports deflator of goods excluding oil is WEO calculated data (TXGXO_D). | J38: Exports deflator of goods excl. oil, 2005=100, Weighted by trade imports from all partner countries. Source of the exports deflator of goods excluding oil is WEO calculated data (TXGXO_D). | K38: Exports deflator of goods excl. oil, 2005=100, Weighted by trade imports from all partner countries. Source of the exports deflator of goods excluding oil is WEO calculated data (TXGXO_D). | L38: Exports deflator of goods excl. oil, 2005=100, Weighted by trade imports from all partner countries. Source of the exports deflator of goods excluding oil is WEO calculated data (TXGXO_D). | M38: Exports deflator of goods excl. oil, 2005=100, Weighted by trade imports from all partner countries. Source of the exports deflator of goods excluding oil is WEO calculated data (TXGXO_D). | N38: Exports deflator of goods excl. oil, 2005=100, Weighted by trade imports from all partner countries. Source of the exports deflator of goods excluding oil is WEO calculated data (TXGXO_D). | O38: Exports deflator of goods excl. oil, 2005=100, Weighted by trade imports from all partner countries. Source of the exports deflator of goods excluding oil is WEO calculated data (TXGXO_D).
A40: Import deflators in U.S. dollars
A41: Goods and services | B41: Imports deflator of goods and services, 2005=100, Weighted by trade exports to all partner countries. Source of the imports deflator of goods and services is WEO calculated data (TM_D). | C41: Exports deflator of goods and services, 2005=100, Weighted by trade imports from all partner countries. Source of the exports deflator of goods and services is WEO calculated data (TX_D). | D41: Exports deflator of goods and services, 2005=100, Weighted by trade imports from all partner countries. Source of the exports deflator of goods and services is WEO calculated data (TX_D). | E41: Exports deflator of goods and services, 2005=100, Weighted by trade imports from all partner countries. Source of the exports deflator of goods and services is WEO calculated data (TX_D). | F41: Exports deflator of goods and services, 2005=100, Weighted by trade imports from all partner countries. Source of the exports deflator of goods and services is WEO calculated data (TX_D). | G41: Exports deflator of goods and services, 2005=100, Weighted by trade imports from all partner countries. Source of the exports deflator of goods and services is WEO calculated data (TX_D). | H41: Exports deflator of goods and services, 2005=100, Weighted by trade imports from all partner countries. Source of the exports deflator of goods and services is WEO calculated data (TX_D). | I41: Exports deflator of goods and services, 2005=100, Weighted by trade imports from all partner countries. Source of the exports deflator of goods and services is WEO calculated data (TX_D). | J41: Exports deflator of goods and services, 2005=100, Weighted by trade imports from all partner countries. Source of the exports deflator of goods and services is WEO calculated data (TX_D). | K41: Exports deflator of goods and services, 2005=100, Weighted by trade imports from all partner countries. Source of the exports deflator of goods and services is WEO calculated data (TX_D). | L41: Exports deflator of goods and services, 2005=100, Weighted by trade imports from all partner countries. Source of the exports deflator of goods and services is WEO calculated data (TX_D). | M41: Exports deflator of goods and services, 2005=100, Weighted by trade imports from all partner countries. Source of the exports deflator of goods and services is WEO calculated data (TX_D). | N41: Exports deflator of goods and services, 2005=100, Weighted by trade imports from all partner countries. Source of the exports deflator of goods and services is WEO calculated data (TX_D). | O41: Exports deflator of goods and services, 2005=100, Weighted by trade imports from all partner countries. Source of the exports deflator of goods and services is WEO calculated data (TX_D).
A42: Goods | B42: Imports deflator of goods, 2005=100, Weighted by trade exports to all partner countries. Source of the imports deflator of goods is WEO calculated data (TMG_D). | C42: Exports deflator of goods, 2005=100, Weighted by trade imports from all partner countries. Source of the exports deflator of goods is WEO calculated data (TXG_D). | D42: Exports deflator of goods, 2005=100, Weighted by trade imports from all partner countries. Source of the exports deflator of goods is WEO calculated data (TXG_D). | E42: Exports deflator of goods, 2005=100, Weighted by trade imports from all partner countries. Source of the exports deflator of goods is WEO calculated data (TXG_D). | F42: Exports deflator of goods, 2005=100, Weighted by trade imports from all partner countries. Source of the exports deflator of goods is WEO calculated data (TXG_D). | G42: Exports deflator of goods, 2005=100, Weighted by trade imports from all partner countries. Source of the exports deflator of goods is WEO calculated data (TXG_D). | H42: Exports deflator of goods, 2005=100, Weighted by trade imports from all partner countries. Source of the exports deflator of goods is WEO calculated data (TXG_D). | I42: Exports deflator of goods, 2005=100, Weighted by trade imports from all partner countries. Source of the exports deflator of goods is WEO calculated data (TXG_D). | J42: Exports deflator of goods, 2005=100, Weighted by trade imports from all partner countries. Source of the exports deflator of goods is WEO calculated data (TXG_D). | K42: Exports deflator of goods, 2005=100, Weighted by trade imports from all partner countries. Source of the exports deflator of goods is WEO calculated data (TXG_D). | L42: Exports deflator of goods, 2005=100, Weighted by trade imports from all partner countries. Source of the exports deflator of goods is WEO calculated data (TXG_D).
A44: Advanced economy partners
A46: Unit labor costs in manufacturing | B46: Unit labor costs in manufacturing, US$, 2005=100, Weighted by trade exports to advanced economies. For advanced economies, unit labor costs in manufacturing is desk submitted data (LULCM). | C46: Unit labor costs in manufacturing, US$, 2005=100, Weighted by trade exports to advanced economies. For advanced economies, unit labor costs in manufacturing is desk submitted data (LULCM). | D46: Unit labor costs in manufacturing, US$, 2005=100, Weighted by trade exports to advanced economies. For advanced economies, unit labor costs in manufacturing is desk submitted data (LULCM). | E46: Unit labor costs in manufacturing, US$, 2005=100, Weighted by trade exports to advanced economies. For advanced economies, unit labor costs in manufacturing is desk submitted data (LULCM). | F46: Unit labor costs in manufacturing, US$, 2005=100, Weighted by trade exports to advanced economies. For advanced economies, unit labor costs in manufacturing is desk submitted data (LULCM). | G46: Unit labor costs in manufacturing, US$, 2005=100, Weighted by trade exports to advanced economies. For advanced economies, unit labor costs in manufacturing is desk submitted data (LULCM). | H46: Unit labor costs in manufacturing, US$, 2005=100, Weighted by trade exports to advanced economies. For advanced economies, unit labor costs in manufacturing is desk submitted data (LULCM). | I46: Unit labor costs in manufacturing, US$, 2005=100, Weighted by trade exports to advanced economies. For advanced economies, unit labor costs in manufacturing is desk submitted data (LULCM). | J46: Unit labor costs in manufacturing, US$, 2005=100, Weighted by trade exports to advanced economies. For advanced economies, unit labor costs in manufacturing is desk submitted data (LULCM). | K46: Unit labor costs in manufacturing, US$, 2005=100, Weighted by trade exports to advanced economies. For advanced economies, unit labor costs in manufacturing is desk submitted data (LULCM). | L46: Unit labor costs in manufacturing, US$, 2005=100, Weighted by trade exports to advanced economies. For advanced economies, unit labor costs in manufacturing is desk submitted data (LULCM). | M46: Unit labor costs in manufacturing, US$, 2005=100, Weighted by trade exports to advanced economies. For advanced economies, unit labor costs in manufacturing is desk submitted data (LULCM). | N46: Unit labor costs in manufacturing, US$, 2005=100, Weighted by trade exports to advanced economies. For advanced economies, unit labor costs in manufacturing is desk submitted data (LULCM). | O46: Unit labor costs in manufacturing, US$, 2005=100, Weighted by trade exports to advanced economies. For advanced economies, unit labor costs in manufacturing is desk submitted data (LULCM).
A49: World Prices
A50: Export unit value for manufactures (MUV) | B50: Deflator of exports of manufactures for the advanced economies. Source of the exports of manufactures is WEO calculated data (TXGM_D).
A51: Petroleum spot price (APSP) | B51: Crude Oil (petroleum), simple average of three spot prices; Dated Brent, West Texas Intermediate, and the Dubai Fateh, US$ per barrel
A53: Average of nonfuel commodity market prices weighted by the 2011-13 composition of nonfuel commodity trade of reporting country
A55: Nonfuel commodity export price | B55: Nonfuel commodity exports price, 2005=100, Average of nonfuel commodity market prices weighted by the 2011-13 composition of nonfuel commodity export trade of country | C55: Nonfuel commodity exports price, 2005=100, Average of nonfuel commodity market prices weighted by the 2008-10 composition of nonfuel commodity export trade of country | D55: Nonfuel commodity exports price, 2005=100, Average of nonfuel commodity market prices weighted by the 2008-10 composition of nonfuel commodity export trade of country | E55: Nonfuel commodity exports price, 2005=100, Average of nonfuel commodity market prices weighted by the 2008-10 composition of nonfuel commodity export trade of country | F55: Nonfuel commodity exports price, 2005=100, Average of nonfuel commodity market prices weighted by the 2008-10 composition of nonfuel commodity export trade of country | G55: Nonfuel commodity exports price, 2005=100, Average of nonfuel commodity market prices weighted by the 2008-10 composition of nonfuel commodity export trade of country | H55: Nonfuel commodity exports price, 2005=100, Average of nonfuel commodity market prices weighted by the 2008-10 composition of nonfuel commodity export trade of country | I55: Nonfuel commodity exports price, 2005=100, Average of nonfuel commodity market prices weighted by the 2008-10 composition of nonfuel commodity export trade of country | J55: Nonfuel commodity exports price, 2005=100, Average of nonfuel commodity market prices weighted by the 2008-10 composition of nonfuel commodity export trade of country | K55: Nonfuel commodity exports price, 2005=100, Average of nonfuel commodity market prices weighted by the 2008-10 composition of nonfuel commodity export trade of country | L55: Nonfuel commodity exports price, 2005=100, Average of nonfuel commodity market prices weighted by the 2008-10 composition of nonfuel commodity export trade of country | M55: Nonfuel commodity exports price, 2005=100, Average of nonfuel commodity market prices weighted by the 2008-10 composition of nonfuel commodity export trade of country | N55: Nonfuel commodity exports price, 2005=100, Average of nonfuel commodity market prices weighted by the 2008-10 composition of nonfuel commodity export trade of country | O55: Nonfuel commodity exports price, 2005=100, Average of nonfuel commodity market prices weighted by the 2008-10 composition of nonfuel commodity export trade of country
A56: Nonfuel commodity import price | B56: Nonfuel commodity imports price, 2005=100, Average of nonfuel commodity market prices weighted by the 2011-13 composition of nonfuel commodity import trade of country | C56: Nonfuel commodity imports price, 2005=100, Average of nonfuel commodity market prices weighted by the 2008-10 composition of nonfuel commodity import trade of country | D56: Nonfuel commodity imports price, 2005=100, Average of nonfuel commodity market prices weighted by the 2008-10 composition of nonfuel commodity import trade of country | E56: Nonfuel commodity imports price, 2005=100, Average of nonfuel commodity market prices weighted by the 2008-10 composition of nonfuel commodity import trade of country | F56: Nonfuel commodity imports price, 2005=100, Average of nonfuel commodity market prices weighted by the 2008-10 composition of nonfuel commodity import trade of country | G56: Nonfuel commodity imports price, 2005=100, Average of nonfuel commodity market prices weighted by the 2008-10 composition of nonfuel commodity import trade of country | H56: Nonfuel commodity imports price, 2005=100, Average of nonfuel commodity market prices weighted by the 2008-10 composition of nonfuel commodity import trade of country | I56: Nonfuel commodity imports price, 2005=100, Average of nonfuel commodity market prices weighted by the 2008-10 composition of nonfuel commodity import trade of country | J56: Nonfuel commodity imports price, 2005=100, Average of nonfuel commodity market prices weighted by the 2008-10 composition of nonfuel commodity import trade of country | K56: Nonfuel commodity imports price, 2005=100, Average of nonfuel commodity market prices weighted by the 2008-10 composition of nonfuel commodity import trade of country | L56: Nonfuel commodity imports price, 2005=100, Average of nonfuel commodity market prices weighted by the 2008-10 composition of nonfuel commodity import trade of country | M56: Nonfuel commodity imports price, 2005=100, Average of nonfuel commodity market prices weighted by the 2008-10 composition of nonfuel commodity import trade of country | N56: Nonfuel commodity imports price, 2005=100, Average of nonfuel commodity market prices weighted by the 2008-10 composition of nonfuel commodity import trade of country | O56: Nonfuel commodity imports price, 2005=100, Average of nonfuel commodity market prices weighted by the 2008-10 composition of nonfuel commodity import trade of country
A59: Component-Based Goods Trade Deflators
A60: Export deflator | B60: Component-based goods trade exports deflator, 2005=100 | C60: Please refer to introduction sheet for more information.
...

Sheet Introduction
A3: GEE data are group composites, based on weighted averages of selected WEO variables from the country databases. The latest GEE data are available for access from EcOS/EcXL and DMX.
A5: The GEE tables present three types of information:
A7: 1. A comparison of the current GEE data with that of the previous WEO.
A9: 2. Historical annual and quarterly GEE data and projections.
A11: 3. The weights used to calculate the GEE table group composites.
A13: For each country weighted averages of output, demand, prices, and costs are calculated by combining data for each of its trading partners with corresponding fixed-year weights that are proportional to the country's geographical distribution of exports (or origin of imports, as the case may be). The relative importance of trading partners currently reflects the average trade in 2011-13, the latest three years for which the IMF's Direction of Trade Statistics (DOTS) provides the highest coverage of trade statistics. The trade weights are generally updated every other year. It should be noted that the weights reflect trade in goods only; complete information on bilateral trade in services is not generally available.
A15: Given a reasonably stable geographic pattern of a country's foreign trade, composites of foreign demand and inflation calculated in this fashion tend to be more meaningful for purposes of analyzing effects on the country from economic developments outside its borders than the conventional WEO group composites based on GDP or total trade weights. An extreme example may clarify the point: in Canada with its foreign trade so concentrated on the United States, a major recession in Germany would tend to have a small impact relative to that on a country such as Austria whose export share to Germany is substantial.
A17: Foreign output and demand measured by GDP or imports may be particularly useful information to guide desks in their projections of exports. Similarly, the composites of partner country export prices may serve to guide the projections of a country's import prices. In general, consistent use of the GEE information will diminish any tendency for the WEO projections to generate inconsistencies at the global level.
A19: Data on non-fuel commodity prices, maintained by the Research Department’s, Commodities Unit, are used in the GEE tables to provide, for each country, an average of non-fuel commodity prices, weighted by its export as well as import composition of average 2011-13 non-fuel commodity trade. The GEE tables also include a set of "component-based" trade deflators. These pre-calculated average foreign trade prices are based on countries' 2011-13 composition of trade in manufactures, oil, and non-fuel commodities using world price indicators (also shown in the GEE tables). The indicators, which at most can be counted upon to approximate recorded trade prices or unit values, may nevertheless be of value for countries lacking reliable statistics on trade unit values, or for desks in their formulation of projections.
A21: Weighting Procedures
A23: 1). The trade weights are derived from the IMF’s Direction of Trade (DOT) database. Every country has four sets of trade weights, i.e., the imports and exports weights for all countries as partners, and the imports and exports weights for only the advanced economies. The weights are calculated from the GEE reporting country’s trade with partner which comprise 100% of the reporter’s total exports or imports. The GEE calculates a reporting country's series not from the reporting country's data but from the aggregated sum of the weighted percentage changes of its partners' data for a given WEO series. The following example demonstrates the process for the exports trade-weighted GEE data series.
A25: The calculation of GEE partner series Real Imports of Goods and Services, for the reporter i is approximately equal to the following:
... A87: The table below illustrates the series names of the variables in the GEE Live.
A88: EcOS: Current GEE Codes | B88: Previous Aremos Codes
A89: Series Description (Series Names)
A90: Foreign Output and Demand
A91: Advanced Economy Countries
A92: Export-weighted averages
A93: Real GDP (NGDP_R_WX) | B93: IcccNGDP_R
A94: Real total domestic demand (NTDD_R_WX) | B94: IcccNGDP_R
A95: All Countries
A96: Real GDP (NGDP_R_WX) | B96: IcccNGDP_R
A97: Real Imports
A98: Goods and Services (TM_R_WX) | B98: XcccTM_R
A99: Goods (TMG_R_WX) | B99: XcccTMG_R
A100: Excluding Oil (TMGXO_R_WX) | B100: XcccTMGXO_R
A101: Import-weighted averages
A102: Foreign Prices and Costs
A103: Advanced Economy Countries
A104: In national currency (NGDP_D_WM) | B104: McccNGDP_D
A105: In U.S. dollars (NGDP_D_USD_WM) | B105: McccNGDP_DUS
A106: Consumer Prices
A107: In national currency (PCPI_WM) | B107: McccPCPI
A108: In U.S. dollars (PCPI_USD_WM) | B108: McccPCPIUS
A109: Import-weighted averages
A110: All Countries
A111: Export deflators in U.S. dollars
A112: Goods and Services (TX_D_WM) | B112: McccTX_D
A113: Goods (TXG_D_WM) | B113: McccTXG_D
A114: Excluding Oil (TXGXO_D_WM) | B114: McccTXGXO_D
...

Sheet EcOS indicators names
B3: GEE Code Map
B5: The GEE database is available in EcOS and DMX. Below is the reference guide to the GEE series codes. The GEE data codes complied with the Catalogue of Economic Time Series (CTS) standards. The "ccc" refers to the 3-digits IMF country code. Should you need assistance, please write to IMFEcOSSupport.
B7: Indicator | C7: Descriptor
B8: cccNGDP_R_WX110 | C8: Partner countries' real GDP, 2005=100, local currency, Weighted by trade exports to advanced economy
B9: cccNTDD_R_WX110 | C9: Partner countries' real total domestic demand, 2005=100, Weighted by trade exports to advanced economy
B10: cccNGDP_R_WX001 | C10: Partner countries' real GDP, 2005=100, local currency, Weighted by trade exports to all economies
B11: cccTM_R_WX001 | C11: Partner countries' imports volume of goods and services, 2005=100, Weighted by trade exports to all partner countries
B12: cccTMG_R_WX001 | C12: Partner countries' imports volume of goods, 2005=100, Weighted by trade exports to all partner countries
B13: cccTMGXO_R_WX001 | C13: Partner countries' imports volume of goods excl. oil, 2005=100, Weighted by trade exports to all partner countries
B14: cccTX_R_WM001 | C14: Partner countries' exports volume of goods and services, 2005=100, Weighted by trade imports from all partner countries
B15: cccTXG_R_WM001 | C15: Partner countries' exports volume of goods, 2005=100, Weighted by trade imports from all partner countries
B16: cccTXGXO_R_WM001 | C16: Partner countries' exports volume of goods excl. oil, 2005=100, Weighted by trade imports from all partner countries
B17: cccNGDP_D_WM110 | C17: Partner countries' GDP deflator, 2005=100, local currency, Weighted by trade imports from advanced economy
B18: cccNGDP_D_USD_WM110 | C18: Partner countries' GDP deflator, US$, 2005=100, Weighted by trade imports from advanced economy
... B31: cccTMGCB_D001 | C31: Component-based goods trade imports deflator, 2005=100

Sheet CompareDataSheet
D2: CURRENT | E2: 714 | F2: Rwanda
C4: Frequency | F4: 2012 | G4: 2013 | H4: 2014 | I4: 2015 | J4: 2016 | K4: 2017 | L4: 2018 | M4: 2019 | N4: 2020
A5: \\RES\GEE\GEE Live | B5: 714LULCM_USD_PCH_WX110.A | C5: Annual | D5: Advanced Economies | E5: LULCM_USD_PCH_WX | F5: -0.98557483 | G5: 1.8669117 | H5: 0.4655008 | I5: -7.6909845 | J5: 1.2531023 | K5: 2.1415024 | L5: 2.1017425 | M5: 1.8077852 | N5: 2.3428212
A6: \\RES\GEE\GEE Live | B6: 714NGDP_D_PCH_WM110.A | C6: Annual | E6: NGDP_D_PCH_WM | F6: 1.4498999 | G6: 1.347444 | H6: 1.1453251 | I6: 0.84705263 | J6: 1.3372 | K6: 1.4862499 | L6: 1.6658317 | M6: 1.7652251 | N6: 1.8079974
A7: \\RES\GEE\GEE Live | B7: 714NGDP_D_USD_PCH_WM110.A | C7: Annual | E7: NGDP_D_USD_PCH_WM | F7: -3.3156393 | G7: 2.3647717 | H7: 0.30301287 | I7: -11.4502 | J7: 1.416271 | K7: 2.3579 | L7: 2.399867 | M7: 2.3106745 | N7: 2.8904062
A8: \\RES\GEE\GEE Live | B8: 714NGDP_R_PCH_WX110.A | C8: Annual | E8: NGDP_R_PCH_WX | F8: 1.0636319 | G8: 1.2502207 | H8: 1.7440203 | I8: 1.9273075 | J8: 2.2413203 | K8: 2.1130838 | L8: 2.0325399 | M8: 1.9911378 | N8: 1.8914638
A9: \\RES\GEE\GEE Live | B9: 714NTDD_R_PCH_WX110.A | C9: Annual | E9: NTDD_R_PCH_WX | F9: 0.96590349 | G9: 1.0616452 | H9: 1.7366034 | I9: 2.2004724 | J9: 2.4334339 | K9: 2.2512916 | L9: 2.1665499 | M9: 2.1319712 | N9: 2.0313772
A10: \\RES\GEE\GEE Live | B10: 714PCPI_PCH_WM110.A | C10: Annual | E10: PCPI_PCH_WM | F10: 2.2015136 | G10: 1.4634036 | H10: 0.99119606 | I10: 0.33850563 | J10: 1.3347293 | K10: 1.6583138 | L10: 1.8172027 | M10: 1.9261979 | N10: 1.9674989
A11: \\RES\GEE\GEE Live | B11: 714PCPI_USD_PCH_WM110.A | C11: Annual | E11: PCPI_USD_PCH_WM | F11: -2.6055764 | G11: 2.4706153 | H11: 0.14682949 | I11: -11.90457 | J11: 1.4131868 | K11: 2.5323886 | L11: 2.5527735 | M11: 2.4730852 | N11: 3.0519011
A12: \\RES\GEE\GEE Live | B12: 714TM_D_PCH_WX110.A | C12: Annual | E12: TM_D_PCH_WX | F12: -1.567555 | G12: 0.8926962 | H12: -0.43134805 | I12: -11.134424 | J12: 0.19584133 | K12: 0.88130457 | L12: 0.80574123 | M12: 0.63271143 | N12: 1.1166566
A13: \\RES\GEE\GEE Live | B13: 714TM_R_PCH_WX110.A | C13: Annual | E13: TM_R_PCH_WX | F13: 1.0331273 | G13: 1.6732216 | H13: 2.9944281 | I13: 4.6657828 | J13: 4.7976499 | K13: 4.7667951 | L13: 4.8228975 | M13: 4.9708661 | N13: 5.0037765
A14: \\RES\GEE\GEE Live | B14: 714TMG_D_PCH_WX110.A | C14: Annual | E14: TMG_D_PCH_WX | F14: -1.8307519 | G14: 0.60537729 | H14: -1.2348248 | I14: -11.325628 | J14: 0.26641762 | K14: 0.86833557 | L14: 0.7997437 | M14: 0.60042266 | N14: 1.0374401
A15: \\RES\GEE\GEE Live | B15: 714TMG_R_PCH_WX110.A | C15: Annual | E15: TMG_R_PCH_WX | F15: 0.57273842 | G15: 1.3281048 | H15: 3.0937209 | I15: 4.5286887 | J15: 4.8992044 | K15: 4.9343136 | L15: 4.9866684 | M15: 5.1315873 | N15: 5.1795196
A16: \\RES\GEE\GEE Live | B16: 714TMGXO_D_PCH_WX110.A | C16: Annual | E16: TMGXO_D_PCH_WX | F16: -2.581096 | G16: 1.1289043 | H16: -0.19988255 | I16: -6.8269783 | J16: -0.37898525 | K16: 0.29950054 | L16: 0.30637417 | M16: 0.39402208 | N16: 1.0817565
A17: \\RES\GEE\GEE Live | B17: 714TMGXO_R_PCH_WX110.A | C17: Annual | E17: TMGXO_R_PCH_WX | F17: 1.2840104 | G17: 1.794893 | H17: 3.8867431 | I17: 3.5760386 | J17: 5.7547101 | K17: 5.4403154 | L17: 5.5076978 | M17: 5.4778191 | N17: 5.3679664
... A23: \\RES\GEE\GEE Live | B23: 714TXGXO_R_PCH_WM001.A | C23: Annual | E23: TXGXO_R_PCH_WM | F23: 1.3613039 | G23: 1.6433003 | H23: 3.0224367 | I23: 1.8825945 | J23: 4.0750275 | K23: 4.0934567 | L23: 4.183384 | M23: 4.3366668 | N23: 4.1769681
A24: \\RES\GEE\GEE Live | B24: 714LULCM_USD_PCH_WX001.A | C24: Annual | D24: World | E24: LULCM_USD_PCH_WX | F24: -1.0809918 | G24: 1.730205 | H24: 0.26881521 | I24: -7.9293131 | J24: 1.2649076 | K24: 2.2018988 | L24: 2.1594757 | M24: 1.8827494 | N24: 2.3955062
A25: \\RES\GEE\GEE Live | B25: 714NGDP_D_PCH_WM001.A | C25: Annual | E25: NGDP_D_PCH_WM | F25: 5.9841285 | G25: 3.225412 | H25: 3.1584376 | I25: 1.8628597 | J25: 3.76009 | K25: 3.5574661 | L25: 3.5459378 | M25: 3.4674574 | N25: 3.5259031
A26: \\RES\GEE\GEE Live | B26: 714NGDP_D_USD_PCH_WM001.A | C26: Annual | E26: NGDP_D_USD_PCH_WM | F26: 4.0674484 | G26: 1.3242872 | H26: 1.3522731 | I26: -7.5659238 | J26: 1.628054 | K26: 2.5095923 | L26: 2.4593594 | M26: 2.4990624 | N26: 2.9924632
A27: \\RES\GEE\GEE Live | B27: 714NGDP_R_PCH_WX001.A | C27: Annual | E27: NGDP_R_PCH_WX | F27: 4.7504048 | G27: 5.0131781 | H27: 5.3151313 | I27: 4.9559147 | J27: 4.8256485 | K27: 4.8536002 | L27: 4.7998265 | M27: 4.6614286 | N27: 4.4379531
A28: \\RES\GEE\GEE Live | B28: 714NTDD_R_PCH_WX001.A | C28: Annual | E28: NTDD_R_PCH_WX | F28: 5.3832785 | G28: 5.478228 | H28: 5.180167 | I28: 5.4324569 | J28: 4.8130244 | K28: 4.9285493 | L28: 4.9476908 | M28: 4.7481555 | N28: 4.5958427
A29: \\RES\GEE\GEE Live | B29: 714PCPI_PCH_WM001.A | C29: Annual | E29: PCPI_PCH_WM | F29: 6.7191248 | G29: 3.9884893 | H29: 3.7839932 | I29: 3.7022051 | J29: 3.8546731 | K29: 3.7101176 | L29: 3.6858241 | M29: 3.7256815 | N29: 3.7623841
A30: \\RES\GEE\GEE Live | B30: 714PCPI_USD_PCH_WM001.A | C30: Annual | E30: PCPI_USD_PCH_WM | F30: 4.7690615 | G30: 2.0567482 | H30: 2.0422141 | I30: -5.7408408 | J30: 1.7166454 | K30: 2.6619207 | L30: 2.5982742 | M30: 2.7561882 | N30: 3.2293345
A31: \\RES\GEE\GEE Live | B31: 714TM_D_PCH_WX001.A | C31: Annual | E31: TM_D_PCH_WX | F31: 0.4703814 | G31: -1.6097154 | H31: -2.0318041 | I31: -9.836507 | J31: 0.45408175 | K31: 1.7665519 | L31: 1.5788321 | M31: 1.2907938 | N31: 1.2328554
A32: \\RES\GEE\GEE Live | B32: 714TM_R_PCH_WX001.A | C32: Annual | E32: TM_R_PCH_WX | F32: 1.3648583 | G32: 5.3828373 | H32: 7.873037 | I32: 7.6238726 | J32: 4.9180281 | K32: 5.6670291 | L32: 5.6430817 | M32: 5.3655171 | N32: 5.3811063
A33: \\RES\GEE\GEE Live | B33: 714TMG_D_PCH_WX001.A | C33: Annual | E33: TMG_D_PCH_WX | F33: -0.016092963 | G33: -2.7948406 | H33: -2.1923363 | I33: -9.4620105 | J33: -0.11153088 | K33: 1.5185747 | L33: 1.3164747 | M33: 0.79634718 | N33: 0.55092311
A34: \\RES\GEE\GEE Live | B34: 714TMG_R_PCH_WX001.A | C34: Annual | E34: TMG_R_PCH_WX | F34: 1.5195069 | G34: 6.9148759 | H34: 6.7764161 | I34: 5.2105954 | J34: 4.8024203 | K34: 5.8732438 | L34: 5.8448798 | M34: 5.5792609 | N34: 5.6168606
A35: \\RES\GEE\GEE Live | B35: 714TMGXO_D_PCH_WX001.A | C35: Annual | E35: TMGXO_D_PCH_WX | F35: -0.39309747 | G35: -2.9648723 | H35: -1.5747081 | I35: -4.5562934 | J35: -0.39246589 | K35: 0.96712038 | L35: 0.87779512 | M35: 0.58388016 | N35: 0.44635836
A36: \\RES\GEE\GEE Live | B36: 714TMGXO_R_PCH_WX001.A | C36: Annual | E36: TMGXO_R_PCH_WX | F36: 1.510718 | G36: 6.9179515 | H36: 6.7268005 | I36: 4.3187755 | J36: 5.4361159 | K36: 6.2082582 | L36: 6.1839007 | M36: 5.8586954 | N36: 5.7897186
... A42: \\RES\GEE\GEE Live | B42: 714TXGXO_R_PCH_WM001.A | C42: Annual | E42: TXGXO_R_PCH_WM | F42: 6.8177888 | G42: 3.0952202 | H42: 4.571133 | I42: 5.9636983 | J42: 5.7877376 | K42: 7.5701631 | L42: 7.451315 | M42: 6.7527534 | N42: 6.5364295
F49: 2013Q1 | G49: 2013Q2 | H49: 2013Q3 | I49: 2013Q4 | J49: 2014Q1 | K49: 2014Q2 | L49: 2014Q3 | M49: 2014Q4 | N49: 2015Q1 | O49: 2015Q2 | P49: 2015Q3 | Q49: 2015Q4 | R49: 2016Q1 | S49: 2016Q2 | T49: 2016Q3 | U49: 2016Q4
A50: \\RES\GEE\GEE Live | B50: 714LULCM_USD_YOY_WX110.Q | C50: Quarterly | D50: Advanced Economies | E50: LULCM_USD_YOY_WX | F50: 1.98268 | G50: 1.0624199 | H50: 2.7469386 | I50: 1.8057311 | J50: 2.0705116 | K50: 3.2629395 | L50: 0.61213786 | M50: -3.8026466 | N50: -8.9394338 | O50: -9.6866813 | P50: -7.9113741 | Q50: -4.6496212 | R50: 0.22863394 | S50: 1.4177109 | T50: 1.7570951 | U50: 1.7663829
A51: \\RES\GEE\GEE Live | B51: 714NGDP_D_USD_YOY_WM110.Q | C51: Quarterly | E51: NGDP_D_USD_YOY_WM | F51: 1.2797407 | G51: 1.919192 | H51: 3.4832424 | I51: 2.6699822 | J51: 2.4111122 | K51: 3.8219396 | L51: 0.93807429 | M51: -5.7406275 | N51: -12.669571 | O51: -13.818823 | P51: -12.194317 | Q51: -7.2652929 | R51: 0.32596515 | S51: 1.3694483 | T51: 2.085394 | U51: 2.0434211
