Workbook
Name Products: #REF!

Sheet Table A Q
B1: Table A
B2: Macro-economic aggregates
C3: 2024 | D3: 2006Q1 | E3: 2006Q2 | F3: 2006Q3 | G3: 2006Q4 | H3: 2007Q1 | I3: 2007Q2 | J3: 2007Q3 | K3: 2007Q4 | L3: 2008Q1 | M3: 2008Q2 | N3: 2008Q3 | O3: 2008Q4 | P3: 2009Q1 | Q3: 2009Q2 | R3: 2009Q3 | S3: 2009Q4 | T3: 2010Q1 | U3: 2010Q2 | V3: 2010Q3 | W3: 2010Q4 | X3: 2011Q1 | Y3: 2011Q2 | Z3: 2011Q3 | AA3: 2011Q4 | AB3: 2012Q1 | AC3: 2012Q2 | AD3: 2012Q3 | AE3: 2012Q4 | AF3: 2013Q1 | AG3: 2013Q2 | AH3: 2013Q3 | AI3: 2013Q4 | AJ3: 2014Q1 | AK3: 2014Q2 | AL3: 2014Q3 | AM3: 2014Q4 | AN3: 2015Q1 | AO3: 2015Q2 | AP3: 2015Q3 | AQ3: 2015Q4 | AR3: 2016Q1 | AS3: 2016Q2 | AT3: 2016Q3 | AU3: 2016Q4 | AV3: 2017Q1 | AW3: 2017Q2 | AX3: 2017Q3 | AY3: 2017Q4 | AZ3: 2018Q1 | BA3: 2018Q2 | BB3: 2018Q3 | BC3: 2018Q4 | BD3: 2019Q1 | BE3: 2019Q2 | BF3: 2019Q3 | BG3: 2019Q4 | BH3: 2020Q1 | BI3: 2020Q2 | BJ3: 2020Q3 | BK3: 2020Q4 | BL3: 2021Q1 | BM3: 2021Q2 | BN3: 2021Q3 | BO3: 2021Q4 | BP3: 2022Q1 | BQ3: 2022Q2 | BR3: 2022Q3 | BS3: 2022Q4 | BT3: 2023Q1 | BU3: 2023Q2 | BV3: 2023Q3 | BW3: 2023Q4 | BX3: 2024Q1 | BY3: 2024Q2 | BZ3: 2024Q3 | CA3: 2024Q4 | CB3: 2025Q1 | CC3: 2025Q2 | CD3: 2025Q3
B5: Gross Domestic Product (Frw billions)
B6: GDP at current prices | C6: 19918 | D6: 401 | E6: 452 | F6: 479 | G6: 499 | H6: 506 | I6: 547 | J6: 574 | K6: 599 | L6: 608 | M6: 687 | N6: 750 | O6: 788 | P6: 786 | Q6: 774 | R6: 809 | S6: 855 | T6: 853 | U6: 858 | V6: 906 | W6: 955 | X6: 963 | Y6: 1000 | Z6: 1074 | AA6: 1096 | AB6: 1114 | AC6: 1144 | AD6: 1210 | AE6: 1234 | AF6: 1214 | AG6: 1253 | AH6: 1261 | AI6: 1329 | AJ6: 1355 | AK6: 1394 | AL6: 1437 | AM6: 1436 | AN6: 1465 | AO6: 1500 | AP6: 1568 | AQ6: 1617 | AR6: 1661 | AS6: 1711 | AT6: 1696 | AU6: 1778 | AV6: 1846 | AW6: 1917 | AX6: 1944 | AY6: 1988 | AZ6: 2016 | BA6: 2132 | BB6: 1884 | BC6: 2277 | BD6: 2160 | BE6: 2468 | BF6: 2195 | BG6: 2637 | BH6: 2395 | BI6: 2413 | BJ6: 2221 | BK6: 2862 | BL6: 2574 | BM6: 2841 | BN6: 2598 | BO6: 3112 | BP6: 3101 | BQ6: 3549 | BR6: 3304 | BS6: 4210 | BT6: 4031 | BU6: 4255 | BV6: 3875 | BW6: 5016 | BX6: 4514 | BY6: 4965 | BZ6: 4659 | CA6: 5780 | CB6: 5276 | CC6: 5799 | CD6: 5525
B7: Growth rate | D7: 0 | E7: 0 | F7: 0 | G7: 0 | H7: 0.262 | I7: 0.211 | J7: 0.198 | K7: 0.2 | L7: 0.2 | M7: 0.256 | N7: 0.307 | O7: 0.316 | P7: 0.294 | Q7: 0.127 | R7: 0.079 | S7: 0.085 | T7: 0.085 | U7: 0.108 | V7: 0.12 | W7: 0.117 | X7: 0.129 | Y7: 0.165 | Z7: 0.186 | AA7: 0.147 | AB7: 0.156 | AC7: 0.144 | AD7: 0.126 | AE7: 0.127 | AF7: 0.089 | AG7: 0.096 | AH7: 0.042 | AI7: 0.076 | AJ7: 0.117 | AK7: 0.113 | AL7: 0.14 | AM7: 0.08 | AN7: 0.081 | AO7: 0.076 | AP7: 0.091 | AQ7: 0.127 | AR7: 0.133 | AS7: 0.14 | AT7: 0.082 | AU7: 0.099 | AV7: 0.111 | AW7: 0.12 | AX7: 0.146 | AY7: 0.118 | AZ7: 0.092 | BA7: 0.112 | BB7: -0.031 | BC7: 0.146 | BD7: 0.072 | BE7: 0.158 | BF7: 0.165 | BG7: 0.158 | BH7: 0.109 | BI7: -0.022 | BJ7: 0.012 | BK7: 0.085 | BL7: 0.075 | BM7: 0.177 | BN7: 0.169 | BO7: 0.087 | BP7: 0.205 | BQ7: 0.249 | BR7: 0.272 | BS7: 0.353 | BT7: 0.3 | BU7: 0.199 | BV7: 0.173 | BW7: 0.191 | BX7: 0.12 | BY7: 0.167 | BZ7: 0.202 | CA7: 0.152 | CB7: 0.169 | CC7: 0.168 | CD7: 0.186
B8: GDP at constant 2024 prices | C8: 19918 | D8: 813 | E8: 873 | F8: 960 | G8: 961 | H8: 922 | I8: 941 | J8: 995 | K8: 1024 | L8: 1009 | M8: 1067 | N8: 1113 | O8: 1127 | P8: 1133 | Q8: 1121 | R8: 1152 | S8: 1180 | T8: 1191 | U8: 1193 | V8: 1244 | W8: 1294 | X8: 1292 | Y8: 1263 | Z8: 1373 | AA8: 1386 | AB8: 1400 | AC8: 1399 | AD8: 1471 | AE8: 1503 | AF8: 1466 | AG8: 1510 | AH8: 1509 | AI8: 1561 | AJ8: 1554 | AK8: 1578 | AL8: 1643 | AM8: 1643 | AN8: 1678 | AO8: 1724 | AP8: 1776 | AQ8: 1808 | AR8: 1858 | AS8: 1872 | AT8: 1833 | AU8: 1841 | AV8: 1862 | AW8: 1904 | AX8: 1955 | AY8: 1973 | AZ8: 3264 | BA8: 3433 | BB8: 3026 | BC8: 3804 | BD8: 3468 | BE8: 3885 | BF8: 3383 | BG8: 4046 | BH8: 3621 | BI8: 3451 | BJ8: 3258 | BK8: 4042 | BL8: 3707 | BM8: 4070 | BN8: 3454 | BO8: 4350 | BP8: 4074 | BQ8: 4541 | BR8: 3852 | BS8: 4644 | BT8: 4386 | BU8: 4659 | BV8: 4261 | BW8: 5270 | BX8: 4741 | BY8: 5137 | BZ8: 4550 | CA8: 5489 | CB8: 5052 | CC8: 5540 | CD8: 5089
B9: Growth rate | D9: 0 | E9: 0 | F9: 0 | G9: 0 | H9: 0.134 | I9: 0.077 | J9: 0.037 | K9: 0.066 | L9: 0.094 | M9: 0.134 | N9: 0.118 | O9: 0.1 | P9: 0.122 | Q9: 0.05 | R9: 0.035 | S9: 0.047 | T9: 0.052 | U9: 0.064 | V9: 0.08 | W9: 0.097 | X9: 0.084 | Y9: 0.059 | Z9: 0.103 | AA9: 0.071 | AB9: 0.084 | AC9: 0.107 | AD9: 0.072 | AE9: 0.085 | AF9: 0.047 | AG9: 0.08 | AH9: 0.026 | AI9: 0.038 | AJ9: 0.06 | AK9: 0.045 | AL9: 0.089 | AM9: 0.053 | AN9: 0.08 | AO9: 0.093 | AP9: 0.081 | AQ9: 0.1 | AR9: 0.107 | AS9: 0.085 | AT9: 0.032 | AU9: 0.018 | AV9: 0.002 | AW9: 0.017 | AX9: 0.066 | AY9: 0.072 | AZ9: 0.753 | BA9: 0.803 | BB9: 0.548 | BC9: 0.928 | BD9: 0.063 | BE9: 0.132 | BF9: 0.118 | BG9: 0.064 | BH9: 0.044 | BI9: -0.112 | BJ9: -0.037 | BK9: -0.001 | BL9: 0.024 | BM9: 0.179 | BN9: 0.06 | BO9: 0.076 | BP9: 0.099 | BQ9: 0.116 | BR9: 0.115 | BS9: 0.068 | BT9: 0.077 | BU9: 0.026 | BV9: 0.106 | BW9: 0.135 | BX9: 0.081 | BY9: 0.103 | BZ9: 0.068 | CA9: 0.042 | CB9: 0.065 | CC9: 0.078 | CD9: 0.118
B10: Implicit GDP deflator | C10: 100 | D10: 49 | E10: 52 | F10: 50 | G10: 52 | H10: 55 | I10: 58 | J10: 58 | K10: 58 | L10: 60 | M10: 64 | N10: 67 | O10: 70 | P10: 69 | Q10: 69 | R10: 70 | S10: 72 | T10: 72 | U10: 72 | V10: 73 | W10: 74 | X10: 75 | Y10: 79 | Z10: 78 | AA10: 79 | AB10: 80 | AC10: 82 | AD10: 82 | AE10: 82 | AF10: 83 | AG10: 83 | AH10: 84 | AI10: 85 | AJ10: 87 | AK10: 88 | AL10: 87 | AM10: 87 | AN10: 87 | AO10: 87 | AP10: 88 | AQ10: 89 | AR10: 89 | AS10: 91 | AT10: 93 | AU10: 97 | AV10: 99 | AW10: 101 | AX10: 99 | AY10: 101 | AZ10: 62 | BA10: 62 | BB10: 62 | BC10: 60 | BD10: 62 | BE10: 64 | BF10: 65 | BG10: 65 | BH10: 66 | BI10: 70 | BJ10: 68 | BK10: 71 | BL10: 69 | BM10: 70 | BN10: 75 | BO10: 72 | BP10: 76 | BQ10: 78 | BR10: 86 | BS10: 91 | BT10: 92 | BU10: 91 | BV10: 91 | BW10: 95 | BX10: 95 | BY10: 97 | BZ10: 102 | CA10: 105 | CB10: 104 | CC10: 105 | CD10: 109
B11: Growth rate | D11: 0 | E11: 0 | F11: 0 | G11: 0 | H11: 0.112 | I11: 0.124 | J11: 0.155 | K11: 0.126 | L11: 0.097 | M11: 0.107 | N11: 0.168 | O11: 0.196 | P11: 0.153 | Q11: 0.073 | R11: 0.042 | S11: 0.036 | T11: 0.032 | U11: 0.041 | V11: 0.037 | W11: 0.018 | X11: 0.042 | Y11: 0.1 | Z11: 0.075 | AA11: 0.072 | AB11: 0.067 | AC11: 0.033 | AD11: 0.051 | AE11: 0.039 | AF11: 0.04 | AG11: 0.015 | AH11: 0.016 | AI11: 0.037 | AJ11: 0.053 | AK11: 0.065 | AL11: 0.047 | AM11: 0.026 | AN11: 0.001 | AO11: -0.015 | AP11: 0.009 | AQ11: 0.024 | AR11: 0.024 | AS11: 0.051 | AT11: 0.048 | AU11: 0.079 | AV11: 0.109 | AW11: 0.101 | AX11: 0.075 | AY11: 0.044 | AZ11: -0.376 | BA11: -0.385 | BB11: -0.371 | BC11: -0.407 | BD11: 0.008 | BE11: 0.023 | BF11: 0.042 | BG11: 0.089 | BH11: 0.062 | BI11: 0.101 | BJ11: 0.051 | BK11: 0.086 | BL11: 0.05 | BM11: -0.002 | BN11: 0.103 | BO11: 0.01 | BP11: 0.096 | BQ11: 0.12 | BR11: 0.14 | BS11: 0.267 | BT11: 0.207 | BU11: 0.169 | BV11: 0.06 | BW11: 0.05 | BX11: 0.036 | BY11: 0.058 | BZ11: 0.126 | CA11: 0.106 | CB11: 0.097 | CC11: 0.083 | CD11: 0.06
B13: GDP per head (in '000 Frw) | C13: 1449 | D13: 45 | E13: 51 | F13: 54 | G13: 55 | H13: 56 | I13: 60 | J13: 63 | K13: 65 | L13: 65 | M13: 73 | N13: 80 | O13: 83 | P13: 83 | Q13: 81 | R13: 84 | S13: 88 | T13: 87 | U13: 87 | V13: 91 | W13: 96 | X13: 96 | Y13: 99 | Z13: 106 | AA13: 107 | AB13: 108 | AC13: 110 | AD13: 116 | AE13: 118 | AF13: 115 | AG13: 118 | AH13: 118 | AI13: 124 | AJ13: 125 | AK13: 128 | AL13: 131 | AM13: 131 | AN13: 132 | AO13: 135 | AP13: 140 | AQ13: 144 | AR13: 147 | AS13: 150 | AT13: 148 | AU13: 154 | AV13: 159 | AW13: 164 | AX13: 166 | AY13: 168 | AZ13: 170 | BA13: 178 | BB13: 157 | BC13: 188 | BD13: 178 | BE13: 202 | BF13: 178 | BG13: 213 | BH13: 192 | BI13: 193 | BJ13: 176 | BK13: 226 | BL13: 202 | BM13: 222 | BN13: 202 | BO13: 240 | BP13: 238 | BQ13: 271 | BR13: 251 | BS13: 318 | BT13: 302 | BU13: 317 | BV13: 288 | BW13: 370 | BX13: 331 | BY13: 362 | BZ13: 338 | CA13: 417 | CB13: 379 | CC13: 414 | CD13: 392
B14: GDP per head (in current US dollars) | C14: 1098 | D14: 82 | E14: 92 | F14: 97 | G14: 101 | H14: 102 | I14: 110 | J14: 114 | K14: 119 | L14: 120 | M14: 135 | N14: 146 | O14: 151 | P14: 146 | Q14: 142 | R14: 147 | S14: 155 | T14: 152 | U14: 151 | V14: 155 | W14: 162 | X14: 160 | Y14: 165 | Z14: 176 | AA14: 178 | AB14: 179 | AC14: 181 | AD14: 189 | AE14: 187 | AF14: 182 | AG14: 185 | AH14: 182 | AI14: 186 | AJ14: 186 | AK14: 188 | AL14: 192 | AM14: 189 | AN14: 189 | AO14: 189 | AP14: 193 | AQ14: 194 | AR14: 193 | AS14: 193 | AT14: 185 | AU14: 189 | AV14: 193 | AW14: 198 | AX14: 199 | AY14: 200 | AZ14: 200 | BA14: 208 | BB14: 181 | BC14: 215 | BD14: 201 | BE14: 226 | BF14: 197 | BG14: 233 | BH14: 207 | BI14: 207 | BJ14: 186 | BK14: 234 | BL14: 207 | BM14: 226 | BN14: 203 | BO14: 239 | BP14: 235 | BQ14: 265 | BR14: 243 | BS14: 301 | BT14: 278 | BU14: 282 | BV14: 242 | BW14: 299 | BX14: 259 | BY14: 279 | BZ14: 255 | CA14: 305 | CB14: 270 | CC14: 291 | CD14: 272
B16: Proportions of GDP
B17: Total final consumption expenditure
B18: Government | C18: 0.17 | D18: 0.16 | E18: 0.18 | F18: 0.16 | G18: 0.14 | H18: 0.15 | I18: 0.13 | J18: 0.14 | K18: 0.15 | L18: 0.13 | M18: 0.12 | N18: 0.12 | O18: 0.12 | P18: 0.13 | Q18: 0.14 | R18: 0.13 | S18: 0.12 | T18: 0.13 | U18: 0.14 | V18: 0.13 | W18: 0.13 | X18: 0.1 | Y18: 0.12 | Z18: 0.13 | AA18: 0.14 | AB18: 0.13 | AC18: 0.15 | AD18: 0.11 | AE18: 0.12 | AF18: 0.12 | AG18: 0.14 | AH18: 0.12 | AI18: 0.13 | AJ18: 0.14 | AK18: 0.16 | AL18: 0.14 | AM18: 0.13 | AN18: 0.14 | AO18: 0.14 | AP18: 0.14 | AQ18: 0.13 | AR18: 0.16 | AS18: 0.14 | AT18: 0.16 | AU18: 0.15 | AV18: 0.14 | AW18: 0.15 | AX18: 0.16 | AY18: 0.15 | AZ18: 0.13 | BA18: 0.13 | BB18: 0.16 | BC18: 0.13 | BD18: 0.15 | BE18: 0.17 | BF18: 0.14 | BG18: 0.13 | BH18: 0.16 | BI18: 0.15 | BJ18: 0.16 | BK18: 0.14 | BL18: 0.17 | BM18: 0.18 | BN18: 0.2 | BO18: 0.16 | BP18: 0.19 | BQ18: 0.16 | BR18: 0.22 | BS18: 0.14 | BT18: 0.17 | BU18: 0.2 | BV18: 0.18 | BW18: 0.13 | BX18: 0.16 | BY18: 0.18 | BZ18: 0.17 | CA18: 0.17 | CB18: 0.16 | CC18: 0.16 | CD18: 0.16
B19: Private | C19: 0.63 | D19: 0.82 | E19: 0.77 | F19: 0.81 | G19: 0.81 | H19: 0.76 | I19: 0.79 | J19: 0.78 | K19: 0.78 | L19: 0.82 | M19: 0.8 | N19: 0.83 | O19: 0.8 | P19: 0.8 | Q19: 0.81 | R19: 0.84 | S19: 0.84 | T19: 0.83 | U19: 0.82 | V19: 0.82 | W19: 0.81 | X19: 0.82 | Y19: 0.84 | Z19: 0.81 | AA19: 0.79 | AB19: 0.8 | AC19: 0.81 | AD19: 0.85 | AE19: 0.76 | AF19: 0.78 | AG19: 0.75 | AH19: 0.8 | AI19: 0.8 | AJ19: 0.8 | AK19: 0.76 | AL19: 0.82 | AM19: 0.77 | AN19: 0.8 | AO19: 0.82 | AP19: 0.82 | AQ19: 0.79 | AR19: 0.74 | AS19: 0.81 | AT19: 0.8 | AU19: 0.76 | AV19: 0.74 | AW19: 0.74 | AX19: 0.74 | AY19: 0.73 | AZ19: 0.75 | BA19: 0.75 | BB19: 0.68 | BC19: 0.73 | BD19: 0.71 | BE19: 0.69 | BF19: 0.64 | BG19: 0.69 | BH19: 0.74 | BI19: 0.75 | BJ19: 0.7 | BK19: 0.76 | BL19: 0.7 | BM19: 0.7 | BN19: 0.88 | BO19: 0.69 | BP19: 0.61 | BQ19: 0.65 | BR19: 0.57 | BS19: 0.66 | BT19: 0.66 | BU19: 0.65 | BV19: 0.57 | BW19: 0.7 | BX19: 0.61 | BY19: 0.64 | BZ19: 0.62 | CA19: 0.66 | CB19: 0.61 | CC19: 0.68 | CD19: 0.6
B20: Gross capital formation | C20: 0.35 | D20: 0.15 | E20: 0.16 | F20: 0.14 | G20: 0.15 | H20: 0.17 | I20: 0.16 | J20: 0.17 | K20: 0.18 | L20: 0.18 | M20: 0.23 | N20: 0.21 | O20: 0.23 | P20: 0.24 | Q20: 0.22 | R20: 0.19 | S20: 0.19 | T20: 0.22 | U20: 0.19 | V20: 0.19 | W20: 0.22 | X20: 0.23 | Y20: 0.19 | Z20: 0.2 | AA20: 0.22 | AB20: 0.23 | AC20: 0.21 | AD20: 0.23 | AE20: 0.26 | AF20: 0.25 | AG20: 0.24 | AH20: 0.23 | AI20: 0.25 | AJ20: 0.24 | AK20: 0.23 | AL20: 0.19 | AM20: 0.26 | AN20: 0.25 | AO20: 0.24 | AP20: 0.22 | AQ20: 0.26 | AR20: 0.28 | AS20: 0.26 | AT20: 0.24 | AU20: 0.26 | AV20: 0.24 | AW20: 0.23 | AX20: 0.24 | AY20: 0.24 | AZ20: 0.18 | BA20: 0.15 | BB20: 0.19 | BC20: 0.2 | BD20: 0.19 | BE20: 0.19 | BF20: 0.27 | BG20: 0.22 | BH20: 0.19 | BI20: 0.17 | BJ20: 0.2 | BK20: 0.17 | BL20: 0.35 | BM20: 0.33 | BN20: 0.39 | BO20: 0.35 | BP20: 0.37 | BQ20: 0.38 | BR20: 0.44 | BS20: 0.33 | BT20: 0.36 | BU20: 0.35 | BV20: 0.49 | BW20: 0.34 | BX20: 0.4 | BY20: 0.34 | BZ20: 0.38 | CA20: 0.29 | CB20: 0.38 | CC20: 0.3 | CD20: 0.37
B21: Resource balance | C21: -0.15 | D21: -0.12 | E21: -0.11 | F21: -0.12 | G21: -0.11 | H21: -0.07 | I21: -0.08 | J21: -0.09 | K21: -0.1 | L21: -0.13 | M21: -0.15 | N21: -0.16 | O21: -0.15 | P21: -0.17 | Q21: -0.17 | R21: -0.15 | S21: -0.15 | T21: -0.17 | U21: -0.15 | V21: -0.14 | W21: -0.16 | X21: -0.14 | Y21: -0.15 | Z21: -0.14 | AA21: -0.14 | AB21: -0.16 | AC21: -0.17 | AD21: -0.18 | AE21: -0.15 | AF21: -0.16 | AG21: -0.13 | AH21: -0.16 | AI21: -0.18 | AJ21: -0.18 | AK21: -0.16 | AL21: -0.15 | AM21: -0.16 | AN21: -0.19 | AO21: -0.2 | AP21: -0.18 | AQ21: -0.18 | AR21: -0.18 | AS21: -0.2 | AT21: -0.2 | AU21: -0.17 | AV21: -0.12 | AW21: -0.12 | AX21: -0.14 | AY21: -0.12 | AZ21: -0.06 | BA21: -0.03 | BB21: -0.03 | BC21: -0.06 | BD21: -0.05 | BE21: -0.05 | BF21: -0.05 | BG21: -0.04 | BH21: -0.09 | BI21: -0.07 | BJ21: -0.06 | BK21: -0.06 | BL21: -0.23 | BM21: -0.21 | BN21: -0.48 | BO21: -0.2 | BP21: -0.16 | BQ21: -0.18 | BR21: -0.22 | BS21: -0.13 | BT21: -0.19 | BU21: -0.2 | BV21: -0.23 | BW21: -0.17 | BX21: -0.17 | BY21: -0.16 | BZ21: -0.16 | CA21: -0.11 | CB21: -0.16 | CC21: -0.13 | CD21: -0.13
B22: Value added by
B23: Agriculture | C23: 0.21 | D23: 0.29 | E23: 0.3 | F23: 0.3 | G23: 0.31 | H23: 0.28 | I23: 0.26 | J23: 0.26 | K23: 0.25 | L23: 0.25 | M23: 0.25 | N23: 0.24 | O23: 0.24 | P23: 0.25 | Q23: 0.26 | R23: 0.25 | S23: 0.26 | T23: 0.25 | U23: 0.25 | V23: 0.24 | W23: 0.24 | X23: 0.23 | Y23: 0.25 | Z23: 0.24 | AA23: 0.24 | AB23: 0.24 | AC23: 0.25 | AD23: 0.25 | AE23: 0.25 | AF23: 0.25 | AG23: 0.26 | AH23: 0.24 | AI23: 0.25 | AJ23: 0.25 | AK23: 0.25 | AL23: 0.24 | AM23: 0.24 | AN23: 0.24 | AO23: 0.24 | AP23: 0.24 | AQ23: 0.24 | AR23: 0.25 | AS23: 0.25 | AT23: 0.25 | AU23: 0.26 | AV23: 0.27 | AW23: 0.27 | AX23: 0.25 | AY23: 0.26 | AZ23: 0.24 | BA23: 0.26 | BB23: 0.16 | BC23: 0.26 | BD23: 0.21 | BE23: 0.24 | BF23: 0.15 | BG23: 0.26 | BH23: 0.23 | BI23: 0.28 | BJ23: 0.17 | BK23: 0.28 | BL23: 0.23 | BM23: 0.24 | BN23: 0.15 | BO23: 0.22 | BP23: 0.2 | BQ23: 0.24 | BR23: 0.16 | BS23: 0.27 | BT23: 0.22 | BU23: 0.27 | BV23: 0.16 | BW23: 0.26 | BX23: 0.22 | BY23: 0.23 | BZ23: 0.15 | CA23: 0.23 | CB23: 0.2 | CC23: 0.23 | CD23: 0.15
B24: Industry | C24: 0.22 | D24: 0.15 | E24: 0.15 | F24: 0.16 | G24: 0.16 | H24: 0.17 | I24: 0.16 | J24: 0.17 | K24: 0.17 | L24: 0.16 | M24: 0.16 | N24: 0.16 | O24: 0.16 | P24: 0.16 | Q24: 0.15 | R24: 0.15 | S24: 0.16 | T24: 0.16 | U24: 0.16 | V24: 0.16 | W24: 0.17 | X24: 0.18 | Y24: 0.17 | Z24: 0.18 | AA24: 0.19 | AB24: 0.18 | AC24: 0.17 | AD24: 0.18 | AE24: 0.2 | AF24: 0.18 | AG24: 0.18 | AH24: 0.18 | AI24: 0.17 | AJ24: 0.17 | AK24: 0.17 | AL24: 0.18 | AM24: 0.18 | AN24: 0.17 | AO24: 0.17 | AP24: 0.18 | AQ24: 0.18 | AR24: 0.17 | AS24: 0.17 | AT24: 0.16 | AU24: 0.17 | AV24: 0.17 | AW24: 0.17 | AX24: 0.17 | AY24: 0.18 | AZ24: 0.18 | BA24: 0.17 | BB24: 0.18 | BC24: 0.17 | BD24: 0.19 | BE24: 0.19 | BF24: 0.21 | BG24: 0.19 | BH24: 0.2 | BI24: 0.19 | BJ24: 0.19 | BK24: 0.19 | BL24: 0.21 | BM24: 0.19 | BN24: 0.23 | BO24: 0.22 | BP24: 0.24 | BQ24: 0.22 | BR24: 0.22 | BS24: 0.2 | BT24: 0.23 | BU24: 0.2 | BV24: 0.23 | BW24: 0.21 | BX24: 0.24 | BY24: 0.22 | BZ24: 0.22 | CA24: 0.21 | CB24: 0.24 | CC24: 0.21 | CD24: 0.22
B25: Services | C25: 0.52 | D25: 0.46 | E25: 0.46 | F25: 0.45 | G25: 0.44 | H25: 0.47 | I25: 0.49 | J25: 0.48 | K25: 0.49 | L25: 0.49 | M25: 0.5 | N25: 0.5 | O25: 0.49 | P25: 0.49 | Q25: 0.49 | R25: 0.5 | S25: 0.49 | T25: 0.5 | U25: 0.51 | V25: 0.5 | W25: 0.49 | X25: 0.48 | Y25: 0.47 | Z25: 0.48 | AA25: 0.48 | AB25: 0.49 | AC25: 0.49 | AD25: 0.48 | AE25: 0.48 | AF25: 0.49 | AG25: 0.49 | AH25: 0.5 | AI25: 0.51 | AJ25: 0.49 | AK25: 0.49 | AL25: 0.49 | AM25: 0.5 | AN25: 0.51 | AO25: 0.5 | AP25: 0.5 | AQ25: 0.49 | AR25: 0.49 | AS25: 0.49 | AT25: 0.5 | AU25: 0.49 | AV25: 0.47 | AW25: 0.47 | AX25: 0.49 | AY25: 0.48 | AZ25: 0.5 | BA25: 0.48 | BB25: 0.57 | BC25: 0.49 | BD25: 0.52 | BE25: 0.49 | BF25: 0.56 | BG25: 0.48 | BH25: 0.49 | BI25: 0.46 | BJ25: 0.56 | BK25: 0.46 | BL25: 0.5 | BM25: 0.5 | BN25: 0.57 | BO25: 0.5 | BP25: 0.51 | BQ25: 0.49 | BR25: 0.57 | BS25: 0.48 | BT25: 0.5 | BU25: 0.48 | BV25: 0.56 | BW25: 0.49 | BX25: 0.49 | BY25: 0.5 | BZ25: 0.57 | CA25: 0.52 | CB25: 0.51 | CC25: 0.5 | CD25: 0.57
B26: Adjustments | C26: 0.05 | D26: 0.09 | E26: 0.09 | F26: 0.09 | G26: 0.09 | H26: 0.09 | I26: 0.09 | J26: 0.09 | K26: 0.09 | L26: 0.1 | M26: 0.09 | N26: 0.1 | O26: 0.1 | P26: 0.1 | Q26: 0.1 | R26: 0.09 | S26: 0.09 | T26: 0.09 | U26: 0.09 | V26: 0.1 | W26: 0.1 | X26: 0.11 | Y26: 0.11 | Z26: 0.1 | AA26: 0.09 | AB26: 0.09 | AC26: 0.08 | AD26: 0.08 | AE26: 0.07 | AF26: 0.07 | AG26: 0.08 | AH26: 0.08 | AI26: 0.08 | AJ26: 0.08 | AK26: 0.09 | AL26: 0.09 | AM26: 0.08 | AN26: 0.08 | AO26: 0.09 | AP26: 0.09 | AQ26: 0.09 | AR26: 0.09 | AS26: 0.09 | AT26: 0.09 | AU26: 0.08 | AV26: 0.08 | AW26: 0.09 | AX26: 0.08 | AY26: 0.09 | AZ26: 0.08 | BA26: 0.08 | BB26: 0.09 | BC26: 0.08 | BD26: 0.09 | BE26: 0.09 | BF26: 0.08 | BG26: 0.08 | BH26: 0.08 | BI26: 0.08 | BJ26: 0.09 | BK26: 0.07 | BL26: 0.06 | BM26: 0.06 | BN26: 0.05 | BO26: 0.05 | BP26: 0.05 | BQ26: 0.06 | BR26: 0.06 | BS26: 0.05 | BT26: 0.05 | BU26: 0.05 | BV26: 0.06 | BW26: 0.04 | BX26: 0.05 | BY26: 0.05 | BZ26: 0.06 | CA26: 0.04 | CB26: 0.05 | CC26: 0.05 | CD26: 0.06
B28: National income and expenditure (Frw billions)
B29: Gross Domestic Product at current prices | C29: 19918 | D29: 401 | E29: 452 | F29: 479 | G29: 499 | H29: 506 | I29: 547 | J29: 574 | K29: 599 | L29: 608 | M29: 687 | N29: 750 | O29: 788 | P29: 786 | Q29: 774 | R29: 809 | S29: 855 | T29: 853 | U29: 858 | V29: 906 | W29: 955 | X29: 963 | Y29: 1000 | Z29: 1074 | AA29: 1096 | AB29: 1114 | AC29: 1144 | AD29: 1210 | AE29: 1234 | AF29: 1214 | AG29: 1253 | AH29: 1261 | AI29: 1329 | AJ29: 1355 | AK29: 1394 | AL29: 1437 | AM29: 1436 | AN29: 1465 | AO29: 1500 | AP29: 1568 | AQ29: 1617 | AR29: 1661 | AS29: 1711 | AT29: 1696 | AU29: 1778 | AV29: 1846 | AW29: 1917 | AX29: 1944 | AY29: 1988 | AZ29: 2016 | BA29: 2132 | BB29: 1884 | BC29: 2277 | BD29: 2160 | BE29: 2468 | BF29: 2195 | BG29: 2637 | BH29: 2395 | BI29: 2413 | BJ29: 2221 | BK29: 2862 | BL29: 2574 | BM29: 2841 | BN29: 2598 | BO29: 3112 | BP29: 3101 | BQ29: 3549 | BR29: 3304 | BS29: 4210 | BT29: 4031 | BU29: 4255 | BV29: 3875 | BW29: 5016 | BX29: 4514 | BY29: 4965 | BZ29: 4659 | CA29: 5780 | CB29: 5276 | CC29: 5799 | CD29: 5525
B30: Factor income from abroad, net | C30: -450 | D30: -4 | E30: -4 | F30: -4 | G30: -4 | H30: -2 | I30: -2 | J30: -2 | K30: -2 | L30: -5 | M30: -5 | N30: -5 | O30: -5 | P30: -5 | Q30: -5 | R30: -5 | S30: -5 | T30: -7 | U30: -7 | V30: -8 | W30: -8 | X30: -9 | Y30: -9 | Z30: -9 | AA30: -9 | AB30: -16 | AC30: -16 | AD30: -16 | AE30: -16 | AF30: -21 | AG30: -21 | AH30: -21 | AI30: -22 | AJ30: -32 | AK30: -32 | AL30: -32 | AM30: -33 | AN30: -24 | AO30: -33 | AP30: -25 | AQ30: -35 | AR30: -35 | AS30: -51 | AT30: -46 | AU30: -55 | AV30: -48 | AW30: -61 | AX30: -67 | AY30: -67 | AZ30: -73 | BA30: -80 | BB30: -72 | BC30: -72 | BD30: -79 | BE30: -76 | BF30: -76 | BG30: -65 | BH30: -53 | BI30: -48 | BJ30: -48 | BK30: -39 | BL30: -48 | BM30: -40 | BN30: -45 | BO30: -41 | BP30: -70 | BQ30: -45 | BR30: -76 | BS30: -58 | BT30: -58 | BU30: -75 | BV30: -94 | BW30: -93 | BX30: -106 | BY30: -111 | BZ30: -114 | CA30: -119 | CB30: -119 | CC30: -125 | CD30: -123
B31: Gross National Income | C31: 19468 | D31: 397 | E31: 448 | F31: 475 | G31: 495 | H31: 504 | I31: 545 | J31: 571 | K31: 597 | L31: 603 | M31: 682 | N31: 745 | O31: 783 | P31: 781 | Q31: 769 | R31: 804 | S31: 850 | T31: 846 | U31: 850 | V31: 898 | W31: 948 | X31: 955 | Y31: 991 | Z31: 1066 | AA31: 1087 | AB31: 1099 | AC31: 1128 | AD31: 1194 | AE31: 1218 | AF31: 1193 | AG31: 1232 | AH31: 1240 | AI31: 1307 | AJ31: 1323 | AK31: 1362 | AL31: 1405 | AM31: 1403 | AN31: 1441 | AO31: 1467 | AP31: 1543 | AQ31: 1582 | AR31: 1626 | AS31: 1660 | AT31: 1650 | AU31: 1722 | AV31: 1798 | AW31: 1856 | AX31: 1876 | AY31: 1921 | AZ31: 1944 | BA31: 2052 | BB31: 1812 | BC31: 2205 | BD31: 2081 | BE31: 2392 | BF31: 2119 | BG31: 2572 | BH31: 2342 | BI31: 2365 | BJ31: 2174 | BK31: 2824 | BL31: 2526 | BM31: 2801 | BN31: 2552 | BO31: 3071 | BP31: 3031 | BQ31: 3504 | BR31: 3228 | BS31: 4152 | BT31: 3973 | BU31: 4180 | BV31: 3782 | BW31: 4922 | BX31: 4408 | BY31: 4854 | BZ31: 4545 | CA31: 5661 | CB31: 5157 | CC31: 5673 | CD31: 5402
B32: Current transfers, net | C32: 1028 | D32: 45 | E32: 45 | F32: 45 | G32: 45 | H32: 63 | I32: 63 | J32: 63 | K32: 63 | L32: 71 | M32: 70 | N32: 71 | O32: 72 | P32: 85 | Q32: 85 | R32: 85 | S32: 85 | T32: 83 | U32: 84 | V32: 86 | W32: 86 | X32: 119 | Y32: 120 | Z32: 120 | AA32: 120 | AB32: 96 | AC32: 96 | AD32: 97 | AE32: 99 | AF32: 117 | AG32: 119 | AH32: 120 | AI32: 123 | AJ32: 97 | AK32: 98 | AL32: 99 | AM32: 100 | AN32: 46 | AO32: 66 | AP32: 77 | AQ32: 79 | AR32: 65 | AS32: 70 | AT32: 65 | AU32: 71 | AV32: 91 | AW32: 133 | AX32: 127 | AY32: 144 | AZ32: 130 | BA32: 124 | BB32: 155 | BC32: 166 | BD32: 136 | BE32: 98 | BF32: 129 | BG32: 161 | BH32: 141 | BI32: 136 | BJ32: 149 | BK32: 160 | BL32: 175 | BM32: 195 | BN32: 176 | BO32: 203 | BP32: 239 | BQ32: 366 | BR32: 186 | BS32: 218 | BT32: 173 | BU32: 384 | BV32: 242 | BW32: 231 | BX32: 205 | BY32: 335 | BZ32: 218 | CA32: 270 | CB32: 215 | CC32: 283 | CD32: 292
B33: Gross National Disposible Income | C33: 20496 | D33: 442 | E33: 492 | F33: 520 | G33: 540 | H33: 567 | I33: 608 | J33: 635 | K33: 660 | L33: 673 | M33: 752 | N33: 816 | O33: 855 | P33: 866 | Q33: 854 | R33: 889 | S33: 936 | T33: 929 | U33: 934 | V33: 984 | W33: 1033 | X33: 1074 | Y33: 1111 | Z33: 1185 | AA33: 1207 | AB33: 1194 | AC33: 1224 | AD33: 1291 | AE33: 1318 | AF33: 1310 | AG33: 1350 | AH33: 1360 | AI33: 1430 | AJ33: 1421 | AK33: 1461 | AL33: 1504 | AM33: 1503 | AN33: 1487 | AO33: 1533 | AP33: 1620 | AQ33: 1661 | AR33: 1691 | AS33: 1730 | AT33: 1714 | AU33: 1793 | AV33: 1889 | AW33: 1990 | AX33: 2004 | AY33: 2066 | AZ33: 2074 | BA33: 2176 | BB33: 1967 | BC33: 2371 | BD33: 2217 | BE33: 2491 | BF33: 2248 | BG33: 2732 | BH33: 2483 | BI33: 2501 | BJ33: 2322 | BK33: 2984 | BL33: 2701 | BM33: 2996 | BN33: 2728 | BO33: 3274 | BP33: 3270 | BQ33: 3870 | BR33: 3414 | BS33: 4370 | BT33: 4146 | BU33: 4564 | BV33: 4024 | BW33: 5153 | BX33: 4613 | BY33: 5189 | BZ33: 4763 | CA33: 5931 | CB33: 5372 | CC33: 5957 | CD33: 5695
B34: Less Final consumption expenditure | C34: -15959 | D34: -392 | E34: -429 | F34: -469 | G34: -476 | H34: -458 | I34: -502 | J34: -530 | K34: -555 | L34: -579 | M34: -633 | N34: -715 | O34: -727 | P34: -730 | Q34: -735 | R34: -781 | S34: -819 | T34: -812 | U34: -824 | V34: -862 | W34: -904 | X34: -881 | Y34: -956 | Z34: -1012 | AA34: -1015 | AB34: -1035 | AC34: -1095 | AD34: -1158 | AE34: -1097 | AF34: -1096 | AG34: -1118 | AH34: -1163 | AI34: -1238 | AJ34: -1274 | AK34: -1292 | AL34: -1375 | AM34: -1285 | AN34: -1378 | AO34: -1437 | AP34: -1506 | AQ34: -1491 | AR34: -1499 | AS34: -1613 | AT34: -1624 | AU34: -1613 | AV34: -1634 | AW34: -1709 | AX34: -1746 | AY34: -1743 | AZ34: -1785 | BA34: -1876 | BB34: -1591 | BC34: -1962 | BD34: -1851 | BE34: -2126 | BF34: -1723 | BG34: -2168 | BH34: -2144 | BI34: -2171 | BJ34: -1911 | BK34: -2561 | BL34: -2254 | BM34: -2498 | BN34: -2826 | BO34: -2632 | BP34: -2467 | BQ34: -2857 | BR34: -2584 | BS34: -3366 | BT34: -3319 | BU34: -3584 | BV34: -2896 | BW34: -4136 | BX34: -3471 | BY34: -4060 | BZ34: -3658 | CA34: -4770 | CB34: -4071 | CC34: -4828 | CD34: -4169
B35: Gross National Saving | C35: 4537 | D35: 51 | E35: 63 | F35: 51 | G35: 64 | H35: 110 | I35: 105 | J35: 105 | K35: 105 | L35: 95 | M35: 119 | N35: 100 | O35: 128 | P35: 136 | Q35: 119 | R35: 108 | S35: 116 | T35: 116 | U35: 111 | V35: 121 | W35: 130 | X35: 194 | Y35: 155 | Z35: 173 | AA35: 192 | AB35: 159 | AC35: 129 | AD35: 133 | AE35: 221 | AF35: 214 | AG35: 232 | AH35: 197 | AI35: 192 | AJ35: 147 | AK35: 168 | AL35: 129 | AM35: 218 | AN35: 109 | AO35: 96 | AP35: 114 | AQ35: 170 | AR35: 192 | AS35: 117 | AT35: 90 | AU35: 180 | AV35: 256 | AW35: 281 | AX35: 258 | AY35: 322 | AZ35: 289 | BA35: 300 | BB35: 377 | BC35: 409 | BD35: 366 | BE35: 364 | BF35: 525 | BG35: 565 | BH35: 339 | BI35: 330 | BJ35: 411 | BK35: 423 | BL35: 447 | BM35: 498 | BN35: -98 | BO35: 642 | BP35: 802 | BQ35: 1013 | BR35: 830 | BS35: 1004 | BT35: 827 | BU35: 979 | BV35: 1128 | BW35: 1017 | BX35: 1141 | BY35: 1129 | BZ35: 1106 | CA35: 1161 | CB35: 1302 | CC35: 1129 | CD35: 1526
B36: Less Gross capital formation | C36: -6916 | D36: -59 | E36: -72 | F36: -68 | G36: -77 | H36: -87 | I36: -86 | J36: -95 | K36: -106 | L36: -110 | M36: -157 | N36: -156 | O36: -182 | P36: -191 | Q36: -171 | R36: -153 | S36: -163 | T36: -186 | U36: -167 | V36: -174 | W36: -207 | X36: -221 | Y36: -194 | Z36: -211 | AA36: -238 | AB36: -258 | AC36: -244 | AD36: -273 | AE36: -321 | AF36: -306 | AG36: -300 | AH36: -296 | AI36: -333 | AJ36: -326 | AK36: -325 | AL36: -280 | AM36: -375 | AN36: -359 | AO36: -363 | AP36: -350 | AQ36: -419 | AR36: -466 | AS36: -442 | AT36: -403 | AU36: -461 | AV36: -442 | AW36: -436 | AX36: -470 | AY36: -487 | AZ36: -356 | BA36: -329 | BB36: -356 | BC36: -448 | BD36: -420 | BE36: -472 | BF36: -585 | BG36: -572 | BH36: -462 | BI36: -416 | BJ36: -446 | BK36: -475 | BL36: -908 | BM36: -936 | BN36: -1009 | BO36: -1089 | BP36: -1139 | BQ36: -1348 | BR36: -1458 | BS36: -1404 | BT36: -1468 | BU36: -1510 | BV36: -1886 | BW36: -1725 | BX36: -1809 | BY36: -1696 | BZ36: -1754 | CA36: -1656 | CB36: -2029 | CC36: -1743 | CD36: -2064
B37: Net lending to the rest of the world | C37: -2379 | D37: -8 | E37: -8 | F37: -17 | G37: -13 | H37: 23 | I37: 19 | J37: 10 | K37: -1 | L37: -15 | M37: -38 | N37: -56 | O37: -54 | P37: -55 | Q37: -52 | R37: -44 | S37: -46 | T37: -70 | U37: -56 | V37: -52 | W37: -77 | X37: -27 | Y37: -39 | Z37: -38 | AA37: -46 | AB37: -99 | AC37: -115 | AD37: -139 | AE37: -100 | AF37: -92 | AG37: -68 | AH37: -99 | AI37: -141 | AJ37: -179 | AK37: -157 | AL37: -151 | AM37: -157 | AN37: -250 | AO37: -267 | AP37: -235 | AQ37: -249 | AR37: -274 | AS37: -325 | AT37: -313 | AU37: -281 | AV37: -186 | AW37: -155 | AX37: -211 | AY37: -164 | AZ37: -67 | BA37: -28 | BB37: 21 | BC37: -38 | BD37: -54 | BE37: -108 | BF37: -61 | BG37: -7 | BH37: -123 | BI37: -86 | BJ37: -35 | BK37: -53 | BL37: -461 | BM37: -438 | BN37: -1107 | BO37: -447 | BP37: -337 | BQ37: -335 | BR37: -628 | BS37: -401 | BT37: -641 | BU37: -531 | BV37: -759 | BW37: -708 | BX37: -668 | BY37: -568 | BZ37: -649 | CA37: -494 | CB37: -727 | CC37: -614 | CD37: -538
B39: Memorandum items
B40: Total population (millions) | D40: 8.8 | E40: 8.9 | F40: 8.9 | G40: 9 | H40: 9.1 | I40: 9.1 | J40: 9.2 | K40: 9.2 | L40: 9.3 | M40: 9.3 | N40: 9.4 | O40: 9.5 | P40: 9.5 | Q40: 9.6 | R40: 9.7 | S40: 9.7 | T40: 9.8 | U40: 9.8 | V40: 9.9 | W40: 10 | X40: 10 | Y40: 10.1 | Z40: 10.2 | AA40: 10.2 | AB40: 10.3 | AC40: 10.4 | AD40: 10.4 | AE40: 10.5 | AF40: 10.5 | AG40: 10.6 | AH40: 10.7 | AI40: 10.7 | AJ40: 10.8 | AK40: 10.9 | AL40: 10.9 | AM40: 11 | AN40: 11.1 | AO40: 11.1 | AP40: 11.2 | AQ40: 11.3 | AR40: 11.3 | AS40: 11.4 | AT40: 11.5 | AU40: 11.5 | AV40: 11.6 | AW40: 11.7 | AX40: 11.7 | AY40: 11.8 | AZ40: 11.879655 | BA40: 11.949558 | BB40: 12.019581 | BC40: 12.089721 | BD40: 12.161228 | BE40: 12.232194 | BF40: 12.303252 | BG40: 12.374397 | BH40: 12.446965 | BI40: 12.518942 | BJ40: 12.590993 | BK40: 12.663116 | BL40: 12.736698 | BM40: 12.809655 | BN40: 12.882678 | BO40: 12.955763 | BP40: 13.030536 | BQ40: 13.104459 | BR40: 13.178373 | BS40: 13.252272 | BT40: 13.327927 | BU40: 13.402665 | BV40: 13.477369 | BW40: 13.552035 | BX40: 13.628523 | BY40: 13.704026 | BZ40: 13.779473 | CA40: 13.854858 | CB40: 13.932178 | CC40: 14.008398 | CD40: 14.084523
B41: Growth rate | D41: 0 | E41: 0 | F41: 0 | G41: 0 | H41: 0.026 | I41: 0.026 | J41: 0.026 | K41: 0.026 | L41: 0.026 | M41: 0.026 | N41: 0.026 | O41: 0.026 | P41: 0.026 | Q41: 0.026 | R41: 0.026 | S41: 0.026 | T41: 0.026 | U41: 0.026 | V41: 0.026 | W41: 0.026 | X41: 0.026 | Y41: 0.026 | Z41: 0.026 | AA41: 0.026 | AB41: 0.026 | AC41: 0.026 | AD41: 0.026 | AE41: 0.026 | AF41: 0.025 | AG41: 0.024 | AH41: 0.024 | AI41: 0.024 | AJ41: 0.024 | AK41: 0.024 | AL41: 0.024 | AM41: 0.024 | AN41: 0.024 | AO41: 0.024 | AP41: 0.024 | AQ41: 0.024 | AR41: 0.024 | AS41: 0.024 | AT41: 0.024 | AU41: 0.024 | AV41: 0.024 | AW41: 0.024 | AX41: 0.024 | AY41: 0.024 | AZ41: 0.024 | BA41: 0.021 | BB41: 0.027 | BC41: 0.025 | BD41: 0.024 | BE41: 0.024 | BF41: 0.024 | BG41: 0.024 | BH41: 0.023 | BI41: 0.023 | BJ41: 0.023 | BK41: 0.023 | BL41: 0.023 | BM41: 0.023 | BN41: 0.023 | BO41: 0.023 | BP41: 0.023 | BQ41: 0.023 | BR41: 0.023 | BS41: 0.023 | BT41: 0.023 | BU41: 0.023 | BV41: 0.023 | BW41: 0.023 | BX41: 0.023 | BY41: 0.022 | BZ41: 0.022 | CA41: 0.022 | CB41: 0.022 | CC41: 0.022 | CD41: 0.022
B42: Exchange rate: Frw per US dollar | D42: 554 | E42: 552 | F42: 551 | G42: 550 | H42: 548 | I42: 546 | J42: 548 | K42: 546 | L42: 544 | M42: 543 | N42: 547 | O42: 553 | P42: 566 | Q42: 568 | R42: 569 | S42: 570 | T42: 573 | U42: 579 | V42: 589 | W42: 592 | X42: 599 | Y42: 601 | Z42: 600 | AA42: 602 | AB42: 605 | AC42: 609 | AD42: 615 | AE42: 628 | AF42: 633 | AG42: 640 | AH42: 649 | AI42: 664 | AJ42: 675 | AK42: 681 | AL42: 684 | AM42: 691 | AN42: 702 | AO42: 713 | AP42: 725 | AQ42: 739 | AR42: 759 | AS42: 776 | AT42: 800 | AU42: 815 | AV42: 823 | AW42: 828 | AX42: 834 | AY42: 842 | AZ42: 849 | BA42: 856 | BB42: 864 | BC42: 875 | BD42: 884 | BE42: 893 | BF42: 904 | BG42: 916 | BH42: 927 | BI42: 933 | BJ42: 947 | BK42: 966 | BL42: 976 | BM42: 983 | BN42: 992 | BO42: 1004 | BP42: 1014 | BQ42: 1021 | BR42: 1032 | BS42: 1055 | BT42: 1088 | BU42: 1127 | BV42: 1187 | BW42: 1239 | BX42: 1279 | BY42: 1300 | BZ42: 1327 | CA42: 1367 | CB42: 1400 | CC42: 1420 | CD42: 1443
B43: Growth rate | D43: 0 | E43: 0 | F43: 0 | G43: 0 | H43: -0.01 | I43: -0.01 | J43: -0.01 | K43: -0.01 | L43: -0.01 | M43: -0.01 | N43: 0 | O43: 0.01 | P43: 0.04 | Q43: 0.05 | R43: 0.04 | S43: 0.03 | T43: 0.01 | U43: 0.02 | V43: 0.04 | W43: 0.04 | X43: 0.05 | Y43: 0.04 | Z43: 0.02 | AA43: 0.02 | AB43: 0.01 | AC43: 0.01 | AD43: 0.02 | AE43: 0.04 | AF43: 0.05 | AG43: 0.05 | AH43: 0.06 | AI43: 0.06 | AJ43: 0.07 | AK43: 0.06 | AL43: 0.05 | AM43: 0.04 | AN43: 0.04 | AO43: 0.05 | AP43: 0.06 | AQ43: 0.07 | AR43: 0.08 | AS43: 0.09 | AT43: 0.1 | AU43: 0.1 | AV43: 0.08 | AW43: 0.07 | AX43: 0.04 | AY43: 0.03 | AZ43: 0.03 | BA43: 0.03 | BB43: 0.04 | BC43: 0.04 | BD43: 0.04 | BE43: 0.04 | BF43: 0.05 | BG43: 0.05 | BH43: 0.05 | BI43: 0.04 | BJ43: 0.05 | BK43: 0.05 | BL43: 0.05 | BM43: 0.05 | BN43: 0.05 | BO43: 0.04 | BP43: 0.04 | BQ43: 0.04 | BR43: 0.04 | BS43: 0.05 | BT43: 0.07 | BU43: 0.1 | BV43: 0.15 | BW43: 0.17 | BX43: 0.18 | BY43: 0.15 | BZ43: 0.12 | CA43: 0.1 | CB43: 0.09 | CC43: 0.09 | CD43: 0.09
B45: Source: National Institute of Statistics of Rwanda
B46: 46007 | BL46: =BL36/BL29 -> -0.35275835 | BM46: =BM36/BM29 -> -0.32946146 | BN46: =BN36/BN29 -> -0.38837567 | BO46: =BO36/BO29 -> -0.34993573 | BP46: =BP36/BP29 -> -0.36730087 | BQ46: =BQ36/BQ29 -> -0.3798253 | BR46: =BR36/BR29 -> -0.44128329 | BS46: =BS36/BS29 -> -0.33349169 | ... CD46: =CD36/CD29 -> -0.37357466

Sheet QGDP_CP
B1: Table 1
B2: Gross Domestic Product by Kind of Activity
B3: at current prices
B4: (in billion Rwf) | D4: Base year
B5: Activity description | C5: ISIC4 | D5: =QGDP_KP!$D$5 -> 2024 | E5: 2006 Q1 | F5: 2006 Q2 | G5: 2006 Q3 | H5: 2006 Q4 | I5: 2007 Q1 | J5: 2007 Q2 | K5: 2007 Q3 | L5: 2007 Q4 | M5: 2008 Q1 | N5: 2008 Q2 | O5: 2008 Q3 | P5: 2008 Q4 | Q5: 2009 Q1 | R5: 2009 Q2 | S5: 2009 Q3 | T5: 2009 Q4 | U5: 2010 Q1 | V5: 2010 Q2 | W5: 2010 Q3 | X5: 2010 Q4 | Y5: 2011 Q1 | Z5: 2011 Q2 | AA5: 2011 Q3 | AB5: 2011 Q4 | AC5: 2012 Q1 | AD5: 2012 Q2 | AE5: 2012 Q3 | AF5: 2012 Q4 | AG5: 2013 Q1 | AH5: 2013 Q2 | AI5: 2013 Q3 | AJ5: 2013 Q4 | AK5: 2014 Q1 | AL5: 2014 Q2 | AM5: 2014 Q3 | AN5: 2014 Q4 | AO5: 2015 Q1 | AP5: 2015 Q2 | AQ5: 2015 Q3 | AR5: 2015 Q4 | AS5: 2016 Q1 | AT5: 2016 Q2 | AU5: 2016 Q3 | AV5: 2016 Q4 | AW5: 2017 Q1 | AX5: 2017 Q2 | AY5: 2017 Q3 | AZ5: 2017 Q4 | BA5: 2018 Q1 | BB5: 2018 Q2 | BC5: 2018 Q3 | BD5: 2018 Q4 | BE5: 2019 Q1 | BF5: 2019 Q2 | BG5: 2019 Q3 | BH5: 2019 Q4 | BI5: 2020 Q1 | BJ5: 2020 Q2 | BK5: 2020 Q3 | BL5: 2020 Q4 | BM5: 2021 Q1 | BN5: 2021 Q2 | BO5: 2021 Q3 | BP5: 2021 Q4 | BQ5: 2022 Q1 | BR5: 2022 Q2 | BS5: 2022 Q3 | BT5: 2022 Q4 | BU5: 2023 Q1 | BV5: 2023 Q2 | BW5: 2023 Q3 | BX5: 2023 Q4 | BY5: 2024 Q1 | BZ5: 2024 Q2 | CA5: 2024 Q3 | CB5: 2024 Q4 | CC5: 2025 Q1 | CD5: 2025 Q2 | CE5: 2025 Q3 | DD5: SUT
B7: GROSS DOMESTIC PRODUCT (GDP) | D7: 19918 | E7: 396 | F7: 446 | G7: 472 | H7: 492 | I7: 499 | J7: 540 | K7: 566 | L7: 592 | M7: 600 | N7: 679 | O7: 741 | P7: 779 | Q7: 777 | R7: 765 | S7: 799 | T7: 844 | U7: 842 | V7: 848 | W7: 895 | X7: 944 | Y7: 952 | Z7: 987 | AA7: 1062 | AB7: 1083 | AC7: 1100 | AD7: 1128 | AE7: 1195 | AF7: 1219 | AG7: 1196 | AH7: 1235 | AI7: 1245 | AJ7: 1312 | AK7: 1336 | AL7: 1403 | AM7: 1296 | AN7: 1513 | AO7: 1451 | AP7: 1511 | AQ7: 1418 | AR7: 1701 | AS7: 1617 | AT7: 1707 | AU7: 1538 | AV7: 1906 | AW7: 1830 | AX7: 1964 | AY7: 1722 | AZ7: 2105 | BA7: 2016 | BB7: 2132 | BC7: 1884 | BD7: 2277 | BE7: 2160 | BF7: 2468 | BG7: 2195 | BH7: 2637 | BI7: 2395 | BJ7: 2413 | BK7: 2221 | BL7: 2862 | BM7: 2574 | BN7: 2841 | BO7: 2598 | BP7: 3112 | BQ7: 3101 | BR7: 3549 | BS7: 3304 | BT7: 4210 | BU7: 4031 | BV7: 4255 | BW7: 3875 | BX7: 5016 | BY7: 4514 | BZ7: 4965 | CA7: 4659 | CB7: 5780 | CC7: 5276 | CD7: 5799 | CE7: 5525 | DD7: KP | DE7: Check KP=CP
B9: AGRICULTURE, FORESTRY & FISHING | C9: A | D9: 4142 | E9: 113 | F9: 129 | G9: 136 | H9: 147 | I9: 133 | J9: 133 | K9: 142 | L9: 143 | M9: 148 | N9: 164 | O9: 175 | P9: 183 | Q9: 184 | R9: 189 | S9: 194 | T9: 210 | U9: 200 | V9: 203 | W9: 210 | X9: 214 | Y9: 207 | Z9: 233 | AA9: 248 | AB9: 248 | AC9: 251 | AD9: 271 | AE9: 287 | AF9: 296 | AG9: 289 | AH9: 302 | AI9: 292 | AJ9: 308 | AK9: 323 | AL9: 356 | AM9: 209 | AN9: 426 | AO9: 339 | AP9: 376 | AQ9: 223 | AR9: 467 | AS9: 371 | AT9: 417 | AU9: 260 | AV9: 596 | AW9: 490 | AX9: 558 | AY9: 273 | AZ9: 633 | BA9: 477 | BB9: 554 | BC9: 300 | BD9: 603 | BE9: 456 | BF9: 583 | BG9: 319 | BH9: 682 | BI9: 558 | BJ9: 673 | BK9: 369 | BL9: 792 | BM9: 597 | BN9: 693 | BO9: 398 | BP9: 697 | BQ9: 614 | BR9: 846 | BS9: 514 | BT9: 1132 | BU9: 900 | BV9: 1150 | BW9: 629 | BX9: 1295 | BY9: 987 | BZ9: 1131 | CA9: 699 | CB9: 1324 | CC9: 1080 | CD9: 1341 | CE9: 812
B10: Food crops | C10: AA | D10: 2373 | E10: 49 | F10: 55 | G10: 68 | H10: 75 | I10: 70 | J10: 68 | K10: 72 | L10: 73 | M10: 72 | N10: 75 | O10: 81 | P10: 89 | Q10: 93 | R10: 93 | S10: 98 | T10: 113 | U10: 105 | V10: 99 | W10: 103 | X10: 107 | Y10: 110 | Z10: 125 | AA10: 121 | AB10: 129 | AC10: 139 | AD10: 153 | AE10: 150 | AF10: 150 | AG10: 168 | AH10: 175 | AI10: 158 | AJ10: 170 | AK10: 192 | AL10: 221 | AM10: 61 | AN10: 275 | AO10: 200 | AP10: 227 | AQ10: 64 | AR10: 313 | AS10: 211 | AT10: 262 | AU10: 93 | AV10: 422 | AW10: 330 | AX10: 389 | AY10: 81 | AZ10: 423 | BA10: 273 | BB10: 343 | BC10: 76 | BD10: 369 | BE10: 245 | BF10: 358 | BG10: 84 | BH10: 440 | BI10: 319 | BJ10: 434 | BK10: 116 | BL10: 535 | BM10: 333 | BN10: 431 | BO10: 108 | BP10: 413 | BQ10: 305 | BR10: 507 | BS10: 149 | BT10: 734 | BU10: 545 | BV10: 786 | BW10: 239 | BX10: 884 | BY10: 583 | BZ10: 722 | CA10: 205 | CB10: 863 | CC10: 600 | CD10: 814 | CE10: 223
B11: Export crops | C11: AB | D11: 351 | E11: 12 | F11: 15 | G11: 14 | H11: 16 | I11: 9 | J11: 9 | K11: 12 | L11: 11 | M11: 11 | N11: 16 | O11: 15 | P11: 13 | Q11: 11 | R11: 14 | S11: 14 | T11: 13 | U11: 13 | V11: 17 | W11: 19 | X11: 16 | Y11: 10 | Z11: 11 | AA11: 28 | AB11: 18 | AC11: 9 | AD11: 12 | AE11: 29 | AF11: 36 | AG11: 11 | AH11: 15 | AI11: 20 | AJ11: 22 | AK11: 13 | AL11: 17 | AM11: 28 | AN11: 29 | AO11: 14 | AP11: 22 | AQ11: 30 | AR11: 23 | AS11: 26 | AT11: 18 | AU11: 27 | AV11: 33 | AW11: 24 | AX11: 29 | AY11: 37 | AZ11: 48 | BA11: 31 | BB11: 28 | BC11: 38 | BD11: 47 | BE11: 25 | BF11: 28 | BG11: 36 | BH11: 36 | BI11: 29 | BJ11: 28 | BK11: 40 | BL11: 46 | BM11: 34 | BN11: 30 | BO11: 49 | BP11: 46 | BQ11: 39 | BR11: 52 | BS11: 82 | BT11: 88 | BU11: 53 | BV11: 52 | BW11: 71 | BX11: 83 | BY11: 70 | BZ11: 66 | CA11: 134 | CB11: 82 | CC11: 88 | CD11: 119 | CE11: 170
B12: Livestock & livestock products | C12: AC | D12: 581 | E12: 12 | F12: 12 | G12: 13 | H12: 13 | I12: 13 | J12: 13 | K12: 13 | L12: 14 | M12: 15 | N12: 16 | O12: 18 | P12: 19 | Q12: 20 | R12: 20 | S12: 20 | T12: 20 | U12: 20 | V12: 21 | W12: 21 | X12: 22 | Y12: 22 | Z12: 23 | AA12: 24 | AB12: 25 | AC12: 25 | AD12: 26 | AE12: 27 | AF12: 28 | AG12: 28 | AH12: 29 | AI12: 30 | AJ12: 30 | AK12: 31 | AL12: 32 | AM12: 33 | AN12: 34 | AO12: 34 | AP12: 35 | AQ12: 37 | AR12: 38 | AS12: 40 | AT12: 41 | AU12: 42 | AV12: 43 | AW12: 45 | AX12: 46 | AY12: 47 | AZ12: 48 | BA12: 51 | BB12: 51 | BC12: 52 | BD12: 52 | BE12: 53 | BF12: 58 | BG12: 61 | BH12: 69 | BI12: 68 | BJ12: 72 | BK12: 71 | BL12: 77 | BM12: 80 | BN12: 78 | BO12: 86 | BP12: 80 | BQ12: 91 | BR12: 99 | BS12: 100 | BT12: 110 | BU12: 108 | BV12: 114 | BW12: 123 | BX12: 132 | BY12: 132 | BZ12: 135 | CA12: 149 | CB12: 165 | CC12: 176 | CD12: 187 | CE12: 190
B13: Forestry | C13: AD | D13: 782 | E13: 38 | F13: 45 | G13: 40 | H13: 42 | I13: 40 | J13: 42 | K13: 43 | L13: 44 | M13: 48 | N13: 55 | O13: 58 | P13: 59 | Q13: 57 | R13: 60 | S13: 59 | T13: 61 | U13: 57 | V13: 63 | W13: 64 | X13: 66 | Y13: 61 | Z13: 70 | AA13: 71 | AB13: 72 | AC13: 73 | AD13: 75 | AE13: 77 | AF13: 78 | AG13: 77 | AH13: 79 | AI13: 79 | AJ13: 80 | AK13: 81 | AL13: 81 | AM13: 82 | AN13: 83 | AO13: 84 | AP13: 86 | AQ13: 86 | AR13: 87 | AS13: 88 | AT13: 90 | AU13: 91 | AV13: 91 | AW13: 84 | AX13: 87 | AY13: 101 | AZ13: 107 | BA13: 113 | BB13: 124 | BC13: 126 | BD13: 127 | BE13: 125 | BF13: 131 | BG13: 130 | BH13: 129 | BI13: 135 | BJ13: 132 | BK13: 135 | BL13: 127 | BM13: 143 | BN13: 146 | BO13: 145 | BP13: 149 | BQ13: 170 | BR13: 179 | BS13: 171 | BT13: 189 | BU13: 184 | BV13: 187 | BW13: 183 | BX13: 186 | BY13: 192 | BZ13: 194 | CA13: 196 | CB13: 201 | CC13: 203 | CD13: 207 | CE13: 214
B14: Fishing | C14: AE | D14: 54 | E14: 2 | F14: 2 | G14: 2 | H14: 2 | I14: 2 | J14: 2 | K14: 2 | L14: 2 | M14: 2 | N14: 2 | O14: 3 | P14: 3 | Q14: 3 | R14: 3 | S14: 3 | T14: 3 | U14: 3 | V14: 3 | W14: 3 | X14: 3 | Y14: 3 | Z14: 4 | AA14: 4 | AB14: 4 | AC14: 4 | AD14: 5 | AE14: 4 | AF14: 4 | AG14: 4 | AH14: 5 | AI14: 5 | AJ14: 6 | AK14: 5 | AL14: 5 | AM14: 6 | AN14: 6 | AO14: 6 | AP14: 6 | AQ14: 6 | AR14: 7 | AS14: 6 | AT14: 6 | AU14: 7 | AV14: 7 | AW14: 7 | AX14: 7 | AY14: 7 | AZ14: 8 | BA14: 8 | BB14: 8 | BC14: 8 | BD14: 7 | BE14: 7 | BF14: 8 | BG14: 8 | BH14: 8 | BI14: 6 | BJ14: 6 | BK14: 7 | BL14: 7 | BM14: 7 | BN14: 9 | BO14: 9 | BP14: 9 | BQ14: 9 | BR14: 10 | BS14: 11 | BT14: 12 | BU14: 10 | BV14: 11 | BW14: 11 | BX14: 11 | BY14: 11 | BZ14: 13 | CA14: 16 | CB14: 14 | CC14: 13 | CD14: 14 | CE14: 15
B15: INDUSTRY | C15: B-F | D15: 4396 | E15: 61 | F15: 70 | G15: 77 | H15: 82 | I15: 84 | J15: 89 | K15: 97 | L15: 102 | M15: 99 | N15: 112 | O15: 123 | P15: 127 | Q15: 126 | R15: 118 | S15: 125 | T15: 137 | U15: 139 | V15: 133 | W15: 146 | X15: 165 | Y15: 178 | Z15: 169 | AA15: 193 | AB15: 210 | AC15: 196 | AD15: 197 | AE15: 223 | AF15: 241 | AG15: 221 | AH15: 219 | AI15: 223 | AJ15: 228 | AK15: 236 | AL15: 238 | AM15: 259 | AN15: 254 | AO15: 254 | AP15: 256 | AQ15: 275 | AR15: 288 | AS15: 290 | AT15: 285 | AU15: 278 | AV15: 299 | AW15: 314 | AX15: 328 | AY15: 337 | AZ15: 351 | BA15: 372 | BB15: 370 | BC15: 339 | BD15: 379 | BE15: 400 | BF15: 463 | BG15: 464 | BH15: 492 | BI15: 476 | BJ15: 448 | BK15: 427 | BL15: 543 | BM15: 541 | BN15: 545 | BO15: 588 | BP15: 683 | BQ15: 730 | BR15: 779 | BS15: 719 | BT15: 853 | BU15: 910 | BV15: 836 | BW15: 874 | BX15: 1069 | BY15: 1087 | BZ15: 1069 | CA15: 1033 | CB15: 1206 | CC15: 1247 | CD15: 1242 | CE15: 1232
B16: Mining & quarrying | C16: B | D16: 354 | E16: 3 | F16: 5 | G16: 5 | H16: 6 | I16: 7 | J16: 9 | K16: 8 | L16: 10 | M16: 9 | N16: 13 | O16: 10 | P16: 9 | Q16: 7 | R16: 6 | S16: 7 | T16: 7 | U16: 5 | V16: 8 | W16: 10 | X16: 13 | Y16: 20 | Z16: 19 | AA16: 21 | AB16: 22 | AC16: 19 | AD16: 17 | AE16: 20 | AF16: 21 | AG16: 24 | AH16: 26 | AI16: 25 | AJ16: 26 | AK16: 27 | AL16: 26 | AM16: 38 | AN16: 28 | AO16: 26 | AP16: 24 | AQ16: 29 | AR16: 26 | AS16: 22 | AT16: 27 | AU16: 28 | AV16: 34 | AW16: 34 | AX16: 35 | AY16: 44 | AZ16: 53 | BA16: 47 | BB16: 48 | BC16: 43 | BD16: 39 | BE16: 35 | BF16: 33 | BG16: 30 | BH16: 24 | BI16: 28 | BJ16: 21 | BK16: 22 | BL16: 34 | BM16: 46 | BN16: 45 | BO16: 76 | BP16: 88 | BQ16: 88 | BR16: 86 | BS16: 68 | BT16: 67 | BU16: 63 | BV16: 67 | BW16: 72 | BX16: 81 | BY16: 89 | BZ16: 87 | CA16: 88 | CB16: 91 | CC16: 98 | CD16: 104 | CE16: 106
B17: TOTAL MANUFACTURING | C17: C | D17: 1618 | E17: 35 | F17: 39 | G17: 45 | H17: 46 | I17: 40 | J17: 41 | K17: 49 | L17: 51 | M17: 47 | N17: 54 | O17: 61 | P17: 63 | Q17: 59 | R17: 60 | S17: 66 | T17: 72 | U17: 69 | V17: 67 | W17: 77 | X17: 82 | Y17: 75 | Z17: 79 | AA17: 95 | AB17: 96 | AC17: 88 | AD17: 93 | AE17: 103 | AF17: 105 | AG17: 83 | AH17: 85 | AI17: 89 | AJ17: 87 | AK17: 90 | AL17: 93 | AM17: 100 | AN17: 100 | AO17: 100 | AP17: 101 | AQ17: 108 | AR17: 110 | AS17: 114 | AT17: 114 | AU17: 111 | AV17: 120 | AW17: 142 | AX17: 153 | AY17: 146 | AZ17: 149 | BA17: 153 | BB17: 158 | BC17: 140 | BD17: 178 | BE17: 174 | BF17: 204 | BG17: 170 | BH17: 219 | BI17: 198 | BJ17: 203 | BK17: 182 | BL17: 247 | BM17: 229 | BN17: 255 | BO17: 220 | BP17: 290 | BQ17: 284 | BR17: 345 | BS17: 284 | BT17: 389 | BU17: 382 | BV17: 362 | BW17: 313 | BX17: 416 | BY17: 390 | BZ17: 396 | CA17: 361 | CB17: 471 | CC17: 470 | CD17: 479 | CE17: 442
B18: Of which: Food | C18: CA | D18: 383 | E18: 6 | F18: 8 | G18: 11 | H18: 11 | I18: 7 | J18: 7 | K18: 11 | L18: 10 | M18: 10 | N18: 11 | O18: 14 | P18: 13 | Q18: 13 | R18: 14 | S18: 17 | T18: 15 | U18: 16 | V18: 16 | W18: 19 | X18: 18 | Y18: 14 | Z18: 17 | AA18: 25 | AB18: 26 | AC18: 17 | AD18: 18 | AE18: 26 | AF18: 28 | AG18: 25 | AH18: 23 | AI18: 23 | AJ18: 24 | AK18: 24 | AL18: 25 | AM18: 27 | AN18: 28 | AO18: 27 | AP18: 26 | AQ18: 26 | AR18: 29 | AS18: 33 | AT18: 30 | AU18: 26 | AV18: 35 | AW18: 51 | AX18: 58 | AY18: 50 | AZ18: 52 | BA18: 36 | BB18: 52 | BC18: 28 | BD18: 57 | BE18: 41 | BF18: 69 | BG18: 37 | BH18: 76 | BI18: 51 | BJ18: 71 | BK18: 36 | BL18: 76 | BM18: 53 | BN18: 77 | BO18: 48 | BP18: 93 | BQ18: 69 | BR18: 126 | BS18: 73 | BT18: 149 | BU18: 104 | BV18: 136 | BW18: 74 | BX18: 148 | BY18: 87 | BZ18: 110 | CA18: 63 | CB18: 123 | CC18: 96 | CD18: 143 | CE18: 85
B19: Beverages & tobacco | C19: CB | D19: 486 | E19: 7 | F19: 7 | G19: 10 | H19: 11 | I19: 8 | J19: 9 | K19: 11 | L19: 11 | M19: 10 | N19: 11 | O19: 15 | P19: 16 | Q19: 15 | R19: 16 | S19: 19 | T19: 22 | U19: 16 | V19: 17 | W19: 23 | X19: 22 | Y19: 18 | Z19: 19 | AA19: 24 | AB19: 22 | AC19: 22 | AD19: 23 | AE19: 27 | AF19: 27 | AG19: 25 | AH19: 27 | AI19: 29 | AJ19: 28 | AK19: 29 | AL19: 29 | AM19: 32 | AN19: 32 | AO19: 32 | AP19: 31 | AQ19: 35 | AR19: 33 | AS19: 34 | AT19: 34 | AU19: 37 | AV19: 35 | AW19: 39 | AX19: 39 | AY19: 40 | AZ19: 41 | BA19: 53 | BB19: 40 | BC19: 38 | BD19: 45 | BE19: 53 | BF19: 45 | BG19: 41 | BH19: 53 | BI19: 63 | BJ19: 40 | BK19: 44 | BL19: 62 | BM19: 77 | BN19: 49 | BO19: 51 | BP19: 73 | BQ19: 87 | BR19: 65 | BS19: 62 | BT19: 88 | BU19: 109 | BV19: 76 | BW19: 76 | BX19: 106 | BY19: 145 | BZ19: 99 | CA19: 99 | CB19: 143 | CC19: 180 | CD19: 119 | CE19: 120
B20: Textiles, clothing & leather goods | C20: CC | D20: 135 | E20: 12 | F20: 13 | G20: 12 | H20: 12 | I20: 12 | J20: 13 | K20: 14 | L20: 15 | M20: 15 | N20: 17 | O20: 16 | P20: 15 | Q20: 17 | R20: 15 | S20: 15 | T20: 15 | U20: 16 | V20: 16 | W20: 16 | X20: 19 | Y20: 21 | Z20: 19 | AA20: 20 | AB20: 21 | AC20: 22 | AD20: 24 | AE20: 21 | AF20: 21 | AG20: 5 | AH20: 5 | AI20: 5 | AJ20: 5 | AK20: 5 | AL20: 6 | AM20: 6 | AN20: 6 | AO20: 5 | AP20: 6 | AQ20: 6 | AR20: 6 | AS20: 6 | AT20: 6 | AU20: 6 | AV20: 7 | AW20: 8 | AX20: 9 | AY20: 8 | AZ20: 8 | BA20: 14 | BB20: 14 | BC20: 15 | BD20: 15 | BE20: 15 | BF20: 17 | BG20: 18 | BH20: 19 | BI20: 19 | BJ20: 18 | BK20: 20 | BL20: 21 | BM20: 20 | BN20: 22 | BO20: 22 | BP20: 24 | BQ20: 22 | BR20: 24 | BS20: 24 | BT20: 26 | BU20: 25 | BV20: 27 | BW20: 30 | BX20: 32 | BY20: 30 | BZ20: 35 | CA20: 36 | CB20: 33 | CC20: 31 | CD20: 32 | CE20: 34
... B26: Electricity | C26: D | D26: 147 | E26: 2 | F26: 2 | G26: 3 | H26: 4 | I26: 5 | J26: 7 | K26: 7 | L26: 6 | M26: 5 | N26: 4 | O26: 4 | P26: 4 | Q26: 5 | R26: 5 | S26: 5 | T26: 5 | U26: 5 | V26: 6 | W26: 6 | X26: 6 | Y26: 6 | Z26: 7 | AA26: 7 | AB26: 8 | AC26: 8 | AD26: 8 | AE26: 9 | AF26: 10 | AG26: 10 | AH26: 10 | AI26: 10 | AJ26: 11 | AK26: 11 | AL26: 11 | AM26: 11 | AN26: 12 | AO26: 12 | AP26: 12 | AQ26: 14 | AR26: 18 | AS26: 19 | AT26: 19 | AU26: 19 | AV26: 20 | AW26: 20 | AX26: 21 | AY26: 21 | AZ26: 22 | BA26: 20 | BB26: 20 | BC26: 27 | BD26: 28 | BE26: 27 | BF26: 27 | BG26: 28 | BH26: 27 | BI26: 28 | BJ26: 28 | BK26: 32 | BL26: 34 | BM26: 32 | BN26: 36 | BO26: 35 | BP26: 33 | BQ26: 29 | BR26: 27 | BS26: 26 | BT26: 25 | BU26: 24 | BV26: 27 | BW26: 29 | BX26: 30 | BY26: 32 | BZ26: 37 | CA26: 39 | CB26: 39 | CC26: 38 | CD26: 41 | CE26: 52
B27: Water & waste management | C27: E | D27: 78 | E27: 2 | F27: 2 | G27: 2 | H27: 3 | I27: 4 | J27: 6 | K27: 6 | L27: 5 | M27: 4 | N27: 3 | O27: 3 | P27: 3 | Q27: 4 | R27: 4 | S27: 4 | T27: 4 | U27: 4 | V27: 5 | W27: 5 | X27: 5 | Y27: 5 | Z27: 5 | AA27: 6 | AB27: 6 | AC27: 6 | AD27: 6 | AE27: 6 | AF27: 6 | AG27: 6 | AH27: 6 | AI27: 6 | AJ27: 6 | AK27: 6 | AL27: 7 | AM27: 7 | AN27: 7 | AO27: 7 | AP27: 7 | AQ27: 7 | AR27: 8 | AS27: 8 | AT27: 8 | AU27: 8 | AV27: 8 | AW27: 8 | AX27: 8 | AY27: 8 | AZ27: 8 | BA27: 8 | BB27: 8 | BC27: 9 | BD27: 9 | BE27: 13 | BF27: 15 | BG27: 16 | BH27: 15 | BI27: 16 | BJ27: 16 | BK27: 17 | BL27: 16 | BM27: 17 | BN27: 17 | BO27: 18 | BP27: 18 | BQ27: 18 | BR27: 18 | BS27: 19 | BT27: 18 | BU27: 18 | BV27: 18 | BW27: 19 | BX27: 19 | BY27: 19 | BZ27: 19 | CA27: 20 | CB27: 20 | CC27: 20 | CD27: 20 | CE27: 21 | CF27: =CF28/SUM(BY15:CB15) -> 0.5003413
B28: Construction | C28: F | D28: 2198 | E28: 19 | F28: 22 | G28: 22 | H28: 24 | I28: 28 | J28: 26 | K28: 27 | L28: 30 | M28: 34 | N28: 38 | O28: 44 | P28: 48 | Q28: 51 | R28: 44 | S28: 41 | T28: 49 | U28: 55 | V28: 47 | W28: 48 | X28: 58 | Y28: 71 | Z28: 59 | AA28: 64 | AB28: 78 | AC28: 75 | AD28: 73 | AE28: 84 | AF28: 99 | AG28: 97 | AH28: 92 | AI28: 92 | AJ28: 97 | AK28: 101 | AL28: 101 | AM28: 104 | AN28: 107 | AO28: 109 | AP28: 112 | AQ28: 117 | AR28: 126 | AS28: 127 | AT28: 117 | AU28: 112 | AV28: 118 | AW28: 111 | AX28: 111 | AY28: 117 | AZ28: 119 | BA28: 144 | BB28: 136 | BC28: 120 | BD28: 126 | BE28: 151 | BF28: 184 | BG28: 220 | BH28: 206 | BI28: 205 | BJ28: 181 | BK28: 175 | BL28: 212 | BM28: 218 | BN28: 192 | BO28: 239 | BP28: 253 | BQ28: 312 | BR28: 302 | BS28: 323 | BT28: 353 | BU28: 422 | BV28: 362 | BW28: 442 | BX28: 523 | BY28: 558 | BZ28: 531 | CA28: 525 | CB28: 585 | CC28: 620 | CD28: 598 | CE28: 611 | CF28: =SUM(BY28:CB28) -> 2199
B29: SERVICES | C29: G-T | D29: 10396 | E29: 186 | F29: 208 | G29: 216 | H29: 219 | I29: 236 | J29: 267 | K29: 277 | L29: 292 | M29: 296 | N29: 341 | O29: 372 | P29: 388 | Q29: 387 | R29: 383 | S29: 408 | T29: 419 | U29: 425 | V29: 434 | W29: 452 | X29: 470 | Y29: 465 | Z29: 474 | AA29: 517 | AB29: 524 | AC29: 551 | AD29: 565 | AE29: 585 | AF29: 597 | AG29: 599 | AH29: 619 | AI29: 629 | AJ29: 671 | AK29: 666 | AL29: 680 | AM29: 704 | AN29: 717 | AO29: 741 | AP29: 744 | AQ29: 780 | AR29: 794 | AS29: 814 | AT29: 842 | AU29: 852 | AV29: 866 | AW29: 870 | AX29: 908 | AY29: 956 | AZ29: 949 | BA29: 998 | BB29: 1029 | BC29: 1081 | BD29: 1117 | BE29: 1118 | BF29: 1210 | BG29: 1229 | BH29: 1256 | BI29: 1164 | BJ29: 1106 | BK29: 1235 | BL29: 1321 | BM29: 1289 | BN29: 1429 | BO29: 1471 | BP29: 1561 | BQ29: 1587 | BR29: 1727 | BS29: 1869 | BT29: 2020 | BU29: 2014 | BV29: 2045 | BW29: 2151 | BX29: 2436 | BY29: 2224 | BZ29: 2501 | CA29: 2668 | CB29: 3004 | CC29: 2688 | CD29: 2903 | CE29: 3161
B30: TRADE &TRANSPORT | C30: G-H | D30: 3594 | E30: 43 | F30: 53 | G30: 55 | H30: 56 | I30: 55 | J30: 63 | K30: 65 | L30: 76 | M30: 72 | N30: 93 | O30: 108 | P30: 103 | Q30: 102 | R30: 100 | S30: 104 | T30: 111 | U30: 112 | V30: 113 | W30: 121 | X30: 128 | Y30: 121 | Z30: 124 | AA30: 145 | AB30: 148 | AC30: 149 | AD30: 152 | AE30: 176 | AF30: 172 | AG30: 159 | AH30: 170 | AI30: 180 | AJ30: 190 | AK30: 182 | AL30: 183 | AM30: 192 | AN30: 197 | AO30: 202 | AP30: 201 | AQ30: 207 | AR30: 213 | AS30: 218 | AT30: 230 | AU30: 227 | AV30: 222 | AW30: 224 | AX30: 238 | AY30: 260 | AZ30: 269 | BA30: 280 | BB30: 294 | BC30: 315 | BD30: 334 | BE30: 323 | BF30: 352 | BG30: 367 | BH30: 382 | BI30: 334 | BJ30: 304 | BK30: 354 | BL30: 428 | BM30: 381 | BN30: 426 | BO30: 444 | BP30: 480 | BQ30: 489 | BR30: 570 | BS30: 579 | BT30: 648 | BU30: 602 | BV30: 623 | BW30: 667 | BX30: 771 | BY30: 713 | BZ30: 876 | CA30: 935 | CB30: 1070 | CC30: 948 | CD30: 1043 | CE30: 1140
B31: Maintenance & repair of motor vehicles | C31: GA | D31: 128 | E31: 2 | F31: 2 | G31: 2 | H31: 2 | I31: 2 | J31: 3 | K31: 3 | L31: 3 | M31: 3 | N31: 4 | O31: 5 | P31: 5 | Q31: 5 | R31: 5 | S31: 5 | T31: 5 | U31: 5 | V31: 5 | W31: 5 | X31: 6 | Y31: 6 | Z31: 6 | AA31: 6 | AB31: 6 | AC31: 7 | AD31: 7 | AE31: 7 | AF31: 7 | AG31: 7 | AH31: 7 | AI31: 7 | AJ31: 8 | AK31: 8 | AL31: 8 | AM31: 8 | AN31: 8 | AO31: 8 | AP31: 8 | AQ31: 8 | AR31: 9 | AS31: 9 | AT31: 9 | AU31: 10 | AV31: 10 | AW31: 10 | AX31: 10 | AY31: 10 | AZ31: 10 | BA31: 14 | BB31: 14 | BC31: 12 | BD31: 7 | BE31: 8 | BF31: 12 | BG31: 15 | BH31: 20 | BI31: 11 | BJ31: 15 | BK31: 19 | BL31: 20 | BM31: 19 | BN31: 21 | BO31: 21 | BP31: 22 | BQ31: 22 | BR31: 24 | BS31: 25 | BT31: 26 | BU31: 26 | BV31: 27 | BW31: 28 | BX31: 28 | BY31: 27 | BZ31: 31 | CA31: 32 | CB31: 38 | CC31: 42 | CD31: 43 | CE31: 46
B32: Wholesale & retail trade | C32: GB | D32: 1822 | E32: 27 | F32: 34 | G32: 34 | H32: 35 | I32: 34 | J32: 40 | K32: 41 | L32: 49 | M32: 46 | N32: 61 | O32: 72 | P32: 67 | Q32: 68 | R32: 64 | S32: 66 | T32: 69 | U32: 71 | V32: 71 | W32: 77 | X32: 82 | Y32: 77 | Z32: 79 | AA32: 93 | AB32: 95 | AC32: 95 | AD32: 95 | AE32: 111 | AF32: 107 | AG32: 97 | AH32: 106 | AI32: 112 | AJ32: 119 | AK32: 116 | AL32: 116 | AM32: 123 | AN32: 127 | AO32: 132 | AP32: 130 | AQ32: 132 | AR32: 135 | AS32: 143 | AT32: 146 | AU32: 141 | AV32: 130 | AW32: 135 | AX32: 145 | AY32: 156 | AZ32: 161 | BA32: 158 | BB32: 162 | BC32: 174 | BD32: 188 | BE32: 177 | BF32: 196 | BG32: 178 | BH32: 183 | BI32: 161 | BJ32: 163 | BK32: 177 | BL32: 212 | BM32: 190 | BN32: 220 | BO32: 242 | BP32: 247 | BQ32: 245 | BR32: 286 | BS32: 286 | BT32: 314 | BU32: 309 | BV32: 328 | BW32: 341 | BX32: 399 | BY32: 356 | BZ32: 462 | CA32: 452 | CB32: 552 | CC32: 477 | CD32: 549 | CE32: 559
B33: Transport | C33: HA | D33: 1644 | E33: 14 | F33: 16 | G33: 18 | H33: 19 | I33: 19 | J33: 20 | K33: 21 | L33: 24 | M33: 24 | N33: 28 | O33: 32 | P33: 31 | Q33: 29 | R33: 32 | S33: 33 | T33: 37 | U33: 36 | V33: 37 | W33: 39 | X33: 40 | Y33: 38 | Z33: 40 | AA33: 46 | AB33: 47 | AC33: 48 | AD33: 50 | AE33: 58 | AF33: 58 | AG33: 55 | AH33: 56 | AI33: 61 | AJ33: 63 | AK33: 59 | AL33: 59 | AM33: 62 | AN33: 62 | AO33: 63 | AP33: 63 | AQ33: 67 | AR33: 70 | AS33: 67 | AT33: 74 | AU33: 77 | AV33: 83 | AW33: 80 | AX33: 84 | AY33: 94 | AZ33: 98 | BA33: 108 | BB33: 117 | BC33: 129 | BD33: 138 | BE33: 138 | BF33: 144 | BG33: 174 | BH33: 179 | BI33: 162 | BJ33: 127 | BK33: 158 | BL33: 195 | BM33: 172 | BN33: 184 | BO33: 180 | BP33: 211 | BQ33: 223 | BR33: 260 | BS33: 268 | BT33: 307 | BU33: 267 | BV33: 268 | BW33: 299 | BX33: 343 | BY33: 330 | BZ33: 383 | CA33: 451 | CB33: 480 | CC33: 429 | CD33: 452 | CE33: 535
B34: OTHER SERVICES | C34: I-T | D34: 6802 | E34: 143 | F34: 154 | G34: 161 | H34: 163 | I34: 180 | J34: 205 | K34: 212 | L34: 217 | M34: 224 | N34: 248 | O34: 263 | P34: 285 | Q34: 285 | R34: 283 | S34: 304 | T34: 308 | U34: 313 | V34: 321 | W34: 331 | X34: 341 | Y34: 344 | Z34: 350 | AA34: 371 | AB34: 376 | AC34: 401 | AD34: 413 | AE34: 409 | AF34: 425 | AG34: 440 | AH34: 449 | AI34: 449 | AJ34: 482 | AK34: 484 | AL34: 497 | AM34: 512 | AN34: 520 | AO34: 539 | AP34: 543 | AQ34: 572 | AR34: 580 | AS34: 596 | AT34: 613 | AU34: 625 | AV34: 644 | AW34: 646 | AX34: 670 | AY34: 697 | AZ34: 680 | BA34: 719 | BB34: 735 | BC34: 766 | BD34: 784 | BE34: 795 | BF34: 858 | BG34: 862 | BH34: 874 | BI34: 830 | BJ34: 802 | BK34: 881 | BL34: 893 | BM34: 907 | BN34: 1004 | BO34: 1027 | BP34: 1082 | BQ34: 1098 | BR34: 1157 | BS34: 1290 | BT34: 1372 | BU34: 1412 | BV34: 1422 | BW34: 1484 | BX34: 1665 | BY34: 1511 | BZ34: 1624 | CA34: 1733 | CB34: 1934 | CC34: 1740 | CD34: 1860 | CE34: 2021
B35: Hotels & restaurants | C35: I | D35: 681 | E35: 11 | F35: 12 | G35: 13 | H35: 13 | I35: 13 | J35: 15 | K35: 15 | L35: 16 | M35: 18 | N35: 17 | O35: 18 | P35: 18 | Q35: 18 | R35: 18 | S35: 19 | T35: 20 | U35: 20 | V35: 21 | W35: 21 | X35: 22 | Y35: 22 | Z35: 22 | AA35: 23 | AB35: 23 | AC35: 24 | AD35: 24 | AE35: 24 | AF35: 24 | AG35: 23 | AH35: 24 | AI35: 26 | AJ35: 27 | AK35: 28 | AL35: 29 | AM35: 31 | AN35: 31 | AO35: 31 | AP35: 33 | AQ35: 34 | AR35: 35 | AS35: 37 | AT35: 39 | AU35: 41 | AV35: 37 | AW35: 36 | AX35: 34 | AY35: 35 | AZ35: 35 | BA35: 42 | BB35: 42 | BC35: 46 | BD35: 50 | BE35: 52 | BF35: 55 | BG35: 60 | BH35: 57 | BI35: 43 | BJ35: 30 | BK35: 31 | BL35: 34 | BM35: 34 | BN35: 43 | BO35: 46 | BP35: 59 | BQ35: 68 | BR35: 90 | BS35: 104 | BT35: 104 | BU35: 95 | BV35: 96 | BW35: 111 | BX35: 124 | BY35: 137 | BZ35: 161 | CA35: 187 | CB35: 196 | CC35: 196 | CD35: 204 | CE35: 241
B36: Information & communication | C36: J | D36: 433 | E36: 7 | F36: 8 | G36: 9 | H36: 9 | I36: 10 | J36: 11 | K36: 11 | L36: 13 | M36: 12 | N36: 14 | O36: 16 | P36: 16 | Q36: 15 | R36: 16 | S36: 17 | T36: 19 | U36: 18 | V36: 19 | W36: 20 | X36: 20 | Y36: 19 | Z36: 21 | AA36: 23 | AB36: 23 | AC36: 25 | AD36: 27 | AE36: 29 | AF36: 28 | AG36: 24 | AH36: 27 | AI36: 27 | AJ36: 29 | AK36: 24 | AL36: 30 | AM36: 32 | AN36: 32 | AO36: 33 | AP36: 32 | AQ36: 35 | AR36: 35 | AS36: 34 | AT36: 37 | AU36: 32 | AV36: 35 | AW36: 32 | AX36: 34 | AY36: 32 | AZ36: 36 | BA36: 36 | BB36: 38 | BC36: 38 | BD36: 40 | BE36: 42 | BF36: 52 | BG36: 53 | BH36: 61 | BI36: 50 | BJ36: 55 | BK36: 63 | BL36: 62 | BM36: 58 | BN36: 80 | BO36: 64 | BP36: 68 | BQ36: 58 | BR36: 65 | BS36: 71 | BT36: 72 | BU36: 77 | BV36: 80 | BW36: 82 | BX36: 101 | BY36: 90 | BZ36: 109 | CA36: 107 | CB36: 126 | CC36: 99 | CD36: 106 | CE36: 111
B37: Financial services | C37: K | D37: 498 | E37: 7 | F37: 12 | G37: 13 | H37: 12 | I37: 9 | J37: 15 | K37: 16 | L37: 14 | M37: 10 | N37: 18 | O37: 15 | P37: 17 | Q37: 17 | R37: 15 | S37: 15 | T37: 13 | U37: 19 | V37: 17 | W37: 19 | X37: 20 | Y37: 23 | Z37: 26 | AA37: 25 | AB37: 20 | AC37: 28 | AD37: 33 | AE37: 28 | AF37: 32 | AG37: 36 | AH37: 35 | AI37: 31 | AJ37: 42 | AK37: 33 | AL37: 37 | AM37: 34 | AN37: 42 | AO37: 39 | AP37: 40 | AQ37: 42 | AR37: 39 | AS37: 40 | AT37: 37 | AU37: 43 | AV37: 44 | AW37: 45 | AX37: 45 | AY37: 53 | AZ37: 48 | BA37: 49 | BB37: 48 | BC37: 61 | BD37: 58 | BE37: 63 | BF37: 67 | BG37: 57 | BH37: 63 | BI37: 61 | BJ37: 59 | BK37: 69 | BL37: 66 | BM37: 78 | BN37: 84 | BO37: 88 | BP37: 95 | BQ37: 96 | BR37: 109 | BS37: 111 | BT37: 159 | BU37: 124 | BV37: 147 | BW37: 118 | BX37: 138 | BY37: 128 | BZ37: 120 | CA37: 122 | CB37: 128 | CC37: 134 | CD37: 142 | CE37: 156
B38: Real estate activities | C38: L | D38: 1372 | E38: 33 | F38: 32 | G38: 34 | H38: 34 | I38: 41 | J38: 51 | K38: 54 | L38: 57 | M38: 58 | N38: 67 | O38: 71 | P38: 84 | Q38: 81 | R38: 79 | S38: 89 | T38: 91 | U38: 84 | V38: 88 | W38: 91 | X38: 93 | Y38: 96 | Z38: 93 | AA38: 93 | AB38: 93 | AC38: 100 | AD38: 97 | AE38: 87 | AF38: 86 | AG38: 93 | AH38: 89 | AI38: 93 | AJ38: 92 | AK38: 104 | AL38: 97 | AM38: 100 | AN38: 100 | AO38: 106 | AP38: 101 | AQ38: 114 | AR38: 108 | AS38: 116 | AT38: 117 | AU38: 124 | AV38: 131 | AW38: 142 | AX38: 133 | AY38: 143 | AZ38: 141 | BA38: 158 | BB38: 160 | BC38: 167 | BD38: 170 | BE38: 180 | BF38: 200 | BG38: 189 | BH38: 186 | BI38: 193 | BJ38: 190 | BK38: 205 | BL38: 221 | BM38: 217 | BN38: 225 | BO38: 237 | BP38: 247 | BQ38: 249 | BR38: 251 | BS38: 263 | BT38: 278 | BU38: 347 | BV38: 301 | BW38: 316 | BX38: 324 | BY38: 314 | BZ38: 309 | CA38: 319 | CB38: 430 | CC38: 320 | CD38: 323 | CE38: 349
B39: Professional, scientific & technical activities | C39: M | D39: 588 | E39: 8 | F39: 8 | G39: 9 | H39: 9 | I39: 11 | J39: 13 | K39: 14 | L39: 14 | M39: 15 | N39: 17 | O39: 18 | P39: 21 | Q39: 21 | R39: 20 | S39: 23 | T39: 23 | U39: 21 | V39: 22 | W39: 23 | X39: 24 | Y39: 23 | Z39: 24 | AA39: 24 | AB39: 25 | AC39: 27 | AD39: 27 | AE39: 26 | AF39: 27 | AG39: 26 | AH39: 31 | AI39: 28 | AJ39: 32 | AK39: 27 | AL39: 29 | AM39: 27 | AN39: 27 | AO39: 32 | AP39: 33 | AQ39: 30 | AR39: 33 | AS39: 33 | AT39: 37 | AU39: 36 | AV39: 38 | AW39: 38 | AX39: 41 | AY39: 41 | AZ39: 44 | BA39: 45 | BB39: 48 | BC39: 49 | BD39: 52 | BE39: 54 | BF39: 58 | BG39: 58 | BH39: 63 | BI39: 62 | BJ39: 64 | BK39: 68 | BL39: 73 | BM39: 75 | BN39: 81 | BO39: 82 | BP39: 88 | BQ39: 90 | BR39: 99 | BS39: 102 | BT39: 111 | BU39: 114 | BV39: 126 | BW39: 134 | BX39: 139 | BY39: 134 | BZ39: 146 | CA39: 146 | CB39: 162 | CC39: 167 | CD39: 178 | CE39: 187
B40: Administrative & support service activities | C40: N | D40: 840 | E40: 11 | F40: 11 | G40: 12 | H40: 12 | I40: 14 | J40: 18 | K40: 19 | L40: 19 | M40: 20 | N40: 23 | O40: 24 | P40: 29 | Q40: 28 | R40: 27 | S40: 30 | T40: 31 | U40: 29 | V40: 30 | W40: 31 | X40: 32 | Y40: 30 | Z40: 31 | AA40: 33 | AB40: 34 | AC40: 35 | AD40: 36 | AE40: 37 | AF40: 37 | AG40: 38 | AH40: 39 | AI40: 37 | AJ40: 43 | AK40: 44 | AL40: 45 | AM40: 45 | AN40: 49 | AO40: 47 | AP40: 52 | AQ40: 57 | AR40: 62 | AS40: 61 | AT40: 62 | AU40: 64 | AV40: 65 | AW40: 66 | AX40: 68 | AY40: 70 | AZ40: 72 | BA40: 75 | BB40: 77 | BC40: 82 | BD40: 79 | BE40: 77 | BF40: 82 | BG40: 96 | BH40: 105 | BI40: 99 | BJ40: 89 | BK40: 102 | BL40: 99 | BM40: 99 | BN40: 113 | BO40: 115 | BP40: 118 | BQ40: 119 | BR40: 129 | BS40: 152 | BT40: 153 | BU40: 158 | BV40: 159 | BW40: 185 | BX40: 195 | BY40: 172 | BZ40: 215 | CA40: 233 | CB40: 220 | CC40: 190 | CD40: 245 | CE40: 266
... B44: Cultural, domestic & other services | C44: R-T | D44: 640 | E44: 26 | F44: 28 | G44: 28 | H44: 29 | I44: 32 | J44: 32 | K44: 33 | L44: 33 | M44: 35 | N44: 35 | O44: 38 | P44: 38 | Q44: 36 | R44: 36 | S44: 38 | T44: 39 | U44: 40 | V44: 39 | W44: 41 | X44: 41 | Y44: 43 | Z44: 41 | AA44: 42 | AB44: 44 | AC44: 46 | AD44: 47 | AE44: 50 | AF44: 52 | AG44: 54 | AH44: 58 | AI44: 56 | AJ44: 59 | AK44: 62 | AL44: 68 | AM44: 72 | AN44: 69 | AO44: 77 | AP44: 84 | AQ44: 84 | AR44: 85 | AS44: 88 | AT44: 89 | AU44: 92 | AV44: 93 | AW44: 94 | AX44: 96 | AY44: 99 | AZ44: 101 | BA44: 102 | BB44: 104 | BC44: 104 | BD44: 111 | BE44: 107 | BF44: 111 | BG44: 110 | BH44: 114 | BI44: 105 | BJ44: 104 | BK44: 110 | BL44: 110 | BM44: 108 | BN44: 113 | BO44: 114 | BP44: 122 | BQ44: 116 | BR44: 121 | BS44: 127 | BT44: 130 | BU44: 119 | BV44: 120 | BW44: 128 | BX44: 237 | BY44: 136 | BZ44: 154 | CA44: 167 | CB44: 183 | CC44: 170 | CD44: 186 | CE44: 193
