Workbook

Sheet CPI
B1: 44206 | C1: 44237 | D1: 44265 | E1: 44296 | F1: 44326 | G1: 44357 | H1: 44387 | I1: 44418 | J1: 44449 | K1: 44479 | L1: 44510 | M1: 44540 | N1: 44571 | O1: 44602 | P1: 44630 | Q1: 44661 | R1: 44691 | S1: 44722 | T1: 44752 | U1: 44783 | V1: 44814 | W1: 44844 | X1: 44875 | Y1: 44905 | Z1: 44927 | AA1: 44958 | AB1: 44986 | AC1: 45017 | AD1: 45047 | AE1: 45078 | AF1: 45108 | AG1: 45139 | AH1: 45170 | AI1: 45200 | AJ1: 45231 | AK1: 45261 | AL1: 45292 | AM1: 45323 | AN1: 45352 | AO1: 45383 | AP1: 45413 | AQ1: 45444 | AR1: 45474 | AS1: 45505 | AT1: 45536 | AU1: 45566 | AV1: 45597 | AW1: 45627 | AX1: 45667 | AY1: 45698 | AZ1: 45726 | BA1: 45757 | BB1: 45787 | BC1: 45818 | BD1: 45848 | BE1: 45879 | BF1: 45910 | BG1: 45940 | BH1: 45971 | BI1: 46001 | BJ1: 46032
A2: GENERAL INDEX (CPI) | B2: 126.91145 | C2: 127.37657 | D2: 129.15009 | E2: 129.358 | F2: 128.74001 | G2: 128.4763 | H2: 128.43823 | I2: 128.76423 | J2: 129.54092 | K2: 130.37251 | L2: 129.66066 | M2: 129.70577 | N2: 132.402 | O2: 134.75045 | P2: 138.87804 | Q2: 142.20278 | R2: 144.92668 | S2: 146.0306 | T2: 148.44115 | U2: 149.20045 | V2: 152.4045 | W2: 156.53324 | X2: 157.80845 | Y2: 157.76338 | Z2: 159.79331 | AA2: 162.72619 | AB2: 165.64946 | AC2: 167.51534 | AD2: 165.3675 | AE2: 166.02467 | AF2: 166.07225 | AG2: 167.50281 | AH2: 173.55876 | AI2: 174.03131 | AJ2: 172.256 | AK2: 167.93568 | AL2: 167.71952 | AM2: 170.75183 | AN2: 172.57499 | AO2: 175.03788 | AP2: 175.02122 | AQ2: 174.39977 | AR2: 174.15236 | AS2: 175.79548 | AT2: 177.92631 | AU2: 180.6 | AV2: 180.80922 | AW2: 179.3197 | AX2: 180.21178 | AY2: 181.42933 | AZ2: 183.85347 | BA2: 186.01397 | BB2: 187.08379 | BC2: 186.66722 | BD2: 186.90166 | BE2: 188.28822 | BF2: 190.87421 | BG2: 193.39084 | BH2: 193.74242 | BI2: 193.71329 | BJ2: 196.32439 | BK2: =BI20/AW20-1 -> 0.070368023 | BL2: Deflator CPI food and non-alcoholic beverages - Average Jan Jul 2016/2015 | BM2: =BK3 -> 0.054944104 | BN2: Food crops
A3: Food and non-alcoholic beverages | B3: 139.22677 | C3: 139.78038 | D3: 143.85495 | E3: 144.57344 | F3: 141.27955 | G3: 140.2038 | H3: 140.29021 | I3: 140.06467 | J3: 142.38103 | K3: 143.01947 | L3: 139.19382 | M3: 138.31137 | N3: 145.42646 | O3: 150.79934 | P3: 158.47997 | Q3: 167.24756 | R3: 175.52664 | S3: 175.34164 | T3: 180.41188 | U3: 180.93181 | V3: 189.63584 | W3: 199.77003 | X3: 202.34608 | Y3: 199.64434 | Z3: 205.0317 | AA3: 214.67695 | AB3: 223.96086 | AC3: 228.79356 | AD3: 220.12713 | AE3: 221.23709 | AF3: 221.53487 | AG3: 225.47528 | AH3: 245.83827 | AI3: 245.82165 | AJ3: 237.74033 | AK3: 222.92408 | AL3: 220.1039 | AM3: 228.20113 | AN3: 229.49192 | AO3: 232.37814 | AP3: 230.56297 | AQ3: 228.14728 | AR3: 224.82087 | AS3: 229.04457 | AT3: 234.7133 | AU3: 243.4 | AV3: 242.70685 | AW3: 236.20754 | AX3: 235.89028 | AY3: 238.50491 | AZ3: 244.20308 | BA3: 250.68292 | BB3: 251.84198 | BC3: 248.01315 | BD3: 239.29056 | BE3: 241.36484 | BF3: 244.49837 | BG3: 247.23448 | BH3: 246.21982 | BI3: 244.76651 | BJ3: 248.45718 | BK3: =BI21/AW21-1 -> 0.054944104 | BL3: Deflator general CPI - Average Jan-Jul 2016/2015 | BM3: =BK2 -> 0.070368023 | BN3: Export crops
A4: v Bread and cereals | B4: 133.07469 | C4: 132.72374 | D4: 132.42361 | E4: 130.36768 | F4: 130.55823 | G4: 129.44976 | H4: 129.60427 | I4: 129.15321 | J4: 129.13068 | K4: 129.20901 | L4: 130.68226 | M4: 133.95541 | N4: 136.7585 | O4: 139.09349 | P4: 142.92634 | Q4: 148.46383 | R4: 155.60201 | S4: 159.92205 | T4: 163.69947 | U4: 165.12548 | V4: 176.71331 | W4: 182.11361 | X4: 185.4059 | Y4: 190.27657 | Z4: 191.91464 | AA4: 190.47701 | AB4: 191.94079 | AC4: 194.33395 | AD4: 177.34099 | AE4: 180.81605 | AF4: 182.20393 | AG4: 183.03318 | AH4: 185.23705 | AI4: 187.48473 | AJ4: 189.0618 | AK4: 189.18632 | AL4: 190.49675 | AM4: 188.70338 | AN4: 187.65261 | AO4: 195.89768 | AP4: 186.96302 | AQ4: 182.12067 | AR4: 180.143 | AS4: 182.15219 | AT4: 181.82335 | AU4: 184.3 | AV4: 184.6751 | AW4: 185.82101 | AX4: 187.47398 | AY4: 187.57921 | AZ4: 188.5381 | BA4: 191.04861 | BB4: 195.35128 | BC4: 196.42578 | BD4: 196.19535 | BE4: 197.35373 | BF4: 199.99644 | BG4: 203.32154 | BH4: 208.22167 | BI4: 208.8238 | BJ4: 208.55582 | BK4: =BI22/AW22-1 -> 0.058088447 | BL4: Deflator CPI meat - Average Jan Jul 2016/2015 | BM4: =BK5 -> 0.2688991 | BN4: Livestock & livestock products
A5: v Meat | B5: 153.90139 | C5: 154.60568 | D5: 154.70202 | E5: 154.85221 | F5: 155.31881 | G5: 155.73178 | H5: 155.85834 | I5: 155.32774 | J5: 157.90731 | K5: 162.72687 | L5: 163.16041 | M5: 163.46179 | N5: 165.02677 | O5: 164.71003 | P5: 165.60764 | Q5: 170.58913 | R5: 172.37421 | S5: 181.36261 | T5: 183.889 | U5: 185.4238 | V5: 186.71755 | W5: 187.12997 | X5: 186.54655 | Y5: 188.26232 | Z5: 187.45075 | AA5: 187.84087 | AB5: 193.48714 | AC5: 201.40759 | AD5: 201.39707 | AE5: 205.58786 | AF5: 206.09583 | AG5: 205.72965 | AH5: 207.27789 | AI5: 207.29104 | AJ5: 208.39521 | AK5: 209.63599 | AL5: 215.05793 | AM5: 219.93418 | AN5: 221.2003 | AO5: 223.87064 | AP5: 225.5674 | AQ5: 226.78717 | AR5: 227.81796 | AS5: 237.18729 | AT5: 248.51193 | AU5: 253.8 | AV5: 258.32662 | AW5: 262.96271 | AX5: 280.97382 | AY5: 293.88028 | AZ5: 297.19214 | BA5: 299.6353 | BB5: 298.97139 | BC5: 299.03699 | BD5: 297.64641 | BE5: 297.54567 | BF5: 299.03785 | BG5: 302.45491 | BH5: 305.90247 | BI5: 307.31776 | BJ5: 318.40505 | BK5: =BI23/AW23-1 -> 0.2688991 | BL5: Deflator general CPI - Average Jan Jul 2016/2015 | BM5: =BK2 -> 0.070368023 | BN5: Forestry
A6: v Fish | B6: 125.22699 | C6: 122.72323 | D6: 122.93953 | E6: 122.28343 | F6: 122.86343 | G6: 123.04829 | H6: 122.38021 | I6: 122.85124 | J6: 128.10854 | K6: 137.88027 | L6: 135.98683 | M6: 127.45605 | N6: 128.56009 | O6: 126.39627 | P6: 127.51764 | Q6: 129.19837 | R6: 131.92676 | S6: 134.36405 | T6: 136.0735 | U6: 138.37648 | V6: 166.41446 | W6: 171.90401 | X6: 170.19453 | Y6: 164.55212 | Z6: 159.73191 | AA6: 158.16636 | AB6: 159.7683 | AC6: 160.23161 | AD6: 161.80677 | AE6: 163.27512 | AF6: 164.28383 | AG6: 165.82054 | AH6: 171.9771 | AI6: 176.36277 | AJ6: 177.00451 | AK6: 178.91049 | AL6: 188.06394 | AM6: 194.17537 | AN6: 195.71326 | AO6: 196.55323 | AP6: 197.40643 | AQ6: 197.66193 | AR6: 198.48857 | AS6: 202.41234 | AT6: 201.379 | AU6: 202.4 | AV6: 203.06752 | AW6: 205.07295 | AX6: 206.16158 | AY6: 207.57123 | AZ6: 209.43332 | BA6: 211.86915 | BB6: 212.59539 | BC6: 213.37171 | BD6: 215.26217 | BE6: 216.75453 | BF6: 217.57718 | BG6: 219.17751 | BH6: 219.56362 | BI6: 218.83834 | BJ6: 223.16059 | BK6: =BI24/AW24-1 -> 0.077980856 | BL6: Deflator CPI fish - Average Jan Jul 2016/2015 | BM6: =BK6 -> 0.077980856 | BN6: Fishing
A7: v Vegetables | B7: 144.7282 | C7: 147.08725 | D7: 159.11208 | E7: 158.41916 | F7: 147.26888 | G7: 146.80694 | H7: 149.55691 | I7: 149.75576 | J7: 152.0559 | K7: 148.68278 | L7: 133.54021 | M7: 127.6182 | N7: 142.7081 | O7: 155.64521 | P7: 160.69307 | Q7: 170.20871 | R7: 180.58854 | S7: 187.72014 | T7: 201.0081 | U7: 202.98949 | V7: 216.24781 | W7: 238.659 | X7: 243.68116 | Y7: 230.34516 | Z7: 241.72988 | AA7: 270.99495 | AB7: 294.45646 | AC7: 300.05395 | AD7: 287.89246 | AE7: 289.99454 | AF7: 287.50492 | AG7: 297.25666 | AH7: 341.85223 | AI7: 329.62356 | AJ7: 298.50086 | AK7: 254.09874 | AL7: 241.70451 | AM7: 265.57164 | AN7: 272.04961 | AO7: 272.36882 | AP7: 281.30413 | AQ7: 285.49624 | AR7: 280.69618 | AS7: 283.97154 | AT7: 294.41407 | AU7: 306.9 | AV7: 296.8555 | AW7: 271.5648 | AX7: 259.47116 | AY7: 264.54033 | AZ7: 280.18367 | BA7: 295.54167 | BB7: 287.66249 | BC7: 279.46609 | BD7: 261.78731 | BE7: 269.36375 | BF7: 275.96501 | BG7: 277.62714 | BH7: 266.7763 | BI7: 258.92144 | BJ7: 266.96606 | BK7: =BI25/AW25-1 -> -0.022544887 | BN7: INDUSTRY
A8: v Non-alcoholic beverages | B8: 130.68464 | C8: 131.43065 | D8: 131.07698 | E8: 130.7014 | F8: 130.6736 | G8: 130.79839 | H8: 131.13203 | I8: 131.25853 | J8: 131.84961 | K8: 133.92724 | L8: 133.79459 | M8: 135.08769 | N8: 134.98712 | O8: 135.05469 | P8: 135.64999 | Q8: 136.6267 | R8: 136.83746 | S8: 137.32339 | T8: 144.8172 | U8: 150.30121 | V8: 154.69786 | W8: 159.9411 | X8: 163.80785 | Y8: 164.75423 | Z8: 169.36432 | AA8: 170.87139 | AB8: 172.01708 | AC8: 173.05046 | AD8: 174.11426 | AE8: 175.56167 | AF8: 179.41281 | AG8: 180.99004 | AH8: 182.37004 | AI8: 182.46909 | AJ8: 184.12676 | AK8: 186.61332 | AL8: 188.5661 | AM8: 192.06069 | AN8: 191.96306 | AO8: 191.82902 | AP8: 192.23297 | AQ8: 191.52888 | AR8: 192.09259 | AS8: 192.34009 | AT8: 192.30824 | AU8: 192.5 | AV8: 193.84061 | AW8: 193.54906 | AX8: 195.77464 | AY8: 196.22794 | AZ8: 197.27477 | BA8: 198.05676 | BB8: 200.48192 | BC8: 203.67515 | BD8: 206.08451 | BE8: 208.19342 | BF8: 209.50636 | BG8: 209.33523 | BH8: 211.51412 | BI8: 211.94731 | BJ8: 215.17994 | BK8: =BI26/AW26-1 -> 0.062157279 | BL8: Deflator PPI Mining - Average Jan-Jul 2016/2015 | BM8: =PPI!CB9 -> 0.030580785 | BN8: Mining & quarrying
A9: Alcoholic beverages and tobacco | B9: 170.42403 | C9: 174.83384 | D9: 174.8078 | E9: 174.86321 | F9: 174.69525 | G9: 175.17315 | H9: 174.8323 | I9: 175.957 | J9: 176.07602 | K9: 176.64995 | L9: 177.0705 | M9: 176.54581 | N9: 180.0259 | O9: 180.27397 | P9: 180.93384 | Q9: 183.19149 | R9: 183.56832 | S9: 184.26984 | T9: 193.34435 | U9: 194.92229 | V9: 195.39294 | W9: 202.19727 | X9: 211.13549 | Y9: 217.51455 | Z9: 221.4963 | AA9: 222.02961 | AB9: 223.56593 | AC9: 221.4463 | AD9: 223.02605 | AE9: 226.14 | AF9: 221.03665 | AG9: 218.74306 | AH9: 219.15637 | AI9: 219.18963 | AJ9: 220.06592 | AK9: 221.56608 | AL9: 221.43428 | AM9: 223.55337 | AN9: 223.67397 | AO9: 223.51388 | AP9: 224.34091 | AQ9: 229.86128 | AR9: 229.93799 | AS9: 230.52139 | AT9: 231.14554 | AU9: 231.6 | AV9: 234.46878 | AW9: 232.44719 | AX9: 234.65043 | AY9: 234.64346 | AZ9: 236.08894 | BA9: 238.54795 | BB9: 241.08278 | BC9: 249.10731 | BD9: 258.02406 | BE9: 261.59385 | BF9: 265.87909 | BG9: 268.7265 | BH9: 272.53295 | BI9: 271.30191 | BJ9: 271.18054 | BK9: =BI27/AW27-1 -> 0.10805073 | BN9: TOTAL MANUFACTURING
A10: Clothing and footwear | B10: 128.85754 | C10: 128.81187 | D10: 128.60772 | E10: 129.20979 | F10: 129.28353 | G10: 129.58659 | H10: 129.56038 | I10: 130.42696 | J10: 130.59684 | K10: 132.28452 | L10: 132.6492 | M10: 133.42637 | N10: 133.81308 | O10: 134.795 | P10: 135.39226 | Q10: 136.67181 | R10: 138.18758 | S10: 140.6206 | T10: 142.08787 | U10: 142.92069 | V10: 144.54232 | W10: 145.55949 | X10: 146.11758 | Y10: 147.64419 | Z10: 148.29592 | AA10: 148.4847 | AB10: 148.65197 | AC10: 149.75056 | AD10: 150.13287 | AE10: 151.3707 | AF10: 152.12378 | AG10: 152.64671 | AH10: 153.10277 | AI10: 153.51017 | AJ10: 154.54432 | AK10: 155.14323 | AL10: 156.6621 | AM10: 157.36255 | AN10: 158.21656 | AO10: 158.53039 | AP10: 159.29289 | AQ10: 159.84405 | AR10: 160.03024 | AS10: 160.32669 | AT10: 161.31251 | AU10: 162.1 | AV10: 163.19446 | AW10: 163.83724 | AX10: 164.43865 | AY10: 164.95365 | AZ10: 165.42446 | BA10: 165.90988 | BB10: 166.32574 | BC10: 166.94213 | BD10: 167.65912 | BE10: 168.4272 | BF10: 168.85559 | BG10: 169.7604 | BH10: 170.36336 | BI10: 170.72308 | BJ10: 173.41258 | BK10: =BI28/AW28-1 -> 0.046375346 | BL10: Deflator PPI Manufacturing food - Average Jan Jul 2016/2015 | BM10: =PPI!CB11 -> 0.074333333 | BN10: Manufacturing of food
A11: Housing, water, electricity, gas and other fuels | B11: 120.54146 | C11: 120.76618 | D11: 121.319 | E11: 120.95817 | F11: 121.49804 | G11: 121.66888 | H11: 121.41711 | I11: 121.74393 | J11: 121.85511 | K11: 122.32538 | L11: 122.57169 | M11: 122.68319 | N11: 123.71317 | O11: 126.20824 | P11: 131.11192 | Q11: 131.61477 | R11: 131.22836 | S11: 131.31933 | T11: 130.54301 | U11: 130.89705 | V11: 131.49416 | W11: 133.19655 | X11: 133.40791 | Y11: 133.80766 | Z11: 134.00112 | AA11: 135.18288 | AB11: 135.5758 | AC11: 135.62165 | AD11: 135.9429 | AE11: 135.92363 | AF11: 134.87519 | AG11: 134.56849 | AH11: 135.86769 | AI11: 135.91471 | AJ11: 136.67373 | AK11: 135.84806 | AL11: 136.79854 | AM11: 138.48425 | AN11: 139.18042 | AO11: 138.28372 | AP11: 139.29466 | AQ11: 138.60303 | AR11: 140.8832 | AS11: 141.06109 | AT11: 141.23944 | AU11: 142.4 | AV11: 142.66385 | AW11: 142.29753 | AX11: 142.32077 | AY11: 142.47304 | AZ11: 142.74219 | BA11: 142.87444 | BB11: 143.86833 | BC11: 143.56319 | BD11: 143.38511 | BE11: 144.2593 | BF11: 146.97158 | BG11: 153.02361 | BH11: 153.6608 | BI11: 154.19322 | BJ11: 157.23607 | BK11: =BI29/AW29-1 -> 0.04291356 | BL11: Deflator PPI Beverages (tobacco neglected) - Average Jan Jul 2016/2015 | BM11: =PPI!CB12 -> 0.072422702 | BN11: Manufacturing of beverages & tobacco
A12: Furnishing, household equipment and routine household maintenance | B12: 119.76546 | C12: 119.90489 | D12: 121.17108 | E12: 121.67572 | F12: 122.36931 | G12: 122.30917 | H12: 122.7665 | I12: 123.36768 | J12: 123.84162 | K12: 125.47681 | L12: 127.33105 | M12: 129.77564 | N12: 131.04431 | O12: 130.75147 | P12: 131.60648 | Q12: 132.56657 | R12: 133.53248 | S12: 137.01432 | T12: 142.39538 | U12: 144.00329 | V12: 144.62393 | W12: 145.8997 | X12: 146.64711 | Y12: 147.08966 | Z12: 148.11094 | AA12: 148.42775 | AB12: 149.35878 | AC12: 149.40291 | AD12: 149.77317 | AE12: 150.64208 | AF12: 150.98745 | AG12: 151.22532 | AH12: 151.49833 | AI12: 151.96374 | AJ12: 154.09127 | AK12: 154.5452 | AL12: 154.97066 | AM12: 154.88695 | AN12: 155.08214 | AO12: 155.39392 | AP12: 155.7941 | AQ12: 155.9859 | AR12: 156.06293 | AS12: 157.94882 | AT12: 158.73246 | AU12: 158.9 | AV12: 160.07823 | AW12: 161.52002 | AX12: 162.84174 | AY12: 163.48994 | AZ12: 163.82692 | BA12: 164.77454 | BB12: 165.76022 | BC12: 167.02366 | BD12: 168.29543 | BE12: 173.38376 | BF12: 173.28201 | BG12: 174.70904 | BH12: 174.88882 | BI12: 175.05949 | BJ12: 175.46247 | BK12: =BI30/AW30-1 -> 0.075306426 | BL12: Deflator PPI textiles - Average Jan Jul 2016/2015 | BM12: =PPI!CB13 -> 0 | BN12: Manufacturing of textiles, clothing & leather goods
A13: Health | B13: 107.71089 | C13: 107.67783 | D13: 107.70763 | E13: 107.72178 | F13: 107.73184 | G13: 107.77805 | H13: 107.80875 | I13: 107.8468 | J13: 108.08107 | K13: 108.13786 | L13: 108.64984 | M13: 108.77187 | N13: 108.7409 | O13: 109.01179 | P13: 109.04107 | Q13: 109.07661 | R13: 109.1976 | S13: 109.15957 | T13: 109.11617 | U13: 109.06591 | V13: 109.28388 | W13: 109.26262 | X13: 109.20678 | Y13: 109.33514 | Z13: 109.37526 | AA13: 109.36833 | AB13: 109.67864 | AC13: 109.59177 | AD13: 109.47071 | AE13: 109.57803 | AF13: 109.57935 | AG13: 109.7112 | AH13: 110.1305 | AI13: 109.86205 | AJ13: 109.89618 | AK13: 110.13544 | AL13: 111.0567 | AM13: 111.17857 | AN13: 112.21391 | AO13: 112.54718 | AP13: 113.77578 | AQ13: 113.47052 | AR13: 113.3956 | AS13: 113.40098 | AT13: 113.00122 | AU13: 113 | AV13: 113.43184 | AW13: 113.51212 | AX13: 113.27024 | AY13: 113.31959 | AZ13: 113.48844 | BA13: 114.53374 | BB13: 113.64822 | BC13: 114.10467 | BD13: 193.5764 | BE13: 193.35043 | BF13: 193.39687 | BG13: 193.66271 | BH13: 193.83884 | BI13: 193.83689 | BJ13: 193.77822 | BK13: =BI31/AW31-1 -> 0.36192636 | BL13: Deflator PPI Paper (wood neglected) - Average Jan Jul 2016/2015 | BM13: =PPI!CB14 -> 0 | BN13: Manufacturing of wood & paper; printing
A14: Transport | B14: 127.9925 | C14: 128.24242 | D14: 129.65427 | E14: 129.87782 | F14: 130.30513 | G14: 129.6981 | H14: 129.55711 | I14: 131.23546 | J14: 131.35396 | K14: 131.9169 | L14: 132.21083 | M14: 133.06904 | N14: 133.99678 | O14: 134.39655 | P14: 134.58993 | Q14: 138.98514 | R14: 140.35729 | S14: 144.59728 | T14: 145.65607 | U14: 147.71075 | V14: 150.41939 | W14: 149.8092 | X14: 150.32495 | Y14: 150.18344 | Z14: 150.93605 | AA14: 150.72108 | AB14: 150.75804 | AC14: 150.73026 | AD14: 150.99576 | AE14: 151.86085 | AF14: 154.11466 | AG14: 158.01511 | AH14: 159.27547 | AI14: 162.45341 | AJ14: 162.74039 | AK14: 160.22171 | AL14: 160.64796 | AM14: 162.92084 | AN14: 173.06412 | AO14: 187.26821 | AP14: 188.32766 | AQ14: 187.10922 | AR14: 187.59472 | AS14: 188.05507 | AT14: 188.24208 | AU14: 188.3 | AV14: 188.04776 | AW14: 188.83579 | AX14: 190.39894 | AY14: 191.23467 | AZ14: 193.75002 | BA14: 194.3838 | BB14: 195.23521 | BC14: 195.42919 | BD14: 200.67289 | BE14: 200.96277 | BF14: 204.3858 | BG14: 204.28418 | BH14: 205.52026 | BI14: 206.65304 | BJ14: 206.7521 | BK14: =BI32/AW32-1 -> 0.088875958 | BL14: Deflator PPI Chemicals and chemical products - Average Jan Jul 2016/2015 | BM14: =PPI!CB15 -> 0.07 | BN14: Manufacturing of chemicals, rubber & plastic products
A15: Communication | B15: 105.78212 | C15: 105.78212 | D15: 105.78212 | E15: 105.78212 | F15: 105.78212 | G15: 105.78212 | H15: 105.78212 | I15: 105.78212 | J15: 105.78212 | K15: 105.78212 | L15: 105.78212 | M15: 105.78212 | N15: 105.78212 | O15: 105.78212 | P15: 105.78212 | Q15: 105.78212 | R15: 106.62378 | S15: 108.13873 | T15: 108.13873 | U15: 108.28571 | V15: 108.57477 | W15: 108.57477 | X15: 108.57477 | Y15: 108.57477 | Z15: 108.57477 | AA15: 108.57477 | AB15: 108.57477 | AC15: 108.57477 | AD15: 108.57477 | AE15: 108.57477 | AF15: 108.57477 | AG15: 108.57477 | AH15: 108.57477 | AI15: 108.57477 | AJ15: 108.57477 | AK15: 108.57477 | AL15: 108.57477 | AM15: 108.57477 | AN15: 109.21856 | AO15: 109.9286 | AP15: 109.9286 | AQ15: 109.9286 | AR15: 109.9286 | AS15: 109.9286 | AT15: 109.9286 | AU15: 109.9 | AV15: 109.9286 | AW15: 109.9286 | AX15: 111.57008 | AY15: 113.57126 | AZ15: 113.57126 | BA15: 113.57126 | BB15: 113.57126 | BC15: 113.57126 | BD15: 114.30037 | BE15: 114.30037 | BF15: 114.30037 | BG15: 114.30037 | BH15: 114.30037 | BI15: 114.28777 | BJ15: 114.27289 | BK15: =BI33/AW33-1 -> 0.037637161 | BL15: Deflator PPI non-metallic mineral products - Average Jan Jul 2016/2015 | BM15: =PPI!CB16 -> -0.0057509585 | BN15: Manufacturing of non-metallic mineral products
A16: Recreation and culture | B16: 126.71275 | C16: 127.17772 | D16: 127.34061 | E16: 127.29378 | F16: 127.9607 | G16: 127.98062 | H16: 128.04178 | I16: 128.0247 | J16: 128.0506 | K16: 128.23771 | L16: 129.13146 | M16: 130.32959 | N16: 135.55869 | O16: 135.57663 | P16: 136.56888 | Q16: 136.66645 | R16: 137.749 | S16: 138.88534 | T16: 138.82512 | U16: 138.5286 | V16: 142.27922 | W16: 149.28806 | X16: 152.19148 | Y16: 153.46504 | Z16: 154.1653 | AA16: 154.14328 | AB16: 155.22338 | AC16: 154.52531 | AD16: 155.2189 | AE16: 155.5705 | AF16: 155.51424 | AG16: 155.89072 | AH16: 155.1344 | AI16: 155.47633 | AJ16: 154.44491 | AK16: 153.59942 | AL16: 154.04912 | AM16: 154.24436 | AN16: 153.45161 | AO16: 154.26176 | AP16: 154.20233 | AQ16: 154.22624 | AR16: 155.48751 | AS16: 155.13564 | AT16: 154.62238 | AU16: 152.7 | AV16: 153.79879 | AW16: 154.53701 | AX16: 155.69041 | AY16: 152.74176 | AZ16: 153.66752 | BA16: 152.10991 | BB16: 152.07741 | BC16: 152.24492 | BD16: 153.10094 | BE16: 153.95986 | BF16: 154.22998 | BG16: 155.39584 | BH16: 155.7107 | BI16: 159.90825 | BJ16: 159.90012 | BK16: =BI34/AW34-1 -> 6.5240597e-05 | BL16: Deflator PPI fabricated metal products, except machinery and equipment - Average Jan Jul 2016/2015 | BM16: =PPI!CB17 -> 0 | BN16: Manufacturing of metal products, machinery & equipment
A17: Education | B17: 109.53138 | C17: 109.63883 | D17: 121.26722 | E17: 121.34385 | F17: 121.34638 | G17: 121.34638 | H17: 121.34638 | I17: 121.34638 | J17: 121.34638 | K17: 130.59075 | L17: 130.59075 | M17: 130.59075 | N17: 130.59745 | O17: 130.59745 | P17: 130.59745 | Q17: 130.59745 | R17: 130.51888 | S17: 130.51888 | T17: 130.51888 | U17: 130.51888 | V17: 130.55243 | W17: 141.29962 | X17: 141.29962 | Y17: 141.29962 | Z17: 141.31253 | AA17: 141.31881 | AB17: 141.31881 | AC17: 141.31881 | AD17: 141.31881 | AE17: 141.31881 | AF17: 141.31881 | AG17: 141.31881 | AH17: 141.31881 | AI17: 143.46535 | AJ17: 143.46535 | AK17: 143.46535 | AL17: 143.46535 | AM17: 143.46535 | AN17: 143.46535 | AO17: 143.56419 | AP17: 143.56419 | AQ17: 143.56419 | AR17: 143.56419 | AS17: 143.56419 | AT17: 155.33551 | AU17: 155.3 | AV17: 155.33551 | AW17: 155.33551 | AX17: 155.49129 | AY17: 155.49129 | AZ17: 155.49129 | BA17: 155.49129 | BB17: 155.49129 | BC17: 155.49129 | BD17: 155.49129 | BE17: 155.49129 | BF17: 173.31887 | BG17: 173.31887 | BH17: 173.31887 | BI17: 173.31887 | BJ17: 173.31887 | BK17: =BI35/AW35-1 -> 0.094761223 | BL17: Deflator PPI Furniture - Average Jan Jul 2016/2015 | BM17: =PPI!CB18 -> 0.020581618 | BN17: Furniture & other manufacturing
A18: Restaurants and hotels | B18: 107.60198 | C18: 107.63245 | D18: 107.72667 | E18: 107.74421 | F18: 108.52968 | G18: 108.7972 | H18: 108.82369 | I18: 108.70707 | J18: 109.20934 | K18: 110.3739 | L18: 111.33959 | M18: 111.44296 | N18: 111.70473 | O18: 114.33591 | P18: 123.56837 | Q18: 123.87756 | R18: 123.99999 | S18: 124.37759 | T18: 127.57148 | U18: 128.76882 | V18: 129.70326 | W18: 130.91377 | X18: 130.31502 | Y18: 133.01533 | Z18: 134.42962 | AA18: 134.47575 | AB18: 136.13998 | AC18: 138.54108 | AD18: 138.28575 | AE18: 137.63767 | AF18: 138.48149 | AG18: 138.51407 | AH18: 138.65053 | AI18: 138.31878 | AJ18: 138.63717 | AK18: 139.4026 | AL18: 140.78129 | AM18: 141.02136 | AN18: 141.12858 | AO18: 141.59009 | AP18: 141.77082 | AQ18: 141.90204 | AR18: 142.16034 | AS18: 145.27461 | AT18: 146.02759 | AU18: 146.2 | AV18: 146.36332 | AW18: 148.9644 | AX18: 154.08777 | AY18: 157.32644 | AZ18: 160.99532 | BA18: 162.42644 | BB18: 165.24302 | BC18: 167.20166 | BD18: 170.78899 | BE18: 172.09032 | BF18: 171.92416 | BG18: 174.06077 | BH18: 174.73694 | BI18: 174.90243 | BJ18: 183.63672 | BK18: =BI36/AW36-1 -> 0.16399859 | BL18: Deflator PPI Electricity - Average Jan Jun 2015/2014 | BM18: =PPI!CB19 -> 0.145 | BN18: Electricity
A19: Miscellaneous goods and services | B19: 116.28344 | C19: 116.33892 | D19: 116.34112 | E19: 116.42635 | F19: 116.46853 | G19: 116.54593 | H19: 116.61686 | I19: 116.68954 | J19: 117.09643 | K19: 116.19373 | L19: 116.4347 | M19: 116.51702 | N19: 116.75351 | O19: 116.99622 | P19: 117.33759 | Q19: 118.20827 | R19: 121.03399 | S19: 124.45666 | T19: 125.50292 | U19: 125.70484 | V19: 126.32934 | W19: 126.89501 | X19: 126.09934 | Y19: 125.16232 | Z19: 125.43886 | AA19: 125.87945 | AB19: 125.90477 | AC19: 132.04047 | AD19: 132.1998 | AE19: 133.04402 | AF19: 133.57947 | AG19: 133.71136 | AH19: 134.13516 | AI19: 134.2422 | AJ19: 135.16606 | AK19: 135.64611 | AL19: 136.61906 | AM19: 137.09273 | AN19: 137.45693 | AO19: 138.05674 | AP19: 138.23424 | AQ19: 138.56738 | AR19: 139.261 | AS19: 139.49778 | AT19: 140.0685 | AU19: 141.4 | AV19: 141.72281 | AW19: 142.00883 | AX19: 142.83587 | AY19: 143.67434 | AZ19: 144.384 | BA19: 144.59695 | BB19: 144.93332 | BC19: 145.21052 | BD19: 146.13081 | BE19: 147.07946 | BF19: 147.52454 | BG19: 148.11733 | BH19: 148.92953 | BI19: 149.15083 | BJ19: 149.42655 | BK19: =BI37/AW37-1 -> 0.049450419 | BL19: Deflator PPI Water - Average Jan Jul 2016/2015 | BM19: =PPI!CB20 -> 0 | BN19: Water & waste management
Y20: =AVERAGE(N2:Y2) -> 146.77848 | AK20: =AVERAGE(Z2:AK2) -> 167.36944 | AW20: =AVERAGE(AL2:AW2) -> 175.34236 | BI20: =AVERAGE(AX2:BI2) -> 187.68085 | BL20: Deflator general PPI - Average Jan-Jul 2016/2015 | BM20: =PPI!CB21 -> 0.066916667 | BN20: Construction
Y21: =AVERAGE(N3:Y3) -> 177.13013 | AK21: =AVERAGE(Z3:AK3) -> 226.09681 | AW21: =AVERAGE(AL3:AW3) -> 231.64821 | BI21: =AVERAGE(AX3:BI3) -> 244.37591 | BN21: SERVICES
Y22: =AVERAGE(N4:Y4) -> 162.17505 | AK22: =AVERAGE(Z4:AK4) -> 186.9192 | AW22: =AVERAGE(AL4:AW4) -> 185.89573 | BI22: =AVERAGE(AX4:BI4) -> 196.69412 | BN22: Trade and Transport
Y23: =AVERAGE(N5:Y5) -> 178.13663 | AK23: =AVERAGE(Z5:AK5) -> 201.79974 | AW23: =AVERAGE(AL5:AW5) -> 235.08534 | BI23: =AVERAGE(AX5:BI5) -> 298.29958 | BL23: Deflator general CPI - Average Jan-Jul 2016/2015 | BM23: =BK2 -> 0.070368023 | BN23: Maintenance & repair of motor vehicles
Y24: =AVERAGE(N6:Y6) -> 143.78986 | AK24: =AVERAGE(Z6:AK6) -> 166.44494 | AW24: =AVERAGE(AL6:AW6) -> 198.53288 | BI24: =AVERAGE(AX6:BI6) -> 214.01464 | BL24: Deflator general CPI - Average Jan-Jul 2016/2015 | BM24: =BK2 -> 0.070368023 | BN24: Wholesale & retail trade
Y25: =AVERAGE(N7:Y7) -> 194.20787 | AK25: =AVERAGE(Z7:AK7) -> 291.16327 | AW25: =AVERAGE(AL7:AW7) -> 279.40809 | BI25: =AVERAGE(AX7:BI7) -> 273.10886 | BL25: Deflator CPI Transport - Average Jan Jul 2016/2015 | BM25: =BK14 -> 0.088875958 | BN25: Transport services
Y26: =AVERAGE(N8:Y8) -> 146.23323 | AK26: =AVERAGE(Z8:AK8) -> 177.5801 | AW26: =AVERAGE(AL8:AW8) -> 192.06761 | BI26: =AVERAGE(AX8:BI8) -> 204.00601 | BN26: Other services
Y27: =AVERAGE(N9:Y9) -> 192.23085 | AK27: =AVERAGE(Z9:AK9) -> 221.45516 | AW27: =AVERAGE(AL9:AW9) -> 228.04155 | BI27: =AVERAGE(AX9:BI9) -> 252.6816 | BL27: Deflator CPI Hotels and Restaurants - Average Jan Jul 2016/2015 | BM27: =BK18 -> 0.16399859 | BN27: Hotels & restaurants
Y28: =AVERAGE(N10:Y10) -> 140.69604 | AK28: =AVERAGE(Z10:AK10) -> 151.47981 | AW28: =AVERAGE(AL10:AW10) -> 160.05914 | BI28: =AVERAGE(AX10:BI10) -> 167.48194 | BL28: Deflator CPI Communication - Average Jan Jul 2016/2015 | BM28: =BK15 -> 0.037637161 | BN28: Information & communication
Y29: =AVERAGE(N11:Y11) -> 130.71184 | AK29: =AVERAGE(Z11:AK11) -> 135.49965 | AW29: =AVERAGE(AL11:AW11) -> 140.09914 | BI29: =AVERAGE(AX11:BI11) -> 146.1113 | BL29: Deflator general CPI - Average Jan-Jul 2016/2015 | BM29: =BK2 -> 0.070368023 | BN29: Financial services
Y30: =AVERAGE(N12:Y12) -> 138.93123 | AK30: =AVERAGE(Z12:AK12) -> 150.83558 | AW30: =AVERAGE(AL12:AW12) -> 157.11301 | BI30: =AVERAGE(AX12:BI12) -> 168.94463 | BL30: Deflator general CPI - Average Jan-Jul 2016/2015 | BM30: =BK2 -> 0.070368023 | BN30: Real estate activities
Y31: =AVERAGE(N13:Y13) -> 109.12484 | AK31: =AVERAGE(Z13:AK13) -> 109.69812 | AW31: =AVERAGE(AL13:AW13) -> 112.83203 | BI31: =AVERAGE(AX13:BI13) -> 153.66892 | BL31: Deflator general CPI - Average Jan-Jul 2016/2015 | BM31: =BK2 -> 0.070368023 | BN31: Professional, scientific and technical activities
Y32: =AVERAGE(N14:Y14) -> 143.4189 | AK32: =AVERAGE(Z14:AK14) -> 155.23523 | AW32: =AVERAGE(AL14:AW14) -> 182.36779 | BI32: =AVERAGE(AX14:BI14) -> 198.5759 | BL32: Deflator general CPI - Average Jan-Jul 2016/2015 | BM32: =BK2 -> 0.070368023 | BN32: Administrative and support service activities
Y33: =AVERAGE(N15:Y15) -> 107.38455 | AK33: =AVERAGE(Z15:AK15) -> 108.57477 | AW33: =AVERAGE(AL15:AW15) -> 109.64141 | BI33: =AVERAGE(AX15:BI15) -> 113.768 | BL33: Deflator Increase in govt unit wages cost - linked to annual - comes from Fiscal | BN33: Public administration and defence; compulsory social security
Y34: =AVERAGE(N16:Y16) -> 141.29854 | AK34: =AVERAGE(Z16:AK16) -> 154.90889 | AW34: =AVERAGE(AL16:AW16) -> 154.2264 | BI34: =AVERAGE(AX16:BI16) -> 154.23646 | BL34: Deflator Increase in govt unit wages cost - linked to annual - comes from Fiscal | BN34: Education
Y35: =AVERAGE(N17:Y17) -> 133.24305 | AK35: =AVERAGE(Z17:AK17) -> 141.85492 | AW35: =AVERAGE(AL17:AW17) -> 147.4603 | BI35: =AVERAGE(AX17:BI17) -> 161.43381 | BL35: Deflator Increase in govt unit wages cost - linked to annual - comes from Fiscal | BN35: Human health and social work activities
Y36: =AVERAGE(N18:Y18) -> 125.17932 | AK36: =AVERAGE(Z18:AK18) -> 137.62621 | AW36: =AVERAGE(AL18:AW18) -> 143.5987 | BI36: =AVERAGE(AX18:BI18) -> 167.14869 | BL36: Deflator general CPI - Average Jan-Jul 2016/2015 | BM36: =BK2 -> 0.070368023 | BN36: Cultural, domestic & other services
Y37: =AVERAGE(N19:Y19) -> 122.54 | AK37: =AVERAGE(Z19:AK19) -> 131.74898 | AW37: =AVERAGE(AL19:AW19) -> 139.1655 | BI37: =AVERAGE(AX19:BI19) -> 146.04729
BL38: Deflator - Deflator calculated in the annual (no link to avoid circularity) - considered as a target - exogenous | BN38: Taxes less subsidies on products
B40: 112.95569 | C40: 112.47517 | D40: 113.70262 | E40: 114.38173 | F40: 114.80019 | G40: 114.59573 | H40: 113.72815 | I40: 113.60798 | J40: 113.88428 | K40: 115.11995 | L40: 116.50878 | N40: 113.7073 | O40: 114.5357 | P40: 115.35701 | Q40: 116.80566 | R40: 118.03255 | S40: 116.99557 | T40: 115.84769 | U40: 116.32555 | V40: 116.51866 | W40: 115.8158 | X40: 115.21639 | Y40: 114.99841 | BE40: obald
B41: =B2-B40 -> 13.955762 | C41: =C2-C40 -> 14.901402 | D41: =D2-D40 -> 15.44747 | E41: =E2-E40 -> 14.976271 | F41: =F2-F40 -> 13.939818 | G41: =G2-G40 -> 13.880563 | H41: =H2-H40 -> 14.710079 | I41: =I2-I40 -> 15.156249 | ... L41: =L2-L40 -> 13.151876 | N41: =N2-N40 -> 18.6947 | O41: =O2-O40 -> 20.214751 | P41: =P2-P40 -> 23.52103 | Q41: =Q2-Q40 -> 25.397126 | R41: =R2-R40 -> 26.894131 | S41: =S2-S40 -> 29.035034 | T41: =T2-T40 -> 32.593462 | U41: =U2-U40 -> 32.874898 | ... Y41: =Y2-Y40 -> 42.764969
...

Sheet PPI
BM1: 2025
B2: 44197 | C2: 44228 | D2: 44256 | E2: 44287 | F2: 44317 | G2: 44348 | H2: 44378 | I2: 44409 | J2: 44440 | K2: 44470 | L2: 44501 | M2: 44531 | N2: 44562 | O2: 44593 | P2: 44621 | Q2: 44652 | R2: 44682 | S2: 44713 | T2: 44743 | U2: 44774 | V2: 44805 | W2: 44835 | X2: 44866 | Y2: 44896 | Z2: 44927 | AA2: 44958 | AB2: 44986 | AC2: 45017 | AD2: 45047 | AE2: 45078 | AF2: 45108 | AG2: 45139 | AH2: 45170 | AI2: 45200 | AJ2: 45231 | AK2: 45261 | AL2: 45292 | AM2: 45323 | AN2: 45352 | AO2: 45383 | AP2: 45413 | AQ2: 45444 | AR2: 45474 | AS2: 45505 | AT2: 45536 | AU2: 45566 | AV2: 45597 | AW2: 45627 | AX2: 45658 | AY2: 45689 | AZ2: 45717 | BA2: 45748 | BB2: 45778 | BC2: 45809 | BD2: 45839 | BE2: 45870 | BF2: 45901 | BG2: 45931 | BH2: 45962 | BI2: 45992 | BJ2: 46023 | BL2: 2024 | BM2: Average tot | BN2: Growth
A3: Rwanda | B3: 71.9 | C3: 72.2 | D3: 72.8 | E3: 72.7 | F3: 73 | G3: 74.7 | H3: 75 | I3: 73.8 | J3: 74.4 | K3: 74.7 | L3: 75.1 | M3: 77.2 | N3: 77.7 | O3: 79.1 | P3: 82.3 | Q3: 83 | R3: 88.4 | S3: 85.6 | T3: 81 | U3: 82.8 | V3: 84.1 | W3: 85 | X3: 84.4 | Y3: 87.1 | Z3: 88.4 | AA3: 88.3 | AB3: 88.3 | AC3: 90.9 | AD3: 92.3 | AE3: 96.2 | AF3: 100.6 | AG3: 101.7 | AH3: 106.7 | AI3: 108.1 | AJ3: 105.6 | AK3: 104.8 | AL3: 105.2 | AM3: 100.6 | AN3: 100.2 | AO3: 100 | AP3: 98.7 | AQ3: 94.4 | AR3: 95.1 | AS3: 96.5 | AT3: 96.8 | AU3: 102 | AV3: 105.5 | AW3: 105 | AX3: 105.9 | AY3: 104.9 | AZ3: 104.3 | BA3: 102.4 | BB3: 105 | BC3: 105.6 | BD3: 107.5 | BE3: 107.1 | BF3: 109.8 | BG3: 108.9 | BH3: 109.1 | BI3: 109.8 | BL3: =AVERAGE(AL3:AW3) -> 100 | BM3: =AVERAGE(AX3:BI3) -> 106.69167 | BN3: =BM3/BL3-1 -> 0.066916667 | CA3: Deflator CPI food and non-alcoholic beverages - Average Jan Jul 2016/2015
A4: Mining and quarrying | B4: 77.3 | C4: 77.3 | D4: 77.4 | E4: 79.6 | F4: 79.7 | G4: 85.9 | H4: 86.2 | I4: 86.4 | J4: 87.5 | K4: 87.7 | L4: 88.9 | M4: 92.7 | N4: 92.7 | O4: 92.7 | P4: 93.5 | Q4: 97.1 | R4: 97 | S4: 96.9 | T4: 97 | U4: 97.1 | V4: 97.1 | W4: 97.2 | X4: 97.3 | Y4: 97.4 | Z4: 97.6 | AA4: 97.7 | AB4: 97.8 | AC4: 97.9 | AD4: 98.1 | AE4: 98.3 | AF4: 98.6 | AG4: 98.7 | AH4: 98.9 | AI4: 99.1 | AJ4: 99.2 | AK4: 99.4 | AL4: 99.6 | AM4: 99.6 | AN4: 99.7 | AO4: 99.8 | AP4: 99.8 | AQ4: 99.9 | AR4: 100 | AS4: 100.1 | AT4: 100.2 | AU4: 100.3 | AV4: 100.5 | AW4: 100.6 | AX4: 100.6 | AY4: 100.8 | AZ4: 100.8 | BA4: 100.9 | BB4: 100.9 | BC4: 101 | BD4: 101.1 | BE4: 101.1 | BF4: 101.2 | BG4: 101.2 | BH4: 106.1 | BI4: 121.1 | BL4: =AVERAGE(AL4:AW4) -> 100.00833 | BM4: =AVERAGE(AX4:BI4) -> 103.06667 | BN4: =BM4/BL4-1 -> 0.030580785 | CA4: Deflator general CPI - Average Jan-Jul 2016/2015
A5: Mining of metal ores | B5: 77.3 | C5: 77.3 | D5: 77.4 | E5: 79.6 | F5: 79.7 | G5: 85.9 | H5: 86.2 | I5: 86.4 | J5: 87.5 | K5: 87.7 | L5: 88.9 | M5: 92.7 | N5: 92.7 | O5: 92.7 | P5: 93.5 | Q5: 97.1 | R5: 97 | S5: 96.9 | T5: 97 | U5: 97.1 | V5: 97.1 | W5: 97.2 | X5: 97.3 | Y5: 97.4 | Z5: 97.6 | AA5: 97.7 | AB5: 97.8 | AC5: 97.9 | AD5: 98.1 | AE5: 98.3 | AF5: 98.6 | AG5: 98.7 | AH5: 98.9 | AI5: 99.1 | AJ5: 99.2 | AK5: 99.4 | AL5: 99.6 | AM5: 99.6 | AN5: 99.7 | AO5: 99.8 | AP5: 99.8 | AQ5: 99.9 | AR5: 100 | AS5: 100.1 | AT5: 100.2 | AU5: 100.3 | AV5: 100.5 | AW5: 100.6 | AX5: 100.6 | AY5: 100.8 | AZ5: 100.8 | BA5: 100.9 | BB5: 100.9 | BC5: 101 | BD5: 101.1 | BE5: 101.1 | BF5: 101.2 | BG5: 101.2 | BH5: 106.1 | BI5: 121.1 | BL5: =AVERAGE(AL5:AW5) -> 100.00833 | BM5: =AVERAGE(AX5:BI5) -> 103.06667 | BN5: =BM5/BL5-1 -> 0.030580785 | CA5: Deflator CPI meat - Average Jan Jul 2016/2015
A6: Mining of non-ferrous metal ores | B6: 118.53429 | C6: 118.62286 | D6: 118.68372 | E6: 122.10674 | F6: 122.30839 | G6: 131.8039 | H6: 132.18022 | I6: 132.49802 | J6: 134.26908 | K6: 134.51234 | L6: 136.41832 | M6: 142.11493 | N6: 142.16608 | O6: 142.21837 | P6: 143.481 | Q6: 148.99731 | R6: 148.76803 | S6: 148.68432 | T6: 148.74425 | U6: 148.97483 | V6: 148.95672 | W6: 149.08412 | X6: 149.22351 | Y6: 149.41082 | Z6: 149.63405 | AA6: 149.82248 | AB6: 149.96023 | AC6: 150.18756 | AD6: 150.41041 | AE6: 150.7875 | AF6: 151.19477 | AG6: 151.41687 | AH6: 151.66714 | AI6: 152.00245 | AJ6: 152.20091 | AK6: 152.48186 | AL6: 152.70899 | AM6: 152.81019 | AN6: 152.94138 | AO6: 153.03332 | AP6: 153.1253 | AQ6: 153.23756 | AR6: 153.42785 | AS6: 153.48813 | AT6: 153.61631 | AU6: 153.90045 | AV6: 154.09669 | AW6: 154.24213 | AX6: 154.37198 | AY6: 154.54115 | AZ6: 154.68591 | BA6: 154.74972 | BB6: 154.79015 | BC6: 154.89487 | BD6: 155.04016 | BL6: =AVERAGE(AL6:AW6) -> 153.38569 | BM6: =AVERAGE(AX6:BI6) -> 154.72485 | BN6: =BM6/BL6-1 -> 0.0087306531 | CA6: Deflator general CPI - Average Jan Jul 2016/2015
A7: Mining of other non-ferrous metal ores | B7: 118.53429 | C7: 118.62286 | D7: 118.68372 | E7: 122.10674 | F7: 122.30839 | G7: 131.8039 | H7: 132.18022 | I7: 132.49802 | J7: 134.26908 | K7: 134.51234 | L7: 136.41832 | M7: 142.11493 | N7: 142.16608 | O7: 142.21837 | P7: 143.481 | Q7: 148.99731 | R7: 148.76803 | S7: 148.68432 | T7: 148.74425 | U7: 148.97483 | V7: 148.95672 | W7: 149.08412 | X7: 149.22351 | Y7: 149.41082 | Z7: 149.63405 | AA7: 149.82248 | AB7: 149.96023 | AC7: 150.18756 | AD7: 150.41041 | AE7: 150.7875 | AF7: 151.19477 | AG7: 151.41687 | AH7: 151.66714 | AI7: 152.00245 | AJ7: 152.20091 | AK7: 152.48186 | AL7: 152.70899 | AM7: 152.81019 | AN7: 152.94138 | AO7: 153.03332 | AP7: 153.1253 | AQ7: 153.23756 | AR7: 153.42785 | AS7: 153.48813 | AT7: 153.61631 | AU7: 153.90045 | AV7: 154.09669 | AW7: 154.24213 | AX7: 154.37198 | AY7: 154.54115 | AZ7: 154.68591 | BA7: 154.74972 | BB7: 154.79015 | BC7: 154.89487 | BD7: 155.04016 | BL7: =AVERAGE(AL7:AW7) -> 153.38569 | BM7: =AVERAGE(AX7:BI7) -> 154.72485 | BN7: =BM7/BL7-1 -> 0.0087306531 | CA7: Deflator CPI fish - Average Jan Jul 2016/2015
A8: Manufacturing | B8: 63.6 | C8: 64 | D8: 64.8 | E8: 64.6 | F8: 64.9 | G8: 67.1 | H8: 67.4 | I8: 65.7 | J8: 66.5 | K8: 66.9 | L8: 67.5 | M8: 70.1 | N8: 70.9 | O8: 72.9 | P8: 77.4 | Q8: 78 | R8: 85.4 | S8: 81.6 | T8: 75.3 | U8: 77.8 | V8: 79.6 | W8: 80.8 | X8: 80 | Y8: 83.6 | Z8: 85.4 | AA8: 85.2 | AB8: 85.2 | AC8: 88.6 | AD8: 90.5 | AE8: 95.3 | AF8: 100.9 | AG8: 102.2 | AH8: 108.4 | AI8: 110 | AJ8: 107 | AK8: 106.1 | AL8: 106.5 | AM8: 100.8 | AN8: 100.2 | AO8: 100 | AP8: 98.5 | AQ8: 93 | AR8: 93.9 | AS8: 95.6 | AT8: 96 | AU8: 102.5 | AV8: 106.8 | AW8: 106.2 | AX8: 107.2 | AY8: 106 | AZ8: 105.3 | BA8: 102.9 | BB8: 106.1 | BC8: 106.8 | BD8: 109.1 | BE8: 106.6 | BF8: 110 | BG8: 108.8 | BH8: 108.8 | BI8: 108.6 | BL8: =AVERAGE(AL8:AW8) -> 100 | BM8: =AVERAGE(AX8:BI8) -> 107.18333 | BN8: =BM8/BL8-1 -> 0.071833333
A9: Manufacture of food products | B9: 60.3 | C9: 60.9 | D9: 62.1 | E9: 61.4 | F9: 61.8 | G9: 64.7 | H9: 65 | I9: 62.4 | J9: 63.5 | K9: 63.9 | L9: 64.8 | M9: 68.6 | N9: 69.7 | O9: 72.1 | P9: 77.6 | Q9: 78.1 | R9: 87.6 | S9: 82.5 | T9: 73.9 | U9: 75.7 | V9: 78.2 | W9: 79 | X9: 77.8 | Y9: 82.9 | Z9: 84.8 | AA9: 84.6 | AB9: 84.5 | AC9: 86.2 | AD9: 88.8 | AE9: 95.4 | AF9: 102.8 | AG9: 104.5 | AH9: 112.1 | AI9: 114.1 | AJ9: 110.3 | AK9: 109.1 | AL9: 109.6 | AM9: 101.7 | AN9: 100.9 | AO9: 100.5 | AP9: 98.3 | AQ9: 90.9 | AR9: 91.3 | AS9: 93.7 | AT9: 94.3 | AU9: 102.9 | AV9: 108.4 | AW9: 107.5 | AX9: 108.4 | AY9: 106.9 | AZ9: 105.9 | BA9: 102.7 | BB9: 106.8 | BC9: 107.8 | BD9: 110.7 | BE9: 105.9 | BF9: 110.5 | BG9: 109 | BH9: 109 | BI9: 105.6 | BL9: =AVERAGE(AL9:AW9) -> 100 | BM9: =AVERAGE(AX9:BI9) -> 107.43333 | BN9: =BM9/BL9-1 -> 0.074333333 | CA9: Deflator PPI Mining - Average Jan-Jul 2016/2015 | CB9: =BN4 -> 0.030580785
A10: Processing and preserving of meat | B10: 163.40075 | C10: 163.40075 | D10: 163.40075 | E10: 163.40075 | F10: 163.40075 | G10: 163.40075 | H10: 163.40075 | I10: 163.40075 | J10: 163.40075 | K10: 163.40075 | L10: 163.40075 | M10: 163.40075 | N10: 163.40075 | O10: 163.40075 | P10: 163.40075 | Q10: 163.40075 | R10: 163.40075 | S10: 163.40075 | T10: 163.40075 | U10: 163.40075 | V10: 163.40075 | W10: 163.40075 | X10: 163.40075 | Y10: 289.0992 | Z10: 289.0992 | AA10: 289.0992 | AB10: 289.0992 | AC10: 289.0992 | AD10: 289.0992 | AE10: 289.0992 | AF10: 343.18899 | AG10: 343.18899 | AH10: 343.18899 | AI10: 343.18899 | AJ10: 343.18899 | AK10: 343.18899 | AL10: 343.18899 | AM10: 343.18899 | AN10: 343.18899 | AO10: 343.18899 | AP10: 343.18899 | AQ10: 343.18899 | AR10: 343.18899 | AS10: 343.18899 | AT10: 343.18899 | AU10: 343.18899 | AV10: 343.18899 | AW10: 343.18899 | AX10: 343.18899 | AY10: 343.18899 | AZ10: 343.18899 | BA10: 343.18899 | BB10: 343.18899 | BC10: 343.18899 | BD10: 343.18899 | BL10: =AVERAGE(AL10:AW10) -> 343.18899 | BM10: =AVERAGE(AX10:BI10) -> 343.18899 | BN10: =BM10/BL10-1 -> 0
A11: Processing and preserving of meat | B11: 163.40075 | C11: 163.40075 | D11: 163.40075 | E11: 163.40075 | F11: 163.40075 | G11: 163.40075 | H11: 163.40075 | I11: 163.40075 | J11: 163.40075 | K11: 163.40075 | L11: 163.40075 | M11: 163.40075 | N11: 163.40075 | O11: 163.40075 | P11: 163.40075 | Q11: 163.40075 | R11: 163.40075 | S11: 163.40075 | T11: 163.40075 | U11: 163.40075 | V11: 163.40075 | W11: 163.40075 | X11: 163.40075 | Y11: 289.0992 | Z11: 289.0992 | AA11: 289.0992 | AB11: 289.0992 | AC11: 289.0992 | AD11: 289.0992 | AE11: 289.0992 | AF11: 343.18899 | AG11: 343.18899 | AH11: 343.18899 | AI11: 343.18899 | AJ11: 343.18899 | AK11: 343.18899 | AL11: 343.18899 | AM11: 343.18899 | AN11: 343.18899 | AO11: 343.18899 | AP11: 343.18899 | AQ11: 343.18899 | AR11: 343.18899 | AS11: 343.18899 | AT11: 343.18899 | AU11: 343.18899 | AV11: 343.18899 | AW11: 343.18899 | AX11: 343.18899 | AY11: 343.18899 | AZ11: 343.18899 | BA11: 343.18899 | BB11: 343.18899 | BC11: 343.18899 | BD11: 343.18899 | BL11: =AVERAGE(AL11:AW11) -> 343.18899 | BM11: =AVERAGE(AX11:BI11) -> 343.18899 | BN11: =BM11/BL11-1 -> 0 | CA11: Deflator PPI Manufacturing food - Average Jan Jul 2016/2015 | CB11: =BN9 -> 0.074333333
A12: Processing and preserving of fruit and vegetables | B12: 163.52202 | C12: 163.52202 | D12: 163.52202 | E12: 171.28688 | F12: 171.28688 | G12: 171.28688 | H12: 171.28688 | I12: 171.28688 | J12: 171.28688 | K12: 171.28688 | L12: 171.28688 | M12: 171.28688 | N12: 171.28688 | O12: 171.28688 | P12: 171.28688 | Q12: 175.96868 | R12: 175.96868 | S12: 175.96868 | T12: 175.96868 | U12: 175.96868 | V12: 175.96868 | W12: 175.96868 | X12: 175.96868 | Y12: 175.96868 | Z12: 175.96868 | AA12: 175.96868 | AB12: 175.96868 | AC12: 175.96868 | AD12: 175.96868 | AE12: 175.96868 | AF12: 175.96868 | AG12: 175.96868 | AH12: 175.96868 | AI12: 175.96868 | AJ12: 175.96868 | AK12: 175.96868 | AL12: 193.45672 | AM12: 193.45672 | AN12: 238.26633 | AO12: 238.26633 | AP12: 250.00427 | AQ12: 250.00427 | AR12: 261.75255 | AS12: 261.75255 | AT12: 261.75255 | AU12: 261.75255 | AV12: 261.75255 | AW12: 261.75255 | AX12: 261.75255 | AY12: 261.75255 | AZ12: 261.75255 | BA12: 261.75255 | BB12: 261.75255 | BC12: 261.75255 | BD12: 261.75255 | BL12: =AVERAGE(AL12:AW12) -> 244.4975 | BM12: =AVERAGE(AX12:BI12) -> 261.75255 | BN12: =BM12/BL12-1 -> 0.070573542 | CA12: Deflator PPI Beverages (tobacco neglected) - Average Jan Jul 2016/2015 | CB12: =BN24 -> 0.072422702
A13: Processing and preserving of fruit and vegetables | B13: 163.52202 | C13: 163.52202 | D13: 163.52202 | E13: 171.28688 | F13: 171.28688 | G13: 171.28688 | H13: 171.28688 | I13: 171.28688 | J13: 171.28688 | K13: 171.28688 | L13: 171.28688 | M13: 171.28688 | N13: 171.28688 | O13: 171.28688 | P13: 171.28688 | Q13: 175.96868 | R13: 175.96868 | S13: 175.96868 | T13: 175.96868 | U13: 175.96868 | V13: 175.96868 | W13: 175.96868 | X13: 175.96868 | Y13: 175.96868 | Z13: 175.96868 | AA13: 175.96868 | AB13: 175.96868 | AC13: 175.96868 | AD13: 175.96868 | AE13: 175.96868 | AF13: 175.96868 | AG13: 175.96868 | AH13: 175.96868 | AI13: 175.96868 | AJ13: 175.96868 | AK13: 175.96868 | AL13: 193.45672 | AM13: 193.45672 | AN13: 238.26633 | AO13: 238.26633 | AP13: 250.00427 | AQ13: 250.00427 | AR13: 261.75255 | AS13: 261.75255 | AT13: 261.75255 | AU13: 261.75255 | AV13: 261.75255 | AW13: 261.75255 | AX13: 261.75255 | AY13: 261.75255 | AZ13: 261.75255 | BA13: 261.75255 | BB13: 261.75255 | BC13: 261.75255 | BD13: 261.75255 | BL13: =AVERAGE(AL13:AW13) -> 244.4975 | BM13: =AVERAGE(AX13:BI13) -> 261.75255 | BN13: =BM13/BL13-1 -> 0.070573542 | CA13: Deflator PPI textiles - Average Jan Jul 2016/2015 | CB13: =BN32 -> 0
A14: Manufacture of dairy products | B14: 101.90809 | C14: 101.90809 | D14: 101.90809 | E14: 105.70085 | F14: 105.70085 | G14: 105.70085 | H14: 105.70085 | I14: 105.70085 | J14: 105.70085 | K14: 105.70085 | L14: 105.70085 | M14: 105.70085 | N14: 105.70085 | O14: 105.70085 | P14: 105.70085 | Q14: 105.70085 | R14: 105.70085 | S14: 105.70085 | T14: 105.70085 | U14: 115.5719 | V14: 115.5719 | W14: 115.5719 | X14: 115.5719 | Y14: 115.5719 | Z14: 115.5719 | AA14: 115.5719 | AB14: 115.5719 | AC14: 115.5719 | AD14: 115.5719 | AE14: 115.5719 | AF14: 115.5719 | AG14: 115.5719 | AH14: 115.5719 | AI14: 115.5719 | AJ14: 115.5719 | AK14: 115.5719 | AL14: 115.5719 | AM14: 115.5719 | AN14: 115.5719 | AO14: 115.5719 | AP14: 131.40544 | AQ14: 131.40544 | AR14: 131.40544 | AS14: 133.22202 | AT14: 133.22202 | AU14: 133.22202 | AV14: 133.22202 | AW14: 133.22202 | AX14: 133.22202 | AY14: 133.22202 | AZ14: 133.22202 | BA14: 133.22202 | BB14: 133.22202 | BC14: 133.22202 | BD14: 133.22202 | BL14: =AVERAGE(AL14:AW14) -> 126.8845 | BM14: =AVERAGE(AX14:BI14) -> 133.22202 | BN14: =BM14/BL14-1 -> 0.049947148 | CA14: Deflator PPI Paper (wood neglected) - Average Jan Jul 2016/2015 | CB14: =BN41 -> 0
A15: Manufacture of dairy products | B15: 101.90809 | C15: 101.90809 | D15: 101.90809 | E15: 105.70085 | F15: 105.70085 | G15: 105.70085 | H15: 105.70085 | I15: 105.70085 | J15: 105.70085 | K15: 105.70085 | L15: 105.70085 | M15: 105.70085 | N15: 105.70085 | O15: 105.70085 | P15: 105.70085 | Q15: 105.70085 | R15: 105.70085 | S15: 105.70085 | T15: 105.70085 | U15: 115.5719 | V15: 115.5719 | W15: 115.5719 | X15: 115.5719 | Y15: 115.5719 | Z15: 115.5719 | AA15: 115.5719 | AB15: 115.5719 | AC15: 115.5719 | AD15: 115.5719 | AE15: 115.5719 | AF15: 115.5719 | AG15: 115.5719 | AH15: 115.5719 | AI15: 115.5719 | AJ15: 115.5719 | AK15: 115.5719 | AL15: 115.5719 | AM15: 115.5719 | AN15: 115.5719 | AO15: 115.5719 | AP15: 131.40544 | AQ15: 131.40544 | AR15: 131.40544 | AS15: 133.22202 | AT15: 133.22202 | AU15: 133.22202 | AV15: 133.22202 | AW15: 133.22202 | AX15: 133.22202 | AY15: 133.22202 | AZ15: 133.22202 | BA15: 133.22202 | BB15: 133.22202 | BC15: 133.22202 | BD15: 133.22202 | BL15: =AVERAGE(AL15:AW15) -> 126.8845 | BM15: =AVERAGE(AX15:BI15) -> 133.22202 | BN15: =BM15/BL15-1 -> 0.049947148 | CA15: Deflator PPI Chemicals and chemical products - Average Jan Jul 2016/2015 | CB15: =BN47 -> 0.07
A16: Manufacture of grain mill products | B16: 111.3634 | C16: 111.36379 | D16: 111.36379 | E16: 111.36379 | F16: 111.31733 | G16: 111.23727 | H16: 111.2407 | I16: 111.23972 | J16: 111.24576 | K16: 111.39268 | L16: 111.39268 | M16: 111.48295 | N16: 111.48295 | O16: 111.48295 | P16: 111.51223 | Q16: 111.51966 | R16: 111.51966 | S16: 111.51966 | T16: 111.76286 | U16: 111.76286 | V16: 111.76783 | W16: 111.84254 | X16: 111.89513 | Y16: 111.89513 | Z16: 112.20178 | AA16: 112.11368 | AB16: 112.11368 | AC16: 112.24729 | AD16: 112.27816 | AE16: 112.27816 | AF16: 112.32478 | AG16: 112.32478 | AH16: 112.43487 | AI16: 112.43487 | AJ16: 112.3932 | AK16: 115.05524 | AL16: 114.75452 | AM16: 114.82859 | AN16: 116.79181 | AO16: 116.83824 | AP16: 118.98169 | AQ16: 119.02347 | AR16: 119.02347 | AS16: 118.97609 | AT16: 118.97609 | AU16: 118.72103 | AV16: 118.72103 | AW16: 118.72103 | AX16: 118.72103 | AY16: 118.72103 | AZ16: 118.72103 | BA16: 118.72103 | BB16: 118.72103 | BC16: 118.72103 | BD16: 118.72103 | BL16: =AVERAGE(AL16:AW16) -> 117.86309 | BM16: =AVERAGE(AX16:BI16) -> 118.72103 | BN16: =BM16/BL16-1 -> 0.0072791654 | CA16: Deflator PPI non-metallic mineral products - Average Jan Jul 2016/2015 | CB16: =BN60 -> -0.0057509585
A17: Manufacture of grain mill products | B17: 111.3634 | C17: 111.36379 | D17: 111.36379 | E17: 111.36379 | F17: 111.31733 | G17: 111.23727 | H17: 111.2407 | I17: 111.23972 | J17: 111.24576 | K17: 111.39268 | L17: 111.39268 | M17: 111.48295 | N17: 111.48295 | O17: 111.48295 | P17: 111.51223 | Q17: 111.51966 | R17: 111.51966 | S17: 111.51966 | T17: 111.76286 | U17: 111.76286 | V17: 111.76783 | W17: 111.84254 | X17: 111.89513 | Y17: 111.89513 | Z17: 112.20178 | AA17: 112.11368 | AB17: 112.11368 | AC17: 112.24729 | AD17: 112.27816 | AE17: 112.27816 | AF17: 112.32478 | AG17: 112.32478 | AH17: 112.43487 | AI17: 112.43487 | AJ17: 112.3932 | AK17: 115.05524 | AL17: 114.75452 | AM17: 114.82859 | AN17: 116.79181 | AO17: 116.83824 | AP17: 118.98169 | AQ17: 119.02347 | AR17: 119.02347 | AS17: 118.97609 | AT17: 118.97609 | AU17: 118.72103 | AV17: 118.72103 | AW17: 118.72103 | AX17: 118.72103 | AY17: 118.72103 | AZ17: 118.72103 | BA17: 118.72103 | BB17: 118.72103 | BC17: 118.72103 | BD17: 118.72103 | BL17: =AVERAGE(AL17:AW17) -> 117.86309 | BM17: =AVERAGE(AX17:BI17) -> 118.72103 | BN17: =BM17/BL17-1 -> 0.0072791654 | CA17: Deflator PPI fabricated metal products, except machinery and equipment - Average Jan Jul 2016/2015 | CB17: =BN63 -> 0
A18: Manufacture of other food products | B18: 144.16452 | C18: 145.81748 | D18: 149.27349 | E18: 147.20471 | F18: 148.22887 | G18: 156.19501 | H18: 157.01115 | I18: 149.97146 | J18: 152.94013 | K18: 154.12268 | L18: 156.50715 | M18: 166.73059 | N18: 169.69865 | O18: 176.20743 | P18: 190.6593 | Q18: 191.97653 | R18: 216.70113 | S18: 203.62074 | T18: 180.91745 | U18: 185.62589 | V18: 192.10447 | W18: 194.26116 | X18: 191.06011 | Y18: 193.33418 | Z18: 198.70683 | AA18: 198.08512 | AB18: 197.96895 | AC18: 202.53721 | AD18: 209.87563 | AE18: 228.13656 | AF18: 241.99857 | AG18: 246.72026 | AH18: 267.61754 | AI18: 272.93154 | AJ18: 262.76041 | AK18: 259.44236 | AL18: 260.83502 | AM18: 239.09846 | AN18: 236.55123 | AO18: 235.33914 | AP18: 229.1611 | AQ18: 207.63257 | AR18: 208.83058 | AS18: 215.90615 | AT18: 217.47029 | AU18: 242.00617 | AV18: 257.18205 | AW18: 254.92124 | AX18: 257.14206 | AY18: 253.04735 | AZ18: 250.51968 | BA18: 241.40789 | BB18: 252.94384 | BC18: 255.70257 | BD18: 263.4615 | BL18: =AVERAGE(AL18:AW18) -> 233.7445 | BM18: =AVERAGE(AX18:BI18) -> 253.4607 | BN18: =BM18/BL18-1 -> 0.084349357 | CA18: Deflator PPI Furniture - Average Jan Jul 2016/2015 | CB18: =BN69 -> 0.020581618
A19: Manufacture of bakery products | B19: 143.6196 | C19: 143.6196 | D19: 143.6196 | E19: 143.6196 | F19: 143.6196 | G19: 143.6196 | H19: 143.6196 | I19: 143.6196 | J19: 143.6196 | K19: 147.24659 | L19: 147.24659 | M19: 151.14079 | N19: 151.14079 | O19: 151.14079 | P19: 151.14079 | Q19: 166.17182 | R19: 166.17182 | S19: 166.17182 | T19: 176.71574 | U19: 176.71574 | V19: 176.71574 | W19: 176.71574 | X19: 176.71574 | Y19: 176.71574 | Z19: 176.71574 | AA19: 176.71574 | AB19: 176.71574 | AC19: 176.71574 | AD19: 176.71574 | AE19: 176.71574 | AF19: 176.71574 | AG19: 176.71574 | AH19: 176.71574 | AI19: 176.71574 | AJ19: 176.71574 | AK19: 176.71574 | AL19: 176.71574 | AM19: 176.71574 | AN19: 176.71574 | AO19: 176.71574 | AP19: 176.71574 | AQ19: 176.71574 | AR19: 176.71574 | AS19: 176.71574 | AT19: 176.71574 | AU19: 176.71574 | AV19: 176.71574 | AW19: 176.71574 | AX19: 176.71574 | AY19: 176.71574 | AZ19: 184.67639 | BA19: 184.67639 | BB19: 184.67639 | BC19: 184.67639 | BD19: 184.67639 | BL19: =AVERAGE(AL19:AW19) -> 176.71574 | BM19: =AVERAGE(AX19:BI19) -> 182.40192 | BN19: =BM19/BL19-1 -> 0.032177018 | CA19: Deflator PPI Electricity - Average Jan Jun 2015/2014 | CB19: =BN73 -> 0.145
A20: Manufacture of sugar | B20: 148.70231 | C20: 151.26559 | D20: 155.85643 | E20: 154.20594 | F20: 154.20594 | G20: 154.20594 | H20: 154.20594 | I20: 145.62157 | J20: 149.52465 | K20: 154.4025 | L20: 156.01508 | M20: 154.05953 | N20: 161.04136 | O20: 171.43488 | P20: 202.29853 | Q20: 207.38293 | R20: 248.70633 | S20: 225.35561 | T20: 186.64206 | U20: 179.4376 | V20: 184.59425 | W20: 189.90333 | X20: 183.57335 | Y20: 190.74311 | Z20: 200.18051 | AA20: 197.66537 | AB20: 198.49573 | AC20: 214.50519 | AD20: 216.12179 | AE20: 237.48646 | AF20: 260.4236 | AG20: 265.80288 | AH20: 295.00381 | AI20: 302.34265 | AJ20: 278.00554 | AK20: 272.31939 | AL20: 273.08356 | AM20: 241.30531 | AN20: 232.08412 | AO20: 238.74604 | AP20: 224.89871 | AQ20: 197.73757 | AR20: 198.56392 | AS20: 192.62706 | AT20: 180.59004 | AU20: 221.95034 | AV20: 244.09322 | AW20: 247.28271 | AX20: 250.51387 | AY20: 242.60901 | AZ20: 226.98865 | BA20: 239.98957 | BB20: 250.95271 | BC20: 246.73252 | BD20: 240.11392 | BL20: =AVERAGE(AL20:AW20) -> 224.41355 | BM20: =AVERAGE(AX20:BI20) -> 242.55718 | BN20: =BM20/BL20-1 -> 0.080849073 | CA20: Deflator PPI Water - Average Jan Jul 2016/2015 | CB20: =BN76 -> 0
A21: Manufacture of other food products n.e.c. (coffee and tea) | B21: 139.54809 | C21: 140.25753 | D21: 142.54429 | E21: 139.93232 | F21: 142.06409 | G21: 158.4003 | H21: 159.96953 | I21: 154.05665 | J21: 156.35604 | K21: 154.07077 | L21: 157.26156 | M21: 177.58957 | N21: 177.6567 | O21: 181.18004 | P21: 179.28421 | Q21: 175.52315 | R21: 175.21683 | S21: 178.76211 | T21: 175.28016 | U21: 191.42149 | V21: 199.1499 | W21: 198.72065 | X21: 198.06497 | Y21: 196.2195 | Z21: 197.93223 | AA21: 199.10164 | AB21: 198.0877 | AC21: 190.29367 | AD21: 204.49052 | AE21: 219.72759 | AF21: 222.90651 | AG21: 227.02815 | AH21: 237.4005 | AI21: 239.96907 | AJ21: 248.46061 | AK21: 247.91024 | AL21: 250.0547 | AM21: 238.48763 | AN21: 242.0376 | AO21: 233.48415 | AP21: 234.32867 | AQ21: 217.08188 | AR21: 218.59981 | AS21: 235.14503 | AT21: 244.34364 | AU21: 259.80692 | AV21: 270.10721 | AW21: 263.42006 | AX21: 264.82773 | AY21: 263.80157 | AZ21: 270.68675 | BA21: 244.12817 | BB21: 256.41779 | BC21: 265.23977 | BD21: 283.87375 | BL21: =AVERAGE(AL21:AW21) -> 242.24144 | BM21: =AVERAGE(AX21:BI21) -> 264.13936 | BN21: =BM21/BL21-1 -> 0.090397074 | CA21: Deflator general PPI - Average Jan-Jul 2016/2015 | CB21: =BN3 -> 0.066916667
A22: Manufacture of coffee products | B22: 120.97934 | C22: 121.28375 | D22: 121.49321 | E22: 121.49321 | F22: 112.32526 | G22: 161.67341 | H22: 168.01647 | I22: 154.39367 | J22: 134.84123 | K22: 135.73944 | L22: 135.74866 | M22: 168.68713 | N22: 168.93011 | O22: 169.17879 | P22: 169.17879 | Q22: 169.04401 | R22: 169.04401 | S22: 169.21619 | T22: 169.48921 | U22: 206.69528 | V22: 207.34824 | W22: 208.0571 | X22: 208.83475 | Y22: 209.88319 | Z22: 211.13783 | AA22: 212.20129 | AB22: 214.60294 | AC22: 215.90467 | AD22: 226.99943 | AE22: 250.34235 | AF22: 253.05255 | AG22: 254.53982 | AH22: 257.07861 | AI22: 258.4924 | AJ22: 273.12657 | AK22: 266.47655 | AL22: 268.06471 | AM22: 255.01587 | AN22: 252.02637 | AO22: 242.62129 | AP22: 243.20399 | AQ22: 238.72743 | AR22: 239.91311 | AS22: 260.06285 | AT22: 260.37408 | AU22: 282.40719 | AV22: 260.3823 | AW22: 259.04696 | AX22: 259.9187 | AY22: 266.74481 | AZ22: 280.64359 | BA22: 251.89175 | BB22: 279.20999 | BC22: 279.96481 | BD22: 298.21188 | BL22: =AVERAGE(AL22:AW22) -> 255.15384 | BM22: =AVERAGE(AX22:BI22) -> 273.79793 | BN22: =BM22/BL22-1 -> 0.073069983
A23: Manufacture of tea products | B23: 151.99022 | C23: 152.92512 | D23: 156.3175 | E23: 152.31371 | F23: 159.67496 | G23: 155.53624 | H23: 152.50658 | I23: 153.7718 | J23: 170.66573 | K23: 166.64076 | L23: 171.58879 | M23: 184.44357 | N23: 184.38705 | O23: 190.1678 | P23: 186.98115 | Q23: 180.6276 | R23: 180.09435 | S23: 186.07012 | T23: 179.87362 | U23: 176.35144 | V23: 191.68446 | W23: 190.11956 | X23: 187.99374 | Y23: 183.02964 | Z23: 185.26294 | AA23: 186.55842 | AB23: 181.66411 | AC23: 161.46484 | AD23: 180.68525 | AE23: 184.81875 | AF23: 188.91305 | AG23: 197.12254 | AH23: 217.85245 | AI23: 221.79594 | AJ23: 223.03275 | AK23: 229.78521 | AL23: 232.58053 | AM23: 222.54372 | AN23: 232.93993 | AO23: 225.19724 | AP23: 226.29917 | AQ23: 194.7451 | AR23: 196.71837 | AS23: 209.05023 | AT23: 229.00016 | AU23: 237.15106 | AV23: 277.78102 | AW23: 266.99186 | AX23: 268.82333 | AY23: 261.272 | AZ23: 261.69814 | BA23: 237.18752 | BB23: 233.47224 | BC23: 251.43765 | BD23: 270.57064 | BL23: =AVERAGE(AL23:AW23) -> 229.24987 | BM23: =AVERAGE(AX23:BI23) -> 254.92308 | BN23: =BM23/BL23-1 -> 0.11198789
A24: Manufacture of beverages | B24: 67.9 | C24: 67.9 | D24: 67.9 | E24: 67.9 | F24: 67.9 | G24: 67.9 | H24: 67.9 | I24: 67.9 | J24: 68.2 | K24: 68.2 | L24: 68.2 | M24: 68.2 | N24: 68.2 | O24: 68.2 | P24: 71.4 | Q24: 71.4 | R24: 71.4 | S24: 71.4 | T24: 71.4 | U24: 78.4 | V24: 78.4 | W24: 82.1 | X24: 82.1 | Y24: 82.1 | Z24: 82.1 | AA24: 82.5 | AB24: 82.5 | AC24: 95.1 | AD24: 95.1 | AE24: 95.1 | AF24: 95.1 | AG24: 95.1 | AH24: 95.1 | AI24: 95.1 | AJ24: 95.1 | AK24: 95.1 | AL24: 95.1 | AM24: 97.5 | AN24: 98.3 | AO24: 98.8 | AP24: 98.8 | AQ24: 98.8 | AR24: 102.1 | AS24: 102.1 | AT24: 102.1 | AU24: 102.1 | AV24: 102.1 | AW24: 102.1 | AX24: 104 | AY24: 104 | AZ24: 104 | BA24: 104 | BB24: 104 | BC24: 104 | BD24: 103.7 | BE24: 109.9 | BF24: 109.9 | BG24: 109.9 | BH24: 109.9 | BI24: 119.5 | BL24: =AVERAGE(AL24:AW24) -> 99.991667 | BM24: =AVERAGE(AX24:BI24) -> 107.23333 | BN24: =BM24/BL24-1 -> 0.072422702 | CA24: Deflator general CPI - Average Jan-Jul 2016/2015
A25: Manufacture of beverages | B25: 127.69045 | C25: 127.69045 | D25: 127.69045 | E25: 127.69045 | F25: 127.69045 | G25: 127.69045 | H25: 127.69045 | I25: 127.69045 | J25: 128.25437 | K25: 128.25437 | L25: 128.25437 | M25: 128.25437 | N25: 128.25437 | O25: 128.25467 | P25: 134.23146 | Q25: 134.23146 | R25: 134.23213 | S25: 134.23213 | T25: 134.23213 | U25: 147.37412 | V25: 147.37412 | W25: 154.41979 | X25: 154.41979 | Y25: 154.41979 | Z25: 154.41979 | AA25: 155.1811 | AB25: 155.1811 | AC25: 178.78215 | AD25: 178.78215 | AE25: 178.78215 | AF25: 178.78215 | AG25: 178.78215 | AH25: 178.78215 | AI25: 178.78215 | AJ25: 178.78215 | AK25: 178.78215 | AL25: 178.78215 | AM25: 183.37444 | AN25: 184.77971 | AO25: 185.80957 | AP25: 185.80957 | AQ25: 185.80957 | AR25: 192.05583 | AS25: 192.05583 | AT25: 192.05583 | AU25: 192.05583 | AV25: 192.05583 | AW25: 192.05583 | AX25: 195.49772 | AY25: 195.49772 | AZ25: 195.49772 | BA25: 195.49822 | BB25: 195.49822 | BC25: 195.49822 | BD25: 195.01001 | BL25: =AVERAGE(AL25:AW25) -> 188.05833 | BM25: =AVERAGE(AX25:BI25) -> 195.42826 | BN25: =BM25/BL25-1 -> 0.039189598 | CA25: Deflator general CPI - Average Jan-Jul 2016/2015
A26: Manufacture of wines | B26: 102.29808 | C26: 102.29808 | D26: 102.29808 | E26: 102.29808 | F26: 102.29808 | G26: 102.29808 | H26: 102.29808 | I26: 102.29808 | J26: 103.61682 | K26: 103.61682 | L26: 103.61682 | M26: 103.61682 | N26: 103.61682 | O26: 103.61682 | P26: 106.32933 | Q26: 106.32933 | R26: 106.32933 | S26: 106.32933 | T26: 106.32933 | U26: 126.37665 | V26: 126.37665 | W26: 128.06569 | X26: 128.06569 | Y26: 128.06569 | Z26: 128.06569 | AA26: 130.1279 | AB26: 130.1279 | AC26: 137.16487 | AD26: 137.16487 | AE26: 137.16487 | AF26: 137.16487 | AG26: 137.16487 | AH26: 137.16487 | AI26: 137.16487 | AJ26: 137.16487 | AK26: 137.16487 | AL26: 137.16487 | AM26: 141.40723 | AN26: 143.86045 | AO26: 146.49083 | AP26: 146.49083 | AQ26: 146.49083 | AR26: 149.12614 | AS26: 149.12614 | AT26: 149.12614 | AU26: 149.12614 | AV26: 149.12614 | AW26: 149.12614 | AX26: 155.99715 | AY26: 155.99715 | AZ26: 155.99715 | BA26: 155.99725 | BB26: 155.99725 | BC26: 155.99725 | BD26: 154.73466 | BL26: =AVERAGE(AL26:AW26) -> 146.38849 | BM26: =AVERAGE(AX26:BI26) -> 155.81684 | BN26: =BM26/BL26-1 -> 0.064406333 | CA26: Deflator CPI Transport - Average Jan Jul 2016/2015
A27: Manufacture of malt liquors and malt | B27: 127.6026 | C27: 127.6026 | D27: 127.6026 | E27: 127.6026 | F27: 127.6026 | G27: 127.6026 | H27: 127.6026 | I27: 127.6026 | J27: 128.17527 | K27: 128.17527 | L27: 128.17527 | M27: 128.17527 | N27: 128.17527 | O27: 128.17527 | P27: 134.31675 | Q27: 134.31675 | R27: 134.31675 | S27: 134.31675 | T27: 134.31675 | U27: 147.58308 | V27: 147.58308 | W27: 154.24335 | X27: 154.24335 | Y27: 154.24335 | Z27: 154.24335 | AA27: 155.00687 | AB27: 155.00687 | AC27: 178.99809 | AD27: 178.99809 | AE27: 178.99809 | AF27: 178.99809 | AG27: 178.99809 | AH27: 178.99809 | AI27: 178.99809 | AJ27: 178.99809 | AK27: 178.99809 | AL27: 178.99809 | AM27: 183.73466 | AN27: 185.16179 | AO27: 186.20176 | AP27: 186.20176 | AQ27: 186.20176 | AR27: 192.56238 | AS27: 192.56238 | AT27: 192.56238 | AU27: 192.56238 | AV27: 192.56238 | AW27: 192.56238 | AX27: 196.04558 | AY27: 196.04558 | AZ27: 196.04558 | BA27: 196.0461 | BB27: 196.0461 | BC27: 196.0461 | BD27: 195.55425 | BL27: =AVERAGE(AL27:AW27) -> 188.48951 | BM27: =AVERAGE(AX27:BI27) -> 195.97561 | BN27: =BM27/BL27-1 -> 0.039716289
A28: Manufacture of soft drinks; production of mineral waters and other bottled waters | B28: 142.36267 | C28: 142.36267 | D28: 142.36267 | E28: 142.36267 | F28: 142.36267 | G28: 142.36267 | H28: 142.36267 | I28: 142.36267 | J28: 142.36267 | K28: 142.36267 | L28: 142.36267 | M28: 142.36267 | N28: 142.36267 | O28: 142.37549 | P28: 142.37549 | Q28: 142.37549 | R28: 142.40644 | S28: 142.40644 | T28: 142.40644 | U28: 147.34857 | V28: 147.34857 | W28: 173.72296 | X28: 173.72296 | Y28: 173.72296 | Z28: 173.72296 | AA28: 174.00549 | AB28: 174.00549 | AC28: 186.25277 | AD28: 186.25277 | AE28: 186.25277 | AF28: 186.25277 | AG28: 186.25277 | AH28: 186.25277 | AI28: 186.25277 | AJ28: 186.25277 | AK28: 186.25277 | AL28: 186.25277 | AM28: 184.09294 | AN28: 184.09294 | AO28: 184.09294 | AP28: 184.09294 | AQ28: 184.09294 | AR28: 185.70753 | AS28: 185.70753 | AT28: 185.70753 | AU28: 185.70753 | AV28: 185.70753 | AW28: 185.70753 | AX28: 185.70753 | AY28: 185.70753 | AZ28: 185.70753 | BA28: 185.70753 | BB28: 185.70753 | BC28: 185.70753 | BD28: 185.70753 | BL28: =AVERAGE(AL28:AW28) -> 185.08022 | BM28: =AVERAGE(AX28:BI28) -> 185.70753 | BN28: =BM28/BL28-1 -> 0.0033893915 | CA28: Deflator CPI Hotels and Restaurants - Average Jan Jul 2016/2015
A29: Manufacture of tobacco products | B29: 100 | C29: 100 | D29: 100 | E29: 100 | F29: 100 | G29: 100 | H29: 100 | I29: 100 | J29: 100 | K29: 100 | L29: 100 | M29: 100 | N29: 100 | O29: 100 | P29: 100 | Q29: 100 | R29: 100 | S29: 100 | T29: 100 | U29: 100 | V29: 100 | W29: 100 | X29: 100 | Y29: 100 | Z29: 100 | AA29: 100 | AB29: 100 | AC29: 100 | AD29: 100 | AE29: 100 | AF29: 100 | AG29: 100 | AH29: 100 | AI29: 100 | AJ29: 100 | AK29: 100 | AL29: 100 | AM29: 100 | AN29: 100 | AO29: 100 | AP29: 100 | AQ29: 100 | AR29: 100 | AS29: 100 | AT29: 100 | AU29: 100 | AV29: 100 | AW29: 100 | AX29: 100 | AY29: 100 | AZ29: 100 | BA29: 100 | BB29: 100 | BC29: 100 | BD29: 100 | BL29: =AVERAGE(AL29:AW29) -> 100 | BM29: =AVERAGE(AX29:BI29) -> 100 | BN29: =BM29/BL29-1 -> 0 | CA29: Deflator CPI Communication - Average Jan Jul 2016/2015
A30: Manufacture of tobacco products | B30: 100 | C30: 100 | D30: 100 | E30: 100 | F30: 100 | G30: 100 | H30: 100 | I30: 100 | J30: 100 | K30: 100 | L30: 100 | M30: 100 | N30: 100 | O30: 100 | P30: 100 | Q30: 100 | R30: 100 | S30: 100 | T30: 100 | U30: 100 | V30: 100 | W30: 100 | X30: 100 | Y30: 100 | Z30: 100 | AA30: 100 | AB30: 100 | AC30: 100 | AD30: 100 | AE30: 100 | AF30: 100 | AG30: 100 | AH30: 100 | AI30: 100 | AJ30: 100 | AK30: 100 | AL30: 100 | AM30: 100 | AN30: 100 | AO30: 100 | AP30: 100 | AQ30: 100 | AR30: 100 | AS30: 100 | AT30: 100 | AU30: 100 | AV30: 100 | AW30: 100 | AX30: 100 | AY30: 100 | AZ30: 100 | BA30: 100 | BB30: 100 | BC30: 100 | BD30: 100 | BL30: =AVERAGE(AL30:AW30) -> 100 | BM30: =AVERAGE(AX30:BI30) -> 100 | BN30: =BM30/BL30-1 -> 0 | CA30: Deflator general CPI - Average Jan-Jul 2016/2015
